Workbook

Sheet games
A1: Name | B1: Year | C1: Type | D1: Connected? | E1: Influencer? | F1: Tags | G1: File | H1: Owned
A2: [Redacted] | B2: 2024 | C2: Action | D2: TRUE | E2: =COUNTIF(connections!A:A, A2) > 0 -> FALSE | G2: redacted
A3: 100 Rogues | B3: 2010 | C3: Traditional | D3: TRUE | E3: =COUNTIF(connections!A:A, A3) > 0 -> TRUE
A4: 20 Minutes Till Dawn | B4: 2022 | C4: Action | D4: TRUE | E4: =COUNTIF(connections!A:A, A4) > 0 -> TRUE | H4: Yes
A5: 20XX | B5: 2017 | C5: Action | D5: TRUE | E5: =COUNTIF(connections!A:A, A5) > 0 -> TRUE | H5: Yes
A6: 30XX | B6: 2021 | C6: Action | D6: TRUE | E6: =COUNTIF(connections!A:A, A6) > 0 -> FALSE | H6: Yes
A7: 9 Kings | B7: 2024 | C7: Deckbuilding | D7: TRUE | E7: =COUNTIF(connections!A:A, A7) > 0 -> FALSE | H7: Yes
A8: 99 Levels to Hell | B8: 2013 | C8: Action | D8: TRUE | E8: =COUNTIF(connections!A:A, A8) > 0 -> FALSE
A9: A la Card | B9: 2025 | C9: Deckbuilding | D9: TRUE | E9: =COUNTIF(connections!A:A, A9) > 0 -> FALSE
A10: A Robot Named Fight! | B10: 2017 | C10: Action | D10: TRUE | E10: =COUNTIF(connections!A:A, A10) > 0 -> FALSE | H10: Yes
A11: Abandoned Archive | B11: 2025 | C11: Action | D11: TRUE | E11: =COUNTIF(connections!A:A, A11) > 0 -> FALSE
A12: Absolum | B12: 2025 | C12: Action | D12: TRUE | E12: =COUNTIF(connections!A:A, A12) > 0 -> FALSE | H12: Yes
A13: Aces & Adventures | B13: 2023 | C13: Deckbuilding | D13: TRUE | E13: =COUNTIF(connections!A:A, A13) > 0 -> FALSE | H13: Yes
A14: Across the Obelisk | B14: 2021 | C14: Deckbuilding | D14: TRUE | E14: =COUNTIF(connections!A:A, A14) > 0 -> TRUE
A15: Aethermancer | B15: 2025 | C15: Strategy | D15: TRUE | E15: =COUNTIF(connections!A:A, A15) > 0 -> FALSE | H15: Yes
A16: AK-xolotl | B16: 2023 | C16: Action | D16: TRUE | E16: =COUNTIF(connections!A:A, A16) > 0 -> FALSE | H16: Yes
A17: Alina of the Arena | B17: 2022 | C17: Deckbuilding | D17: TRUE | E17: =COUNTIF(connections!A:A, A17) > 0 -> FALSE | H17: Yes
A18: Ancient Domains of Mystery | B18: 1994 | C18: Traditional | D18: TRUE | E18: =COUNTIF(connections!A:A, A18) > 0 -> TRUE | H18: Yes
A19: Angband | B19: 1990 | C19: Traditional | D19: TRUE | E19: =COUNTIF(connections!A:A, A19) > 0 -> TRUE | G19: angband
A20: Another Farm Roguelike | B20: 2022 | C20: Strategy | D20: FALSE | E20: =COUNTIF(connections!A:A, A20) > 0 -> TRUE | H20: Yes
A21: Another Farm Roguelike: Rebirth | B21: 2025 | C21: Strategy | D21: FALSE | E21: =COUNTIF(connections!A:A, A21) > 0 -> FALSE
A22: Aotenjo: Infinite Hands | B22: 2024 | C22: Deckbuilding | D22: TRUE | E22: =COUNTIF(connections!A:A, A22) > 0 -> FALSE
A23: Approaching Infinity | B23: 2020 | C23: Traditional | D23: TRUE | E23: =COUNTIF(connections!A:A, A23) > 0 -> FALSE
A24: Arcane Trigger | B24: 2025 | C24: Action | D24: FALSE | E24: =COUNTIF(connections!A:A, A24) > 0 -> FALSE
A25: Arcanium: Rise of Akhan | B25: 2020 | C25: Deckbuilding | D25: TRUE | E25: =COUNTIF(connections!A:A, A25) > 0 -> FALSE | H25: Yes
A26: Archons | B26: 2024 | C26: Action | D26: TRUE | E26: =COUNTIF(connections!A:A, A26) > 0 -> FALSE | H26: Yes
A27: Army of Ruin | B27: 2022 | C27: Action | D27: TRUE | E27: =COUNTIF(connections!A:A, A27) > 0 -> FALSE | G27: army-of-ruin
A28: Arrogue | B28: 2025 | C28: Deckbuilding | D28: TRUE | E28: =COUNTIF(connections!A:A, A28) > 0 -> FALSE
A29: As We Descend | B29: 2025 | C29: Deckbuilding | D29: TRUE | E29: =COUNTIF(connections!A:A, A29) > 0 -> FALSE
A30: Asgard's Fall: Viking Survivors | B30: 2025 | C30: Action | D30: TRUE | E30: =COUNTIF(connections!A:A, A30) > 0 -> FALSE | H30: Yes
A31: Asterogues | B31: 2023 | C31: Action | D31: TRUE | E31: =COUNTIF(connections!A:A, A31) > 0 -> FALSE
A32: Astral Ascent | B32: 2022 | C32: Action | D32: TRUE | E32: =COUNTIF(connections!A:A, A32) > 0 -> FALSE | H32: Yes
A33: Astro Prospector | B33: 2025 | C33: Action | D33: TRUE | E33: =COUNTIF(connections!A:A, A33) > 0 -> FALSE | G33: astro-prospector | H33: Yes
A34: Astronarch | B34: 2020 | C34: Strategy | D34: TRUE | E34: =COUNTIF(connections!A:A, A34) > 0 -> TRUE | H34: Yes
A35: Atomicrops | B35: 2020 | C35: Action | D35: TRUE | E35: =COUNTIF(connections!A:A, A35) > 0 -> TRUE | G35: atomicrops | H35: Yes
A36: Auro: A Monster-Bumping Adventure | B36: 2014 | C36: Strategy | D36: TRUE | E36: =COUNTIF(connections!A:A, A36) > 0 -> TRUE
A37: Auto Rogue | B37: 2025 | C37: Strategy | D37: FALSE | E37: =COUNTIF(connections!A:A, A37) > 0 -> FALSE
A38: Backpack Battles | B38: 2023 | C38: Strategy | D38: TRUE | E38: =COUNTIF(connections!A:A, A38) > 0 -> TRUE
A39: Backpack Hero | B39: 2022 | C39: Deckbuilding | D39: TRUE | E39: =COUNTIF(connections!A:A, A39) > 0 -> TRUE | H39: Yes
A40: Bad North | B40: 2018 | C40: Strategy | D40: FALSE | E40: =COUNTIF(connections!A:A, A40) > 0 -> FALSE | H40: Yes
...

Sheet connections
A1: Influencer | B1: Influencee | C1: Influencer Time | D1: Dev/Series Relation | E1: Source
A2: 100 Rogues | B2: Auro: A Monster-Bumping Adventure | C2: 2010 | D2: Yes
A3: 20 Minutes Till Dawn | B3: Disfigure | C3: 2022 | E3: check folder
A4: 20XX | B4: 30XX | C4: 2017 | D4: Yes
A5: Across the Obelisk | B5: The Royal Writ | C5: 2021 | E5: https://store.steampowered.com/app/3333700/The_Royal_Writ/
A6: Ancient Domains of Mystery | B6: Caves of Qud | C6: 1994
A7: Ancient Domains of Mystery | B7: Elona | C7: 1994
A8: Ancient Domains of Mystery | B8: Moonring | C8: 1994 | E8: check folder
A9: Ancient Domains of Mystery | B9: Stoneshard | C9: 1994 | E9: https://www.kickstarter.com/projects/1926605606/stoneshard-open-world-roguelike-rpg-with-tactical
A10: Ancient Domains of Mystery | B10: Ultimate ADOM | C10: 1994
A11: Ancient Domains of Mystery | B11: KeeperRL | C11: 1994 | E11: check folder
A12: Ancient Domains of Mystery | B12: Soulash | C12: 1994 | E12: https://x.com/ArturSmiarowski/status/1870390372389597210
A13: Ancient Domains of Mystery | B13: Rogue Empire | C13: 1994 | E13: https://www.patreon.com/roguempire/about
A14: Angband | B14: Elona | C14: 1990
A15: Angband | B15: Zangband | C15: 1990 | E15: https://roguebasin.com/index.php/Zangband
A16: Angband | B16: Infra Arcana | C16: 1990 | E16: check folder
A17: Angband | B17: Sil | C17: 1990 | E17: https://roguebasin.com/index.php/Sil
A18: Angband | B18: Zorbus | C18: 1990 | E18: check folder
A19: Another Farm Roguelike | B19: Another Farm Roguelike: Rebirth | C19: 2022 | D19: Yes
A20: Astronarch | B20: The Last Flame | C20: 2020 | E20: https://steamcommunity.com/app/1830970/discussions/0/6660355571253835571/
A21: Atomicrops | B21: Pesticide Not Required | C21: 2020 | E21: https://store.steampowered.com/app/2479320/Pesticide_Not_Required/
A22: Auro: A Monster-Bumping Adventure | B22: Rack and Slay | C22: 2014 | E22: https://www.youtube.com/watch?v=kYUYXX5vdkU
A23: Backpack Battles | B23: Knightica | C23: 2023 | E23: https://www.reddit.com/r/IndieGaming/comments/1iooyqr/roguelike_autobattler_cute_creatures_what_do_you/
A24: Backpack Battles | B24: He is Coming | C24: 2023 | E24: check folder
A25: Backpack Battles | B25: Lootplot | C25: 2023 | E25: https://codetheory.itch.io/lootplot-playtest#:~:text=A%20downloadable%20game%20for%20Windows,it%20to%20the%20next%20round.
A26: Backpack Battles | B26: Toy Smash Kaboom! | C26: 2023 | E26: look at it
A27: Backpack Hero | B27: Moon Watch | C27: 2022 | D27: Yes
A28: Backpack Hero | B28: Spin Hero | C28: 2022 | E28: check folder
A29: Balatro | B29: Aotenjo: Infinite Hands | C29: 2023 | E29: talks about balatro in discord
A30: Balatro | B30: Bingle Bingle | C30: 2023 | E30: check folder
A31: Balatro | B31: Sky's The Limit MAH-JONG | C31: 2023 | E31: duh
A32: Balatro | B32: RollScape | C32: 2023 | E32: https://steamcommunity.com/games/2904290/announcements/detail/4185610799649293674#:~:text=RollScape%20is%20a%20game%20inspired,I%20played%20throughout%20the%20years.
A33: Balatro | B33: Drop Pockets | C33: 2023 | E33: clear influence but also check folder, he clearly plays it and made a game like it
A34: Balatro | B34: Omelet You Cook | C34: 2023 | E34: https://store.steampowered.com/app/3205380/Omelet_You_Cook/
A35: Balatro | B35: Pip My Dice | C35: 2023 | E35: https://store.steampowered.com/app/2797650/Pip_My_Dice/
A36: Balatro | B36: The Royal Writ | C36: 2023 | E36: https://store.steampowered.com/app/3333700/The_Royal_Writ/
A37: Balatro | B37: Steve's Warehouse: Physics. Roguelike. Chaos. | C37: 2023 | E37: https://store.steampowered.com/app/2902440/Steves_Warehouse_Physics_Roguelike_Chaos/
A38: Balatro | B38: Clutchtime: Basketball Deckbuilder | C38: 2023 | E38: https://www.gamespress.com/Solo-Developer-Bigosaur-Launches-Basketball-Roguelike-Clutchtime-Baske#:~:text=With%20inspirations%20from%20hometown%20superstars%20Nikola%20Joki%C4%87%2C,passion%20project%20using%20basketball%20as%20the%20medium.
A39: Balatro | B39: Drop Duchy | C39: 2023 | E39: check folder
... A56: Bleak Sword | B56: Scourgebringer | C56: 2019 | E56: check folder
...

Sheet characters
A1: Name | B1: Game | C1: Health | D1: Energy | E1: Str | F1: Dex | G1: Int | H1: Cha | I1: Reroll | J1: Dash | K1: Skip | L1: Discovery | M1: FoV | N1: Luck | O1: Random | P1: Level Up | Q1: Description | R1: Combat Style | S1: Strikes | T1: Defends | U1: Unique 1 | V1: Starting items
A2: Rodney | B2: Rogue | C2: 75 | D2: 3 | E2: 0 | F2: 0 | G2: 0 | H2: 0 | I2: 0 | J2: 0 | K2: 0 | L2: 0 | M2: 0 | N2: 0 | O2: 2 | P2: Beat a game without meta progression | Q2: Now I abide here, searching endlessly for the precious Amulet... and finding a thousand horrors. | R2: Identify | S2: 5 | T2: 5 | V2: N/A
A3: Isaac | B3: The Binding of Isaac | C3: 75 | D3: 3 | E3: 1 | F3: 0 | G3: 0 | H3: 0 | I3: 1 | J3: 0 | K3: 0 | L3: 0 | M3: 0 | N3: 0 | O3: 0 | P3: Unlock a new gameplay element | Q3: Who am I? | R3: Dice | S3: 5 | T3: 4 | U3: Isaac's D6 | V3: N/A
A4: Zoe | B4: Haste | C4: 50 | D4: 3 | E4: 1 | F4: 0 | G4: 0 | H4: 0 | I4: 0 | J4: 1 | K4: 0 | L4: 0 | M4: 0 | N4: 0 | O4: 0 | P4: Perfect a Game | Q4: Express Delivery: Arrives with haste, before the world ends. | R4: Perfect | S4: 5 | T4: 5 | V4: N/A
A5: Minä | B5: Noita | C5: 60 | D5: 3 | E5: 0 | F5: 0 | G5: 1 | H5: 1 | I5: 0 | J5: 0 | K5: 0 | L5: 0 | M5: 0 | N5: 0 | O5: 0 | P5: Craft or combine a spell or weapon | Q5: Why must you go destroying everything? Why? For glory? For your precious god of gods. Is it really worth all this? Is it? Is it really? | R5: Spells | S5: 5 | T5: 5 | V5: N/A
A6: Ironclad | B6: Slay the Spire | C6: 80 | D6: 3 | E6: 1 | F6: 1 | G6: 0 | H6: 0 | I6: 0 | J6: 0 | K6: 0 | L6: 0 | M6: 0 | N6: 0 | O6: 0 | P6: Beat a game on a hard difficulty | Q6: The remaining soldier of the Ironclads. Sold his soul to harness demonic energies. | R6: Cards | S6: 5 | T6: 4 | U6: Bash | V6: Burning Blood

Sheet items
A1: Name | B1: Rating | C1: Type | D1: Description | E1: Reference | F1: tags | G1: File | H1: Requirement | I1: Sorting
A2: Ride the Bus | B2: Uncommon | C2: Usable | D2: Teleport to a random Deckbuilder space | E2: Balatro | G2: RideTheBus | H2: N/A | I2: Movement
A3: Bowler Hat | B3: Uncommon | C3: Passive | D3: Gain +6 Charisma, but -2 Dexterity | E3: Brotato | F3: wearable, hat | G3: BowlerHat | H3: N/A | I3: Stats
A4: Campfire | B4: Uncommon | C4: Passive | D4: Gain +6 Intelligence, but -2 Dexterity | E4: Brotato | G4: Campfire | H4: N/A | I4: Stats
A5: Panda | B5: Rare | C5: Pickup | D5: Gain +20 Max Health and +2 Luck, but -3 Strength | E5: Brotato | G5: Panda | H5: N/A | I5: Health, Stats
A6: Wheat | B6: Uncommon | C6: Passive | D6: Gain +6 Strength, but -2 Intelligence | E6: Brotato | F6: food | G6: Wheat | H6: N/A | I6: Stats
A7: Wings | B7: Uncommon | C7: Passive | D7: Gain +6 Dexterity, but -2 Intelligence | E7: Brotato | F7: mutation | G7: Wings | H7: N/A | I7: Stats
A8: Reactive Trauma Plate | B8: Rare | C8: Triggered | D8: If the player would take lethal damage, negate that damage and destroy this item | E8: Caves of Qud | F8: cybernetics | G8: ReactiveTraumaPlate | H8: N/A | I8: Health
A9: Stabilizer Arm Locks | B9: Rare | C9: Passive | D9: Gain +6 Dexterity | E9: Caves of Qud | F9: cybernetics | G9: StabilizerArmLocks | H9: N/A | I9: Stats
A10: Unstable Genome | B10: Uncommon | C10: Triggered | D10: When you beat a game, there's a 33% chance for this item to be destroyed and you may gain 1 of 3 random items | E10: Caves of Qud | F10: mutation | G10: UnstableGenome | H10: N/A | I10: Economy
A11: Ballistic Boots | B11: Rare | C11: Passive | D11: Gain +1 Dash | E11: Enter the Gungeon | F11: wearable, shoes | G11: BallisticBoots | H11: N/A | I11: Stats
A12: Sunglasses | B12: Common | C12: Passive | D12: Gain +2 Charisma | E12: Enter the Gungeon | F12: wearable, glasses | G12: Sunglasses | H12: N/A | I12: Stats
A13: Golden Beetle | B13: Rare | C13: Triggered | D13: Whenever you get rid of a curse, gain one Chest | E13: Forward: Escape the Fold | F13: bug | G13: GoldenBeetle | H13: N/A | I13: Curse, Economy
A14: Vitality Orb | B14: Rare | C14: Triggered | D14: Gain +8 Max Health whenever you obtain a curse | E14: Forward: Escape the Fold | F14: orb | G14: VitalityOrb | H14: N/A | I14: Health, Curse
A15: Boon of Aphrodite | B15: N/A | C15: Boon | D15: If the player charms an enemy gain +1 to all combat roll bonus stats, but 20% chance for games to be Charmed | E15: Hades | G15: BoonOfAphrodite | H15: N/A | I15: Boon
A16: Boon of Artemis | B16: N/A | C16: Boon | D16: If the player uses ranged strategies primarlity to win the run gain +1 to all combat roll bonus stats, but 20% chance for games to be Marked | E16: Hades | G16: BoonOfArtemis | H16: N/A | I16: Boon
A17: Boon of Athena | B17: N/A | C17: Boon | D17: If the player negates damage with a shield 5+ times gain +1 to all combat roll bonus stats, but 20% for games to be Shielded | E17: Hades | G17: BoonOfAthena | H17: N/A | I17: Boon
A18: Boon of Hermes | B18: N/A | C18: Boon | D18: If the player beats a game within an hour gain +1 to all combat roll bonus stats, but 20% chance for games to be Timed | E18: Hades | G18: BoonOfHermes | H18: N/A | I18: Boon
A19: Boon of Poseidon | B19: N/A | C19: Boon | D19: If the player defeats an enemy underwater gain +1 to all combat roll bonus stats, but 20% chance for games to be Soaked | E19: Hades | G19: BoonOfPoseidon | H19: N/A | I19: Boon
A20: Boon of Zeus | B20: N/A | C20: Boon | D20: If the player defeats an enemy with lightning in their run gain +1 to all combat roll bonus stats, but 20% chance for games to be Shocked | E20: Hades | G20: BoonOfZeus | H20: N/A | I20: Boon
A21: Clown Shoes | B21: Uncommon | C21: Triggered | D21: Whenever you don't Perfect a game, (beat a game/combat without losing a run) 50% chance to treat it like you did | E21: Haste | F21: wearable, shoes, clown | G21: ClownShoes | H21: N/A | I21: Perfect
A22: Performance Based Health Insurance | B22: Common | C22: Triggered | D22: Whenever you perfect a game (beat a game/combat without losing a run), Gain +5 Health | E22: Haste | G22: PerformanceBasedHealthInsurance | H22: N/A | I22: Perfect, Health
A23: Secret Technique Instructions | B23: Rare | C23: Triggered | D23: Whenever you perfect a game (beat a game/combat without losing a run), gain +1 Dash | E23: Haste | F23: book | G23: SecretTechniqueInstructions | H23: N/A | I23: Perfect, Stats
A24: Steady Investment | B24: Common | C24: Triggered | D24: Whenever you perfect a game (beat a game/combat without losing a run), Gain +5 Gold | E24: Haste | G24: SteadyInvestment | H24: N/A | I24: Perfect, Economy
A25: Beefy Ring | B25: Rare | C25: Scaling | D25: Gain scaling +1 Strength per 20 max health | E25: Megabonk | F25: wearable, ring | G25: BeefyRing | H25: N/A | I25: Stats
A26: Wand of Wishing | B26: Legendary | C26: Usable | D26: Obtain any one item in the game | E26: NetHack | G26: WandOfWishing | H26: N/A | I26: Economy
A27: Focus Crystal | B27: Common | C27: Passive | D27: Melee Attacks deal +1 Dmg | E27: Risk of Rain 2 | F27: crystal | G27: FocusCrystal | H27: N/A | I27: Stats
A28: Scroll of Teleportation | B28: Common | C28: Usable | D28: Teleport to a random space | E28: Rogue | G28: ScrollOfTeleportation | H28: N/A | I28: Movement
A29: Blood Vial | B29: Common | C29: Triggered | D29: At the start of combat, gain +1 Health | E29: Slay the Spire | F29: blood | G29: BloodVial | H29: N/A | I29: Health
A30: Busted Crown | B30: Rare | C30: Passive | D30: Gain +1 Max Energy, but -2 Discovery | E30: Slay the Spire | F30: wearable, hat, crown | G30: BustedCrown | H30: N/A | I30: Energy
A31: Fire Potion | B31: Uncommon | C31: Usable | D31: In combat, deal 20 damage to a target enemy | E31: Slay the Spire | F31: potion | G31: FirePotion | H31: N/A | I31: Damage
A32: Horn Cleat | B32: Uncommon | C32: Passive | D32: Start the 2nd turn of combat with +14 Block | E32: Slay the Spire | F32: sea, ship | G32: HornCleat | H32: N/A | I32: Defense
A33: Meat on the Bone | B33: Uncommon | C33: Triggered | D33: Whenever your Health is at 50% or below Max Health at the end of combat, gain +12 Health | E33: Slay the Spire | F33: food, meat | G33: MeatOnTheBone | H33: N/A | I33: Health
A34: Oddly Smooth Stone | B34: Common | C34: Passive | D34: Gain +3 Dexterity | E34: Slay the Spire | F34: stone | G34: OddlySmoothStone | H34: N/A | I34: Stats
A35: Philosopher's Stone | B35: Rare | C35: Passive | D35: Gain +1 Max Energy, but all enemies start with 1 Power | E35: Slay the Spire | F35: stone | G35: PhilosophersStone | H35: N/A | I35: Energy
A36: Vajra | B36: Common | C36: Passive | D36: Gain +3 Strength | E36: Slay the Spire | G36: Vajra | H36: N/A | I36: Stats
A37: Winged Boots | B37: Rare | C37: Usable | D37: Move to a one of three games that share the year of the game you're currently on | E37: Slay the Spire | F37: wearable, shoes | G37: WingedBoots | H37: N/A | I37: Movement
A38: Garlic | B38: Uncommon | C38: Triggered | D38: At the start of combat, gain +1 Brace | E38: Super Auto Pets | F38: food | G38: Garlic | H38: N/A | I38: Defense
A39: Charm of the Vampire | B39: Uncommon | C39: Triggered | D39: When you defeat an enemy, 50% chance to Heal +3 Health | E39: The Binding of Isaac | G39: CharmOfTheVampire | H39: N/A | I39: Health
A40: D6 | B40: Uncommon | C40: Passive | D40: Gain +2 Rerolls | E40: The Binding of Isaac | G40: D6 | H40: N/A | I40: Stats
...

Sheet weapons
A1: Name | B1: Rarity | C1: Upgrade | D1: Reference | E1: tags | F1: File | G1: Unlock Condition
A2: Barrel | B2: Uncommon | C2: If you obtain at least 1 fish, gain (1/2) random fish | D2: Enter the Gungeon | E2: gun, fish, ranged | F2: Barrel | G2: N/A
A3: Blasma Pistol | B3: Common | C3: If you open more than 10 chests, gain a (small/normal) chest | D3: Flinthook | E3: gun, ranged | F3: BlasmaPistol | G3: N/A
A4: Lil' Bomber | B4: Common | C4: If you kill an enemy with a bomb at least one time, this weapon gains (+1/+2) Dmg | D4: Enter the Gungeon | E4: gun, ranged | F4: LilBomber | G4: N/A
A5: Blood Magic | B5: Rare | C5: If you create or use a magic circle, this weapon gains (+1/+2/) Infuse | D5: Megabonk | E5: ranged | F5: BloodMagic | G5: N/A
A6: Dexecutioner | B6: Uncommon | C6: If you kill an enemy with a piercing attack at least one time, this weapon gains (+1/+2) Assassinate | D6: Megabonk | E6: melee | F6: Dexecutioner | G6: N/A

Sheet events
A1: Name | B1: Description | C1: Option 1 | D1: Option 2 | E1: Option 3 | F1: Option 4 | G1: Requirement
A2: Primordial Teleporter | B2: A trio of Stone Golems back you up into what seems to be an ancient teleporter. Do you activate it? | C2: Enter the teleporter (teleport to a random action roguelike) | D2: Interact with the teleporter, then enter it (teleport to the starting game and decrease difficulty by 3) | E2: Fight off the Stone Golems (Enter three consecutive combats with the Stone Golem Enemy) | G2: N/A
A3: A Wild Muncher Appears | B3: You come across a green chest that looks hungry. Should you feed it? | C3: Feed it four items (discard four items and get two random new ones of rarity equal to the least rare item discarded) | D3: Feed it two items (discard 2 items and get one random new one of rarity equal to the least rare item discarded) | E3: Leave it hungry (Do Nothing) | G3: 4 or more items
A4: The Collosseum | B4: You wake up in the center of a roaring arena, and must survive as long as you can. You must fight off an enemy and then are given the choice to escape or double down. (Teleport to an action game off of the map and beat it.) | C4: Escape the arena (you then get teleported back to the game that originally had the event trigger) | D4: Challenge the Champion (You get teleported to another game that isn't connected to the rest and have three attempts to beat it, if you succeed gain 2 random items, if you fail lose 3 health) | G4: N/A
A5: A Sushi Bar By The Blue Hole | B5: As you continue on your journey, you stumble upon a sushi resteraunt residing near a large ocean. You meet an eccentric older gentleman who challenges you to a fishing contest. | C5: Keep the fish (You are able to sell fish in the shop for gold) | D5: Allow the chef to prepare sushi (exchange fish for health)
A13: Deal with the Devil | B13: You enter a room devoid of light with a large statue of Satan standing above 3 different floating question marks. Do you take them? | C13: Grab one question mark (Get one random item and lose one health) | D13: Grab two question marks (Get two random items and lose two health) | E13: Grab three question mark (Get three random items and lose three health) | F13: Do nothing
A14: The Colloseum | B14: You wake up in the center of a roaring arena, and must survive as long as you can. You must fight off an enemy and then are given the choice to escape or double down. (Teleport to an action game off of the map and beat it. You get the item reward, but not the event trigger) | C14: Escape the arena (Teleport back to the spot you were on before) | D14: Challenge the Champion (You have three attempts to beat the game you are currently on, if you succeed gain 2 random items, if you fail lose 3 health)

Sheet enemies
A1: Name | B1: Type | C1: Difficulty | D1: Weight | E1: Min HP | F1: Max HP | G1: Ability | H1: Game | I1: Location | J1: Pattern | K1: File | L1: Variant | M1: Tag
A2: Lemurian | B2: Strength | C2: Low | D2: 1 | E2: 30 | F2: 34 | G2: Stagger 33% | H2: Risk of Rain | I2: General | J2: Always: 75% 6 Dmg Ranged, 1 Burn / 25% 9 Dmg Melee | K2: Lemurian | L2: N/A
A3: Stone Golem | B3: Strength | C3: Medium | D3: 2 | E3: 64 | F3: 70 | G3: Stagger 33% | H3: Risk of Rain | I3: General | J3: Turn 1: Unknown Intent ("Charging") | Turn 2: 50% 20 Dmg Ranged / 50% 10 Dmg Melee 3 Vulnerable | Next: Repeat | K3: StoneGolem | L3: N/A
A4: Elder Lemurian | B4: Strength | C4: High | D4: 7 | E4: 150 | F4: 160 | G4: Stagger 33% | H4: Risk of Rain | I4: General | J4: Always: 50% 3x5 Dmg Ranged / 50% 8 Dmg Melee 5 Burn | K4: ElderLemurian | L4: N/A
A5: Pacer | B5: Strength | C5: Low | D5: N/A | E5: 20 | F5: 24 | G5: N/A | H5: The Binding of Isaac | I5: General | J5: Always: 75% Unknown Intent ("Wandering") / 25% 6 Dmg Melee | K5: Pacer | L5: N/A
A6: Gaper | B6: Strength | C6: Low | D6: 1 | E6: 20 | F6: 24 | G6: When Defeated, 60% Spawn Pacer / 40% Spawn Gusher | H6: The Binding of Isaac | I6: General | J6: Always: 6 Dmg Melee | K6: Gaper | L6: N/A
A7: Gusher | B7: Strength | C7: Low | D7: N/A | E7: 20 | F7: 24 | G7: N/A | H7: The Binding of Isaac | I7: General | J7: Always: 75% Unknown Intent ("Wandering") / 25% 6 Dmg Ranged | K7: Gusher | L7: N/A
A8: Double Vis | B8: Strength | C8: Medium | D8: 3 | E8: 48 | F8: 54 | G8: N/A | H8: The Binding of Isaac | I8: General | J8: Always: 10 Dmg Overload Ranged | K8: DoubleVis | L8: N/A
A9: Tainted Pooter | B9: Strength | C9: High | D9: 7 | E9: 130 | F9: 140 | G9: When Defeated, Strength Save 15 or take 3 Dmg | H9: The Binding of Isaac | I9: General | J9: Turn 1: 5x4 Dmg Ranged | Turn 2: 5x2 Dmg Ranged | K9: TaintedPooter | L9: N/A | M9: bug
A10: Mung | B10: Intelligence | C10: Low | D10: 1 | E10: 20 | F10: 24 | G10: Pigment Rich | H10: Brutal Orchestra | I10: Desert | J10: Always: 50% 3 Dmg Melee / 50% Add 1 random Pigment Status card to your deck | K10: Mung | L10: N/A
A11: Mud Lung | B11: Intelligence | C11: Low | D11: 2 | E11: 30 | F11: 34 | G11: Pigment Rich | H11: Brutal Orchestra | I11: Desert | J11: Always: 58% 6 Dmg Melee / 42% Consume 1 random Pigment Status card in Any for 3 Power, 6 Block | K11: MudLung | L11: N/A
A12: Mungling Mud Lung | B12: Intelligence | C12: Low | D12: 3 | E12: 40 | F12: 44 | G12: Pigment Rich / Multi Attack 2 / When Defeated, 50% chance to Spawn Mung | H12: Brutal Orchestra | I12: Desert | J12: Always: 41% 6 Dmg Melee / 29% Consume 1 random Pigment Status card in Any for 3 Power, 6 Block / 30% 4 Pain, Spawn Mungie | K12: MunglingMudLung | L12: N/A
A13: Mungie | B13: Intelligence | C13: Low | D13: N/A | E13: 12 | F13: 14 | G13: Pigment Rich | H13: Brutal Orchestra | I13: Desert | J13: Always: 3 Dmg Melee | K13: Mungie | L13: N/A
A14: Revola | B14: Intelligence | C14: Medium | D14: 3 | E14: 130 | F14: 140 | G14: Pigment Rich / Forgetful / Barricade | H14: Brutal Orchestra | I14: Watery | J14: Always: 41% 3 Dmg Ranged, 3 Oiled / 41% 15 Dmg Ranged, 16 Block / 18% Alter Revola (Standing), Gain 2 Frail | K14: Revola | L14: N/A
A15: Revola (Standing) | B15: Intelligence | C15: Medium | D15: N/A | E15: 130 | F15: 140 | G15: Pigment Rich / Forgetful / Barricade | H15: Brutal Orchestra | I15: Watery | J15: Always: 77% 9 Dmg Melee, Inflict 3 Ruptured, 20 Block, Alter Revola, Lose All Frail / 23% Unknown Intent ("Stood up too fast, got a headrush") | K15: RevolaStanding | L15: Revola
A16: Skinning Homunculus | B16: Intelligence | C16: High | D16: 5 | E16: 100 | F16: 110 | G16: Formless / When another ally takes Melee Dmg, Add 1 Frail Overload to Intent | H16: Brutal Orchestra | I16: Chaos | J16: Always: 43% 10 Dmg Ranged OverloadExceptLeft / 43% 10 Dmg Ranged OverloadExceptRight / 14% 40 Dmg Ranged, 35 Pain | K16: SkinningHomunculus | L16: N/A
A17: Hobgoblin | B17: Dexterity | C17: Low | D17: 1 | E17: 30 | F17: 34 | G17: Rerollable | H17: Rogue | I17: General | J17: Always: D8 Dmg Melee | K17: Hobgoblin | L17: N/A | M17: goblin
A18: Aquator | B18: Dexterity | C18: Medium | D18: 2 | E18: 40 | F18: 46 | G18: Rust / Rerollable | H18: Rogue | I18: General | J18: Always: D6x3 Dmg Melee | K18: Aquator | L18: N/A
A19: Troll | B19: Dexterity | C19: Medium | D19: 4 | E19: 60 | F19: 66 | G19: Rerollable | H19: Rogue | I19: General | J19: Always: D8x2+D6x2 Dmg Melee | K19: Troll | L19: N/A
A20: Dragon | B20: Dexterity | C20: High | D20: 9 | E20: 250 | F20: 270 | G20: Immune to Burn, Rerollable | H20: Rogue | I20: General | J20: Always: 50% D6x6 Dmg Ranged, 5 Burn / 50% D8x2+D10x3 Dmg Melee | K20: Dragon | L20: N/A | M20: dragon
A21: Cultist | B21: Charisma | C21: Low | D21: 2 | E21: 48 | F21: 54 | G21: N/A | H21: Slay the Spire | I21: General | J21: Turn 1: Gain 3 Ritual | Next: 6 Dmg Melee | K21: Cultist | L21: N/A
A22: Snecko | B22: Charisma | C22: Medium | D22: 6 | E22: 114 | F22: 120 | G22: N/A | H22: Slay the Spire | I22: General | J22: Turn 1: Inflict 6 Confused | Next: 60% 8 Dmg Melee 2 Vulnerable / 40% 15 Dmg Melee | K22: Snecko | L22: N/A
A23: Transient | B23: Charisma | C23: High | D23: 9 | E23: 999 | F23: 999 | G23: Fading 4/Shifting | H23: Slay the Spire | I23: General | J23: Always: 30 + (Turn Number - 1 x 10) Dmg Melee | K23: Transient | L23: N/A
A24: Bones | B24: Intelligence | C24: Low | D24: 1 | E24: 30 | F24: 34 | G24: When Defeated, 5 Dmg to it's adjacent allies | H24: Slice & Dice | I24: Undead | J24: Always: 60% 9 Dmg Melee / 40% 6 Dmg Melee | K24: Bones | L24: N/A | M24: undead
A25: Fanatic | B25: Intelligence | C25: Medium | D25: 3 | E25: 48 | F25: 54 | G25: N/A | H25: Slice & Dice | I25: General | J25: Always: 33.3% 20 Dmg Melee, 20 Pain / 33.3% 15 Dmg Melee, 15 Pain / 33.4% 10 Dmg Melee, 10 Pain | K25: Fanatic | L25: N/A
A26: Spiker | B26: Intelligence | C26: High | D26: 3 | E26: 60 | F26: 66 | G26: 3 Thorns | H26: Slice & Dice | I26: General | J26: Always: 60% 15 Dmg Melee / 40% 10 Dmg Ranged, Gain 1 Thorns | K26: Spiker | L26: N/A
A27: Jaw Worm | B27: Charisma | C27: Low | D27: 3 | E27: 40 | F27: 44 | G27: N/A | H27: Slay the Spire | I27: General | J27: Turn 1: 11 Dmg Melee | Next: 45% Get 3 Power, 6 Block / 30% 7 Dmg Melee, 6 Block / 25% 11 Dmg Melee | K27: JawWorm | L27: N/A
A28: Red Louse | B28: Charisma | C28: Low | D28: 1 | E28: 10 | F28: 15 | G28: Curl Up Determined(3-7) | H28: Slay the Spire | I28: General | J28: Always: 75% Determined(5-7) Dmg Melee / 25% Gain 3 Power | K28: RedLouse | L28: N/A | M28: bug
A29: Green Louse | B29: Charisma | C29: Low | D29: 1 | E29: 11 | F29: 17 | G29: Curl Up Determined(3-7) | H29: Slay the Spire | I29: General | J29: Always: 75% Determined(5-7) Dmg Melee / 25% Inflict 2 Weak | K29: GreenLouse | L29: N/A | M29: bug
A30: Acid Slime (L) | B30: Charisma | C30: Low | D30: 4 | E30: 65 | F30: 69 | G30: Split 2 Acid Slime (M) | H30: Slay the Spire | I30: General | J30: Always: 30% 11 Dmg Ranged, Add 2 Slimed to Discard / 40% 16 Dmg Melee / 30% Inflict 2 Weak | K30: AcidSlime(L) | L30: N/A | M30: slime
A31: Acid Slime (M) | B31: Charisma | C31: Low | D31: 2 | E31: 28 | F31: 32 | G31: N/A | H31: Slay the Spire | I31: General | J31: Always: 30% 7 Dmg Ranged, Add 1 Slimed to Discard / 40% 10 Dmg Melee / 30% Inflict 1 Weak | K31: AcidSlime(M) | L31: N/A | M31: slime
A32: Acid Slime (S) | B32: Charisma | C32: Low | D32: 1 | E32: 8 | F32: 12 | G32: N/A | H32: Slay the Spire | I32: General | J32: Always: 50% 3 Dmg Melee / 50% Inflict 1 Weak | K32: AcidSlime(S) | L32: N/A | M32: slime
A33: Spike Slime (L) | B33: Charisma | C33: Low | D33: 4 | E33: 64 | F33: 70 | G33: Split 2 Spike Slime (M) | H33: Slay the Spire | I33: General | J33: Always: 30% 16 Dmg Melee, Add 2 Slimed to Discard / 70% Inflict 2 Frail | K33: SpikeSlime(L) | L33: N/A | M33: slime
A34: Spike Slime (M) | B34: Charisma | C34: Low | D34: 2 | E34: 28 | F34: 32 | G34: N/A | H34: Slay the Spire | I34: General | J34: Always: 30% 8 Dmg Melee, Add 1 Slimed to Discard / 70% Inflict 1 Frail | K34: SpikeSlime(M) | L34: N/A | M34: slime
A35: Spike Slime (S) | B35: Charisma | C35: Low | D35: 1 | E35: 10 | F35: 14 | G35: N/A | H35: Slay the Spire | I35: General | J35: Always: 5 Dmg Melee | K35: SpikeSlime(S) | L35: N/A | M35: slime

Sheet curses
A1: Name | B1: Stat | C1: Power | D1: Duration | E1: Description | F1: Type
A2: Curse of Devotion I | B2: Charisma | C2: Low | D2: Until 2 Games Beaten | E2: Every time you reset a run, lose 1 health | F2: Manual
A3: Curse of Devotion II | B3: Charisma | C3: Medium | D3: Until 2 Games Beaten | E3: Every time you reset a run, lose 3 health | F3: Manual
A4: Curse of Devotion III | B4: Charisma | C4: High | D4: Until 2 Games Beaten | E4: Every time you reset a run, lose 5 health | F4: Manual
A5: Curse of Greed I | B5: Charisma | C5: Low | D5: Until 2 Games Beaten | E5: Every time you skip an upgrade/item choice in game, lose 1 health | F5: Manual
A6: Curse of Greed II | B6: Charisma | C6: Medium | D6: Until 2 Games Beaten | E6: Every time you skip an upgrade/item choice in game, lose 3 health | F6: Manual
A7: Curse of Greed III | B7: Charisma | C7: High | D7: Until 2 Games Beaten | E7: Every time you skip an upgrade/item choice in game, lose 5 health | F7: Manual
A8: Curse of Impulse I | B8: Charisma | C8: Low | D8: Until 1 Game Beaten | E8: When given options for upgrades/items, if you don't take the option that is the topmost, the leftmost, or what the cursor is set to, lose 1 health | F8: Manual
A9: Curse of Impulse II | B9: Charisma | C9: Medium | D9: Until 1 Game Beaten | E9: When given options for upgrades/items, if you don't take the option that is the topmost, the leftmost, or what the cursor is set to, lose 3 health | F9: Manual
A10: Curse of Impulse III | B10: Charisma | C10: High | D10: Until 1 Game Beaten | E10: When given options for upgrades/items, if you don't take the option that is the topmost, the leftmost, or what the cursor is set to, lose 5 health | F10: Manual
A11: Curse of Haste I | B11: Dexterity | C11: Low | D11: Until 1 Game Beaten | E11: If you don't beat the next game within 4 hours, lose 3 Health | F11: Manual
A12: Curse of Haste II | B12: Dexterity | C12: Medium | D12: Until 1 Game Beaten | E12: If you don't beat the next game within 3 hours, lose 3 Health | F12: Manual
... A58: Curse of Misfortune III | B58: Charisma | C58: High | D58: 3 Rolls | E58: Gain Disadvantage on the next roll | F58: Auto

Sheet allies
A1: Name | B1: Type | C1: Rarity | D1: HP | E1: Ability | F1: Game | G1: Dice Face 1 | H1: Dice Face 2 | I1: Dice Face 3 | J1: Dice Face 4 | K1: Dice Face 5 | L1: Dice Face 6 | M1: File
A2: Clumsy | B2: Hero | C2: Low | D2: 6 | E2: N/A | F2: Slice & Dice | G2: 1 Pain Cantrip | H2: 1 Pain Cantrip | I2: 1 Dmg Cleave | J2: 1 Dmg Cleave | K2: 1 Dmg Cantrip | L2: 1 Dmg Cantrip | M2: Clumsy
A3: Mystic | B3: Hero | C3: Low | D3: 4 | E3: As long as Mystic is alive, Gain the spell Gaze | F3: Slice & Dice | G3: X | H3: 1 Mana | I3: 1 Heal, 1 Mana | J3: 1 Heal, 1 Mana | K3: 1 Heal, 1 Mana | L3: 1 Heal, 1 Mana, 1 Block | M3: Mystic

Sheet gamestatuses
A1: Name | B1: Description | C1: Type
A2: Charmed | B2: When landed on, get Curse of Affection scaled by difficulty | C2: Negative
A3: Devilish | B3: When landed on, lose +2 health | C3: Negative
A4: Holy | B4: When landed on, gain +2 health | C4: Positive
A5: Marked | B5: When landed on, get Curse of the Hunter scaled by difficulty | C5: Negative
A6: Portal | B6: Creates a portal connection on a game space. When more than one portal exists, those games become directly connected to each other | C6: Positive
A7: Shielded | B7: When landed on, get Curse of Obstruction scaled by difficulty | C7: Negative
A8: Shocked | B8: When landed on, get Curse of the Dazed scaled by difficulty | C8: Negative
A9: Soaked | B9: When landed on, get Curse of the Damp scaled by difficulty | C9: Negative
A10: Stinky | B10: Games marked as "stinky" are deprioritized in selections, they appear last in the game choice list unless they're the only option available | C10: Neutral
A11: Timed | B11: When landed on, get Curse of Haste scaled by difficulty | C11: Negative

Sheet locations
A1: Name | B1: Difficulty | C1: Game | D1: Type | E1: Effect
A2: Keep of the Lead Lord | B2: Low | C2: Enter the Gungeon | D2: Building | E2: Guns are 20% more likely to show up
A3: Black Powder Mine | B3: Medium | C3: Enter the Gungeon | D3: Underground | E3: Guns are 20% more likely to show up
A4: Hollow | B4: Medium | C4: Enter the Gungeon | D4: Icy | E4: Guns are 20% more likely to show up
A5: Forge | B5: Hard | C5: Enter the Gungeon | D5: Firey | E5: Guns are 20% more likely to show up
A6: Bullet Hell | B6: Hard | C6: Enter the Gungeon | D6: Undead | E6: Guns are 20% more likely to show up
A7: Basement | B7: Low | C7: The Binding of Isaac | D7: Building | E7: All games in this Location have a 10% chance to be Holy, Devilish, or Stinky
A8: Burning Basement | B8: Low | C8: The Binding of Isaac | D8: Fiery | E8: All games in this Location have a 10% chance to be Holy, Devilish, or Stinky
A9: Dross | B9: Low | C9: The Binding of Isaac | D9: Sewage | E9: All games in this Location have a 10% chance to be Holy, Devilish, or Stinky
A10: Caves | B10: Medium | C10: The Binding of Isaac | D10: Underground | E10: All games in this Location have a 10% chance to be Holy, Devilish, or Stinky
A11: Flooded Caves | B11: Medium | C11: The Binding of Isaac | D11: Watery | E11: All games in this Location have a 10% chance to be Holy, Devilish, or Stinky
A12: Necropolis | B12: Medium | C12: The Binding of Isaac | D12: Undead | E12: All games in this Location have a 10% chance to be Holy, Devilish, or Stinky
... A39: The Garden | B39: Hard | C39: Brutal Orchestra | D39: Chaos | E39: All Enemies have Pigment Rich.

Sheet statuses
A1: Name | B1: Description | C1: Type | D1: Stackable | E1: Max Stack | F1: Decay | G1: Who | H1: Preference | I1: File | J1: Rarity | K1: File2
A2: Burn | B2: Deals 3 damage to target at the end of turn | C2: Debuff | D2: Yes | E2: N/A | F2: Down by 1 at end of turn | G2: All | H2: Negative | I2: Burn | J2: Common | K2: N/A
A3: Poison | B3: Deals X damage to any target where X is the stack at the start of turn | C3: Debuff | D3: Yes | E3: N/A | F3: Down by 1 at end of turn | G3: All | H3: Negative | I3: Poison | J3: Common | K3: N/A
A4: Dodge | B4: Negate the next X sources of damage where X is the stack | C4: Buff | D4: Yes | E4: N/A | F4: Down when player was going to lose health | G4: All | H4: Positive | I4: Dodge | J4: Rare | K4: N/A
A5: Power | B5: Raise or Lower the damage dealth by this target by X | C5: Buff | D5: Yes | E5: N/A | F5: None | G5: All | H5: Positive | I5: Power | J5: Uncommon | K5: N/A
A6: Oiled | B6: Burn deals double damage, and at end of turn, Dex save 10 or Lose 1 Energy | C6: Debuff | D6: Yes | E6: N/A | F6: Down by 1 at end of turn | G6: All | H6: Negative | I6: Oiled | J6: N/A | K6: N/A
A7: Forgetful | B7: This enemy cannot repeat any of its intents until it has performed all of them. | C7: Ability | D7: No | E7: N/A | F7: Down by 1 when all sides have been rolled | G7: Enemy | H7: Negative | I7: Forgetful | J7: N/A | K7: N/A
A8: Barricade | B8: Block goes down by half at end of turn | C8: Ability | D8: No | E8: N/A | F8: None | G8: All | H8: Positive | I8: Barricade | J8: Rare | K8: N/A
A9: Ruptured | B9: Deals 3 damage to the player when they use a dash to gain dodge | C9: Debuff | D9: Yes | E9: N/A | F9: Down by 1 when dash is used | G9: All | H9: Negative | I9: Ruptured | J9: N/A | K9: N/A
A10: Frail | B10: All damage deals double to target | C10: Debuff | D10: Yes | E10: N/A | F10: Down by 1 at end of turn | G10: All | H10: Negative | I10: Frail | J10: Rare | K10: N/A
A11: Formless | B11: When dealt damage, change it's intent | C11: Ability | D11: No | E11: N/A | F11: None | G11: Enemy | H11: Neutral | I11: Formless | J11: N/A | K11: N/A
A12: Multi Attack X | B12: This enemy has X amount of intents in a turn | C12: Ability | D12: No | E12: N/A | F12: None | G12: Enemy | H12: Positive | I12: MultiAttack | J12: N/A | K12: N/A
... A19: Weak | B19: Target deals 25% less damage. | C19: Debuff | D19: Yes | E19: N/A | F19: Down by 1 at end of turn | G19: All | H19: Negative | I19: Weak | J19: Common | K19: N/A
A20: Stun | B20: The enemy's intent will be changed to "Stunned" and will do nothing on this turn | C20: Debuff | D20: No | E20: 1 | F20: Down by 1 at end of turn | G20: Enemy | H20: Negative | I20: Stun | J20: N/A | K20: N/A
A21: Unknown | B21: This enemy intends to do something specific | C21: Intent | D21: No | E21: N/A | F21: None | G21: Enemy | H21: Neutral | I21: Unknown | J21: N/A | K21: N/A
A22: Stagger X | B22: Target will gain Stun when hit with X% of Total Health lost in one hit | C22: Ability | D22: No | E22: N/A | F22: None | G22: Enemy | H22: Negative | I22: Stun | J22: N/A | K22: N/A
A23: Pigment Rich | B23: When hit, add a random pigment card to your hand. | C23: Ability | D23: No | E23: N/A | F23: None | G23: Enemy | H23: Neutral | I23: PigmentRich | J23: N/A | K23: N/A
A24: Rerollable | B24: Attacks from this enemy can be rerolled costing 1 Reroll | C24: Ability | D24: No | E24: N/A | F24: None | G24: Enemy | H24: Neutral | I24: Rerollable | J24: N/A | K24: N/A
A25: Rust | B25: If this enemy does damage that causes the player to lose health, Downgrade a random passive item | C25: Ability | D25: No | E25: N/A | F25: None | G25: Enemy | H25: Neutral | I25: Rust | J25: N/A | K25: N/A
A26: Brace | B26: Target takes 1 less damage from all sources per stack. (minimum 1) | C26: Buff | D26: Yes | E26: N/A | F26: None | G26: All | H26: Positive | I26: Brace | J26: Common | K26: N/A
A27: Bruise | B27: Increases all melee and ranged damage taken by 1 per stack. | C27: Debuff | D27: Yes | E27: N/A | F27: None | G27: All | H27: Negative | I27: Bruise | J27: Common | K27: N/A
A28: Leeches | B28: Drains 1 health per stack from all afflicted units at the end of the applier's turn and gives it to the applier. When hovering, it will say "X's Leeches" | C28: Debuff | D28: Yes | E28: N/A | F28: None | G28: All | H28: Negative | I28: Leeches | J28: Uncommon | K28: N/A
A29: Soul Link | B29: Whenever a soul linked target loses health, all soul linked characters lose that health as well. | C29: Debuff | D29: No | E29: N/A | F29: None | G29: All | H29: Negative | I29: SoulLink | J29: Rare | K29: N/A
A30: Holy Shield | B30: The next time this unit gets hit, take no damage and lose 1 Holy Shield. This takes precedence over Block | C30: Buff | D30: Yes | E30: N/A | F30: When the target would take damage | G30: All | H30: Positive | I30: HolyShield | J30: Rare | K30: N/A
A31: Regeneration | B31: At the end of target's turn, it gains X health where X is the stack | C31: Buff | D31: Yes | E31: N/A | F31: Down by 1 at end of turn | G31: All | H31: Positive | I31: Regeneration | J31: Uncommon | K31: N/A
A32: Defense | B32: Raise or Lower the Block gained by this target by X | C32: Buff | D32: Yes | E32: N/A | F32: None | G32: All | H32: Positive | I32: Defense | J32: Uncommon | K32: N/A
... A34: Split | B34: When target's health is at or below 50%, it's intent will become Unknown Intent ("Splitting") and Spawn X Y with its current HP on it's turn | C34: Ability | D34: No | E34: N/A | F34: None | G34: Enemy | H34: Positive | I34: Split | J34: N/A | K34: N/A

Sheet moves
A1: Name | B1: Description | C1: Preferred Target | D1: File | E1: Scaling | F1: Rarity
A2: Dmg | B2: Deals X damage to target | C2: Enemy | D2: Attack | E2: Strength | F2: Common
A3: Block | B3: Give target X block, X amount of damage a target can take before it affects their health | C3: Ally/Self | D3: Defense | E3: Dexterity | F3: Common
A4: Reroll | B4: Gains X rerolls | C4: Self | D4: Status | E4: Charisma | F4: Rare
A5: Heal | B5: Give target X health | C5: Ally/Self | D5: Health | E5: Intelligence | F5: Uncommon
A6: Spawn X Y | B6: Spawn X number of Y where X is the number of creatures and Y is the name of a creature. If used by enemies, the new enemy will have the Unknown intent showing "Spawning" | C6: Self | D6: Status | E6: N/A | F6: N/A
A7: Alter | B7: Alter target into X with the same Health as the original target, but Max Health of X | C7: Self | D7: Status | E7: N/A | F7: N/A
A8: Get | B8: Give X status to self | C8: Self | D8: Status | E8: Charisma | F8: Common
A9: Inflict | B9: Inflict X status to target | C9: Enemy | D9: Status | E9: Charisma | F9: Common
A10: Cleanse | B10: Removes X stacks of all debuff statuses | C10: Ally/Self | D10: Status | E10: Charisma | F10: Uncommon
A11: Mana | B11: Gain X Mana | C11: Self | D11: Mana | E11: Intelligence | F11: Common
A12: Pain | B12: Target Deals X damage to self (not Melee or Ranged) | C12: Self | D12: Status | E12: Strength | F12: N/A
... A18: Lose | B18: Target loses X status Y times (# or All) | C18: Self | D18: Status | E18: N/A | F18: N/A

Sheet addons
A1: Name | B1: Description | C1: Can Be Attached To | D1: Forms
A2: Cantrip | B2: Whenever this side is rolled, trigger its effect immediately (to a random preferred target) | C2: All | D2: N/A
A3: Ranged | B3: Ignores effects come from contact | C3: Attack, Status | D3: N/A
A4: Multiply X | B4: Multiplies this side by X (Example: 2 Damage Multi 2) | C4: All | D4: N/A
A5: Overload | B5: Applies this to every target (both the player/allies and enemies). Adding ExceptLeft or ExceptRight will allow an enemy to hit everything except any other enemy targets to it's left or right | C5: All | D5: OverloadExceptLeft, OverloadExceptRight
A6: Cleave | B6: Applies this to target and every target on it's side (Allies or Enemies) | C6: All | D6: N/A
A7: Engage | B7: x2 on targets with full health | C7: All | D7: N/A
A8: Finesse | B8: This weapon scales damage with Dexterity instead of Strength | C8: Weapon | D8: N/A
A9: Fishing Weight | B9: Gain +1 Dmg for every 3 Common, 2 Uncommon, or 1 Rare fish in your loot inventory | C9: Weapon | D9: N/A
A10: Wealth | B10: Add +1 for every 10 Gold the player has | C10: All | D10: N/A
A11: Indiscriminate | B11: Will use random applicable targets | C11: All | D11: N/A
A12: Infuse X | B12: If this kills an enemy, gain X Max Health | C12: All | D12: N/A
... A16: Ethereal | B16: If an Ethereal card is in your hand at the end of your turn, it is Exhausted. | C16: Cards | D16: N/A

Sheet spells
A1: Name | B1: Cost | C1: Rarity | D1: Description | E1: Keywords | F1: Bonus | G1: Game | H1: Element | I1: File
A2: Poultice | B2: 1 | C2: Common | D2: 2 Heal | E2: SingleCast | F2: Yes | G2: Slice & Dice | H2: Earth | I2: Poultice
A3: Remedy | B3: 1 | C3: Common | D3: 1 Heal, 1 Cleanse | E3: SingleCast | F3: Yes | G3: Slice & Dice | H3: Earth | I3: Remedy
A4: Sprout | B4: 3 | C4: Common | D4: 3 Heal | E4: Channel | F4: Yes | G4: Slice & Dice | H4: Earth | I4: Sprout
A5: Abyss | B5: 5 | C5: Uncommon | D5: Kill an enemy with half or less health | E5: N/A | F5: No | G5: Slice & Dice | H5: Dark | I5: Abyss
A6: Infinity | B6: 13 | C6: Rare | D6: Kill an enemy | E6: N/A | F6: No | G6: Slice & Dice | H6: N/A | I6: Infinity
A7: Harvest | B7: 1 | C7: Rare | D7: Kill an enemy with exactly 1 health, then Gain 3 mana | E7: Cooldown | F7: No | G7: Slice & Dice | H7: Blood | I7: Harvest
A8: Miasma | B8: 3 | C8: Rare | D8: 1 Dmg Cleave, 1 Poison Cleave | E8: N/A | F8: Yes | G8: Slice & Dice | H8: Poison | I8: Miasma
A9: Scald | B9: 3 | C9: Uncommon | D9: 2 Dmg to all damaged enemies | E9: N/A | F9: Yes | G9: Slice & Dice | H9: Water | I9: Scald
A10: Blaze | B10: 6 | C10: Rare | D10: 13 Dmg | E10: N/A | F10: Yes | G10: Slice & Dice | H10: Fire | I10: Blaze
A11: Crush | B11: 3 | C11: Rare | D11: 3 Dmg to leftmost and rightmost enemy | E11: N/A | F11: Yes | G11: Slice & Dice | H11: N/A | I11: Crush
A12: Burn | B12: 1 | C12: Uncommon | D12: 1 Dmg Overload | E12: N/A | F12: Yes | G12: Slice & Dice | H12: Fire | I12: Burn
A13: Bind | B13: 3 | C13: Rare | D13: Self/Ally gains 1 Dodge | E13: Deplete | F13: Yes | G13: Slice & Dice | H13: N/A | I13: Bind
... A20: Gaze | B20: 1 | C20: Common | D20: Gain 1 Reroll | E20: Future | F20: No | G20: Slice & Dice | H20: N/A | I20: Gaze

Sheet spellkeywords
A1: Name | B1: Description
A2: SingleCast | B2: Only usable once per combat
A3: Channel | B3: Costs 1 less mana each time it's cast (minimum 1)
A4: Cooldown | B4: Only usable once per turn
A5: Deplete | B5: Costs 1 more mana each time it's cast
A6: Future | B6: Effect is delayed until the start of the next turn

Sheet fish
A1: Name | B1: Rarity | C1: Types | D1: Game | E1: Image
A2: Hellfish | B2: Common | C2: Undead | D2: Hades | E2: hellfish
A3: Knucklehead | B3: Uncommon | C3: Undead | D3: Hades | E3: knucklehead
A4: Scyllascion | B4: Rare | C4: Undead | D4: Hades | E4: scyllascion
A5: Slavug | B5: Common | C5: Firey | D5: Hades | E5: slavug
A6: Chrustacean | B6: Uncommon | C6: Firey | D6: Hades | E6: chrustacean
A7: Flameater | B7: Rare | C7: Firey | D7: Hades | E7: flameater
A8: Chlam | B8: Common | C8: Watery | D8: Hades | E8: chlam
A9: Charp | B9: Uncommon | C9: Watery | D9: Hades | E9: charp
A10: Seamare | B10: Rare | C10: Watery | D10: Hades | E10: seamare
A11: Gupp | B11: Common | C11: Building | D11: Hades | E11: gupp
A12: Scuffer | B12: Uncommon | C12: Building | D12: Hades | E12: scuffer
... A39: Styxeon | B39: Rare | C39: Undead | D39: Hades II | E39: styxeon

Sheet bingo
A1: Goal | B1: Difficulty
A2: Beat a boss with 1 Health left | B2: Easy
A3: Defeat 15 Skeletons | B3: Easy
A4: Defeat 15 Zombies | B4: Easy
A5: Defeat an enemy with a ball | B5: Easy
A6: Get drunk | B6: Easy
A7: Obtain a mushroom | B7: Easy
A8: Pet a pet | B8: Easy
A9: Trade Health for resources | B9: Easy
A10: Unlock a new Character | B10: Easy
A11: Worship an altar | B11: Easy
A12: Beat a run without moving | B12: Hard
... A40: Use elements to your advantage | B40: Normal

Sheet cards
A1: Name | B1: Rarity | C1: Cost | D1: Type | E1: Description | F1: Upgraded Description | G1: Upgraded Cost | H1: Img | I1: Game | J1: Tags
A2: Strike | B2: Starter | C2: 1 | D2: Attack | E2: Deal 6 Dmg Melee. | F2: Deal 9 Dmg Melee. | G2: 1 | H2: N/A | I2: N/A
A3: Defend | B3: Starter | C3: 1 | D3: Skill | E3: Gain 5 Block. | F3: Gain 8 Block. | G3: 1 | H3: N/A | I3: N/A
A4: Bash | B4: Starter | C4: 2 | D4: Attack | E4: Deal 8 Dmg Melee. Inflict 2 Vulnerable. | F4: Deal 10 Dmg Melee. Apply 3 Vulnerable. | G4: 2 | H4: Bash | I4: Slay the Spire | J4: ironclad
A5: Feed | B5: Rare | C5: 1 | D5: Attack | E5: Deal 10 Dmg Melee. Infuse 3. Exhaust. | F5: Deal 12 Dmg Melee. Infuse 4. Exhaust. | G5: 1 | H5: Feed | I5: Slay the Spire | J5: ironclad
A6: Shrug It Off | B6: Common | C6: 1 | D6: Skill | E6: Gain 8 Block. Draw 1 Card. | F6: Gain 11 Block. Draw 1 card. | G6: 1 | H6: ShrugItOff | I6: Slay the Spire | J6: ironclad
A7: Pommel Strike | B7: Common | C7: 1 | D7: Attack | E7: Deal 9 Dmg Melee. Draw 1 card. | F7: Deal 10 Dmg Melee. Draw 2 cards. | G7: 1 | H7: PommelStrike | I7: Slay the Spire | J7: ironclad
A8: Disarm | B8: Uncommon | C8: 1 | D8: Skill | E8: Inflict -2 Power to Target. Exhaust. | F8: Inflict -3 Power to Target. Exhaust. | G8: 1 | H8: Disarm | I8: Slay the Spire | J8: ironclad
A9: Isaac's D6 | B9: Starter | C9: 1 | D9: Dice | E9: 1: Gain random curse from the current difficulty. 2: Take 3 Dmg 3: Gain 5 Block 4: Heal 3 Health 5: Draw 1 Card 6: Gain a Random Common Item | F9: 1: Gain 2 random curses from the current difficulty. 2: Take 5 Dmg 3: Gain 8 Block 4: Heal 3 Health 5: Draw 2 Cards 6: Gain a Random Item | G9: 1 | H9: N/A | I9: The Binding of Isaac
A10: Demon Form | B10: Rare | C10: 3 | D10: Power | E10: At the start of each turn, gain 2 Power. | F10: At the start of each turn, gain 3 Power. | G10: 3 | H10: DemonForm | I10: Slay the Spire | J10: ironclad
A11: Bloodletting | B11: Uncommon | C11: 0 | D11: Skill | E11: Lose 3 Health. Gain 2 Energy. | F11: Lose 3 Health. Gain 3 Energy. | G11: 0 | H11: Bloodletting | I11: Slay the Spire | J11: ironclad
A12: Barrel | B12: Uncommon | C12: 1 | D12: Attack | E12: Deal 5 Dmg Ranged. Fishing Weight. | F12: Deal 5 Dmg Ranged. Fishing Weight. | G12: 1 | H12: Barrel | I12: Enter the Gungeon | J12: weapon
A13: Blasma Pistol | B13: Common | C13: 1 | D13: Attack | E13: Deal 2 Dmg Ranged. Wealth. | F13: Deal 2 Dmg Ranged. Wealth. | G13: 1 | H13: BlasmaPistol | I13: Flinthook | J13: weapon
A14: Lil' Bomber | B14: Common | C14: 1 | D14: Attack | E14: Deal 3 Dmg Ranged. | F14: Deal 3 Dmg Ranged. | G14: 1 | H14: LilBomber | I14: Enter the Gungeon | J14: weapon
A15: Blood Magic | B15: Rare | C15: 1 | D15: Attack | E15: Deal 2x3 Dmg Ranged. Indiscriminate. 2 Infuse. | F15: Deal 2x3 Dmg Ranged. Indiscriminate. 2 Infuse. | G15: 1 | H15: BloodMagic | I15: Megabonk | J15: weapon
A16: Dexecutioner | B16: Uncommon | C16: 0 | D16: Attack | E16: 5 Assassinate. | F16: 5 Assassinate. | G16: 1 | H16: Dexecutioner | I16: Megabonk | J16: weapon
A17: Blue Pigment | B17: None | C17: 1 | D17: Status | E17: Gain +3 Intelligence until end of combat. Exhaust. | F17: N/A | G17: N/A | H17: BluePigment | I17: Brutal Orchestra | J17: pigment
A18: Purple Pigment | B18: None | C18: 1 | D18: Status | E18: Gain +3 Charisma until end of combat. Exhaust. | F18: N/A | G18: N/A | H18: PurplePigment | I18: Brutal Orchestra | J18: pigment
A19: Red Pigment | B19: None | C19: 1 | D19: Status | E19: Gain +3 Strength until end of combat. Exhaust. | F19: N/A | G19: N/A | H19: RedPigment | I19: Brutal Orchestra | J19: pigment
A20: Yellow Pigment | B20: None | C20: 1 | D20: Status | E20: Gain +3 Dexterity until end of combat. Exhaust. | F20: N/A | G20: N/A | H20: YellowPigment | I20: Brutal Orchestra | J20: pigment
A21: Barricade | B21: Rare | C21: 3 | D21: Power | E21: Gain Barricade. | F21: Gain Barricade. | G21: 2 | H21: Barricade | I21: Slay the Spire | J21: ironclad
A22: Claw | B22: Common | C22: 0 | D22: Attack | E22: Deal 3 Dmg Melee. Increase the damage of ALL Claw cards by 2 this combat. | F22: Deal 4 Dmg Melee. Increase the damage of ALL Claw cards by 3 this combat. | G22: 0 | H22: Claw | I22: Slay the Spire | J22: Defect
A23: Target Practice | B23: Uncommon | C23: 3 | D23: Training | E23: Permanently Gain +1 Strength and +2 Charisma. Destroy. | F23: Permanently Gain +2 Strength and +3 Charisma. Destroy. | G23: 3 | H23: TargetPractice | I23: Monmusu Gladiator
A24: Boulder Dodge | B24: Uncommon | C24: 3 | D24: Training | E24: Permanently Gain +1 Intelligence and +2 Dexterity. Destroy. | F24: Permanently Gain +2 Intelligence and +3 Dexterity. Destroy. | G24: 3 | H24: BoulderDodge | I24: Monmusu Gladiator
A25: Mock Battle | B25: Rare | C25: 5 | D25: Training | E25: Permanently Gain +2 Strength, Dexterity, Intelligence, and Charisma. Destroy. | F25: Permanently Gain +2 Strength, Dexterity, Intelligence, and Charisma. Destroy. | G25: 4 | H25: MockBattle | I25: Monmusu Gladiator
A26: Runner's High | B26: Uncommon | C26: 2 | D26: Training | E26: For every 10 Health you have under Max Health, Gain +2 Max Health. Destroy. | F26: For every 10 Health you have under Max Health, Gain +3 Max Health. Destroy. | G26: 2 | H26: Runner'sHigh | I26: Monmusu Gladiator
A27: Slimed | B27: None | C27: 1 | D27: Status | E27: Draw 1 card. Exhaust. | F27: N/A | G27: N/A | H27: Slimed | I27: Slay the Spire
A28: Cleave | B28: Common | C28: 1 | D28: Attack | E28: Deal 8 Dmg Melee Cleave. | F28: Deal 11 Dmg Melee Cleave. | G28: 1 | H28: Cleave | I28: Slay the Spire | J28: ironclad
A29: Clothesline | B29: Common | C29: 2 | D29: Attack | E29: Deal 12 Dmg Melee. Inflict 2 Weak. | F29: Deal 14 Dmg Melee. Inflict 3 Weak. | G29: 2 | H29: Clothesline | I29: Slay the Spire | J29: ironclad
A30: Carnage | B30: Uncommon | C30: 2 | D30: Attack | E30: Ethereal. Deal 20 Dmg Melee | F30: Ethereal. Deal 28 Dmg Melee. | G30: 2 | H30: Carnage | I30: Slay the Spire | J30: ironclad
A31: Inflame | B31: Uncommon | C31: 1 | D31: Power | E31: Gain 2 Power. | F31: Gain 3 Power. | G31: 1 | H31: Inflame | I31: Slay the Spire | J31: ironclad
A32: Twin Strike | B32: Common | C32: 1 | D32: Attack | E32: Deal 5x2 Dmg Melee. | F32: Deal 7x2 Dmg Melee. | G32: 1 | H32: TwinStrike | I32: Slay the Spire | J32: ironclad
A33: Uppercut | B33: Uncommon | C33: 2 | D33: Attack | E33: Deal 13 Dmg Melee. Inflict 1 Weak. Inflict 1 Vulnerable. | F33: Deal 13 Dmg Melee. Inflict 2 Weak. Inflict 2 Vulnerable. | G33: 2 | H33: Uppercut | I33: Slay the Spire | J33: ironclad
A34: Adrenaline | B34: Rare | C34: 0 | D34: Skill | E34: Gain 1 Energy. Draw 2 Cards. Exhaust. | F34: Gain 2 Energy. Draw 2 Cards. Exhaust. | G34: 0 | H34: Adrenaline | I34: Slay the Spire | J34: silent

Sheet amulet
A1: Name | B1: Part | C1: Rarity | D1: Effect | E1: Requirement
