Workbook

Sheet games
A1: Name | B1: Year | C1: Type | D1: Connected? | E1: Influencer? | F1: Tags | G1: File | H1: Owned | I1: File Location | J1: Steam Page
A2: [Redacted] | B2: 2024 | C2: Action | D2: =TRUE() -> TRUE | E2: =COUNTIF(connections!A:A, A2) > 0 -> FALSE | G2: redacted
A3: 100 Rogues | B3: 2010 | C3: Traditional | D3: =TRUE() -> TRUE | E3: =COUNTIF(connections!A:A, A3) > 0 -> TRUE | G3: 100-rogues
A4: 2 Fights in 2 Tight Spaces | B4: 2026 | C4: Deckbuilder | D4: =TRUE() -> TRUE | E4: =COUNTIF(connections!A:A, A4) > 0 -> FALSE | G4: 2-fights-in-2-tight-spaces | J4: https://store.steampowered.com/app/3734890/2_Fights_in_2_Tight_Spaces/
A5: 20 Minutes Till Dawn | B5: 2022 | C5: Action | D5: =TRUE() -> TRUE | E5: =COUNTIF(connections!A:A, A5) > 0 -> TRUE | G5: 20-minutes-till-dawn | H5: Yes | I5: C:\Users\Owner\Documents\Roguelike Roguelike\Roguelikes\20 Minutes Till Dawn.url | J5: https://store.steampowered.com/app/1966900/20_Minutes_Till_Dawn/
A6: 20XX | B6: 2017 | C6: Action | D6: =TRUE() -> TRUE | E6: =COUNTIF(connections!A:A, A6) > 0 -> TRUE | G6: 20xx | H6: Yes | I6: C:\Users\Owner\Documents\Roguelike Roguelike\Roguelikes\20XX.url | J6: https://store.steampowered.com/app/322110/20XX/
A7: 30XX | B7: 2021 | C7: Action | D7: =TRUE() -> TRUE | E7: =COUNTIF(connections!A:A, A7) > 0 -> FALSE | G7: 30xx | H7: Yes | I7: C:\Users\Owner\Documents\Roguelike Roguelike\Roguelikes\30XX.url | J7: https://store.steampowered.com/app/1029210/30XX/
A8: 33 Immortals | B8: 2026 | C8: Action | D8: =TRUE() -> TRUE | E8: =COUNTIF(connections!A:A, A8) > 0 -> FALSE | F8: hell | G8: 33-immortals | H8: Yes | I8: C:\Users\Owner\Documents\Roguelike Roguelike\Roguelikes\33 Immortals.url | J8: https://store.steampowered.com/app/958520/33_Immortals/
A9: 868-Back | B9: 2026 | C9: Traditional | D9: =TRUE() -> TRUE | E9: =COUNTIF(connections!A:A, A9) > 0 -> FALSE | G9: 868-back | J9: https://store.steampowered.com/app/3304110/868BACK/
A10: 868-Hack | B10: 2015 | C10: Traditional | D10: =TRUE() -> TRUE | E10: =COUNTIF(connections!A:A, A10) > 0 -> TRUE | G10: 868-hack | H10: Yes | I10: C:\Users\Owner\Documents\Roguelike Roguelike\Roguelikes\868-HACK.url | J10: https://store.steampowered.com/app/274700/868HACK/
A11: 9 Kings | B11: 2024 | C11: Deckbuilder | D11: =TRUE() -> TRUE | E11: =COUNTIF(connections!A:A, A11) > 0 -> TRUE | G11: 9-kings | H11: Yes | I11: C:\Users\Owner\Documents\Roguelike Roguelike\Roguelikes\9 Kings.url | J11: https://store.steampowered.com/app/2784470/9_Kings/
A12: 99 Levels to Hell | B12: 2013 | C12: Action | D12: =TRUE() -> TRUE | E12: =COUNTIF(connections!A:A, A12) > 0 -> FALSE | F12: hell | G12: 99-levels-to-hell
A13: A la Card | B13: 2025 | C13: Deckbuilder | D13: =TRUE() -> TRUE | E13: =COUNTIF(connections!A:A, A13) > 0 -> FALSE | G13: a-la-card
A14: A Robot Named Fight! | B14: 2017 | C14: Action | D14: =TRUE() -> TRUE | E14: =COUNTIF(connections!A:A, A14) > 0 -> FALSE | G14: a-robot-named-fight | H14: Yes | I14: C:\Users\Owner\Documents\Roguelike Roguelike\Roguelikes\A Robot Named Fight.url | J14: https://store.steampowered.com/app/603530/A_Robot_Named_Fight/
A15: Abandon Ship | B15: 2019 | C15: Strategy | D15: =TRUE() -> TRUE | E15: =COUNTIF(connections!A:A, A15) > 0 -> FALSE | G15: abandon-ship | H15: Yes | I15: C:\Users\Owner\Documents\Roguelike Roguelike\Roguelikes\Abandon Ship.url | J15: https://store.steampowered.com/app/551860/Abandon_Ship/
A16: Abandoned Archive | B16: 2025 | C16: Action | D16: =TRUE() -> TRUE | E16: =COUNTIF(connections!A:A, A16) > 0 -> FALSE | G16: abandoned-archive
A17: Absolum | B17: 2025 | C17: Action | D17: =TRUE() -> TRUE | E17: =COUNTIF(connections!A:A, A17) > 0 -> FALSE | F17: beat 'em up | G17: absolum | H17: Yes | I17: C:\Users\Owner\Documents\Roguelike Roguelike\Roguelikes\Absolum.url | J17: https://store.steampowered.com/app/1904480/Absolum/
A18: Abyssus | B18: 2025 | C18: Action | D18: =TRUE() -> TRUE | E18: =COUNTIF(connections!A:A, A18) > 0 -> FALSE | G18: abyssus | H18: Yes | I18: C:\Users\Owner\Documents\Roguelike Roguelike\Roguelikes\Abyssus.url | J18: https://store.steampowered.com/app/1721110/Abyssus/
A19: Aces & Adventures | B19: 2023 | C19: Deckbuilder | D19: =TRUE() -> TRUE | E19: =COUNTIF(connections!A:A, A19) > 0 -> FALSE | G19: aces-adventures | H19: Yes | I19: C:\Users\Owner\Documents\Roguelike Roguelike\Roguelikes\Aces and Adventures.url | J19: https://store.steampowered.com/app/1815570/Aces__Adventures/
A20: Across the Obelisk | B20: 2021 | C20: Deckbuilder | D20: =TRUE() -> TRUE | E20: =COUNTIF(connections!A:A, A20) > 0 -> TRUE | G20: across-the-obelisk | H20: Yes | I20: C:\Users\Owner\Documents\Roguelike Roguelike\Roguelikes\Across the Obelisk.url | J20: https://store.steampowered.com/app/1385380/Across_the_Obelisk/
A21: Aethermancer | B21: 2025 | C21: Strategy | D21: =TRUE() -> TRUE | E21: =COUNTIF(connections!A:A, A21) > 0 -> TRUE | G21: aethermancer | H21: Yes | I21: C:\Users\Owner\Documents\Roguelike Roguelike\Roguelikes\Aethermancer.url | J21: https://store.steampowered.com/app/2288470/Aethermancer/
A22: AK-xolotl | B22: 2023 | C22: Action | D22: =TRUE() -> TRUE | E22: =COUNTIF(connections!A:A, A22) > 0 -> FALSE | G22: ak-xolotl | H22: Yes | I22: C:\Users\Owner\Documents\Roguelike Roguelike\Roguelikes\AK-xolotl Together.url | J22: https://store.steampowered.com/app/1479140/AKxolotl_Together/
A23: Alina of the Arena | B23: 2022 | C23: Deckbuilder | D23: =TRUE() -> TRUE | E23: =COUNTIF(connections!A:A, A23) > 0 -> FALSE | G23: alina-of-the-arena | H23: Yes | I23: C:\Users\Owner\Documents\Roguelike Roguelike\Roguelikes\Alina of the Arena.url | J23: https://store.steampowered.com/app/1668690/Alina_of_the_Arena/
A24: An Amazing Wizard | B24: 2025 | C24: Action | D24: =TRUE() -> TRUE | E24: =COUNTIF(connections!A:A, A24) > 0 -> FALSE | G24: an-amazing-wizard | J24: https://store.steampowered.com/app/1372660/An_Amazing_Wizard/
A25: Ancient Domains of Mystery | B25: 1994 | C25: Traditional | D25: =TRUE() -> TRUE | E25: =COUNTIF(connections!A:A, A25) > 0 -> TRUE | G25: ancient-domains-of-mystery | H25: Yes | I25: C:\Users\Owner\Documents\Roguelike Roguelike\Roguelikes\ADOM (Ancient Domains Of Mystery).url | J25: https://store.steampowered.com/app/333300/ADOM_Ancient_Domains_Of_Mystery/
A26: Angband | B26: 1990 | C26: Traditional | D26: =TRUE() -> TRUE | E26: =COUNTIF(connections!A:A, A26) > 0 -> TRUE | G26: angband | H26: Yes | I26: C:\Users\Owner\Documents\Roguelike Roguelike\Roguelikes\angband.lnk
A27: Anomaly Collapse | B27: 2024 | C27: Strategy | D27: =TRUE() -> TRUE | E27: =COUNTIF(connections!A:A, A27) > 0 -> FALSE | G27: anomaly-collapse | J27: https://store.steampowered.com/app/2082410/Anomaly_Collapse/
A28: Another Farm Roguelike | B28: 2022 | C28: Strategy | D28: =FALSE() -> FALSE | E28: =COUNTIF(connections!A:A, A28) > 0 -> TRUE | F28: food | G28: another-farm-roguelike | H28: Yes | I28: C:\Users\Owner\Documents\Roguelike Roguelike\Roguelikes\Another Farm Roguelike.url | J28: https://store.steampowered.com/app/2116850/Another_Farm_Roguelike/
A29: Another Farm Roguelike: Rebirth | B29: 2025 | C29: Strategy | D29: =FALSE() -> FALSE | E29: =COUNTIF(connections!A:A, A29) > 0 -> FALSE | F29: food | G29: another-farm-roguelike-rebirth
A30: Aotenjo: Infinite Hands | B30: 2024 | C30: Deckbuilder | D30: =TRUE() -> TRUE | E30: =COUNTIF(connections!A:A, A30) > 0 -> FALSE | F30: mahjong | G30: aotenjo-infinite-hands
A31: Approaching Infinity | B31: 2020 | C31: Traditional | D31: =TRUE() -> TRUE | E31: =COUNTIF(connections!A:A, A31) > 0 -> FALSE | F31: space | G31: approaching-infinity
A32: Arc Seed | B32: 2024 | C32: Deckbuilder | D32: =TRUE() -> TRUE | E32: =COUNTIF(connections!A:A, A32) > 0 -> FALSE | F32: mecha | G32: arc-seed | H32: Yes | I32: C:\Users\Owner\Documents\Roguelike Roguelike\Roguelikes\ARC SEED.url | J32: https://store.steampowered.com/app/2332970/ARC_SEED/
A33: Arcane Trigger | B33: 2025 | C33: Action | D33: TRUE | E33: =COUNTIF(connections!A:A, A33) > 0 -> FALSE | G33: arcane-trigger
A34: Arcanium: Rise of Akhan | B34: 2020 | C34: Deckbuilder | D34: =TRUE() -> TRUE | E34: =COUNTIF(connections!A:A, A34) > 0 -> FALSE | G34: arcanium-rise-of-akhan | H34: Yes | I34: C:\Users\Owner\Documents\Roguelike Roguelike\Roguelikes\Arcanium.url | J34: https://store.steampowered.com/app/1056840/Arcanium_Rise_of_Akhan/
A35: Archon Soul | B35: 2026 | C35: Deckbuilder | D35: =TRUE() -> TRUE | E35: =COUNTIF(connections!A:A, A35) > 0 -> FALSE | G35: archon-soul | J35: https://store.steampowered.com/app/4252700/Archon_Soul/
A36: Archons | B36: 2024 | C36: Action | D36: =TRUE() -> TRUE | E36: =COUNTIF(connections!A:A, A36) > 0 -> FALSE | G36: archons | H36: Yes | I36: C:\Users\Owner\Documents\Roguelike Roguelike\Roguelikes\Archons.url | J36: https://store.steampowered.com/app/2779570/Archons/
A37: Arms of God | B37: 2026 | C37: Action | D37: =TRUE() -> TRUE | E37: =COUNTIF(connections!A:A, A37) > 0 -> FALSE | G37: arms-of-god | J37: https://store.steampowered.com/app/3100310/Arms_of_God/
A38: Army of Ruin | B38: 2022 | C38: Action | D38: =TRUE() -> TRUE | E38: =COUNTIF(connections!A:A, A38) > 0 -> FALSE | G38: army-of-ruin | H38: Yes | I38: C:\Users\Owner\Documents\Roguelike Roguelike\Roguelikes\Army of Ruin.url | J38: https://store.steampowered.com/app/1918040/Army_of_Ruin/
A39: Arrogue | B39: 2025 | C39: Deckbuilder | D39: =TRUE() -> TRUE | E39: =COUNTIF(connections!A:A, A39) > 0 -> FALSE | G39: arrogue
A40: As We Descend | B40: 2025 | C40: Deckbuilder | D40: =TRUE() -> TRUE | E40: =COUNTIF(connections!A:A, A40) > 0 -> FALSE | G40: as-we-descend
...

Sheet connections
A1: Influencer | B1: Influencee | C1: Influencer Time | D1: Dev/Series Relation | E1: Source | F1: Proof | G1: Needs Proof
A2: Hades | B2: [Redacted] | C2: 2019 | E2: look at it | F2: hades---redacted | G2: Yes
A3: Mystery Dungeon 2: Shiren the Wanderer | B3: 100 Rogues | C3: 1995 | E3: https://www.gamedeveloper.com/business/marketing-on-the-app-store-the-cautionary-tale-of-i-100-rogues-i- | F3: mystery_dungeon_2_shiren_the_wanderer---100_rogues | G3: No
A4: Powder | B4: 100 Rogues | C4: 2003 | E4: https://www.gamedeveloper.com/business/marketing-on-the-app-store-the-cautionary-tale-of-i-100-rogues-i- | F4: powder---100_rogues | G4: No
A5: Fights in Tight Spaces | B5: 2 Fights in 2 Tight Spaces | C5: 2021 | D5: Yes | F5: fights_in_tight_spaces---2_fights_in_2_tight_spaces | G5: No
A6: Nova Drift | B6: 20 Minutes Till Dawn | C6: 2019 | E6: https://www.gamebusiness.jp/article/2022/06/15/20252.html | F6: nova_drift---20_minutes_till_dawn | G6: No
A7: Vampire Survivors | B7: 20 Minutes Till Dawn | C7: 2021 | E7: look at it | F7: vampire_survivors---20_minutes_till_dawn | G7: No
A8: Crypt of the NecroDancer | B8: 20XX | C8: 2015 | E8: https://www.reddit.com/r/IAmA/comments/4po4pn/i_am_the_developer_of_20xx_the_megaman_xinspired/ | F8: crypt_of_the_necrodancer---20xx | G8: No
A9: The Binding of Isaac | B9: 20XX | C9: 2011 | E9: https://www.reddit.com/r/IAmA/comments/4po4pn/i_am_the_developer_of_20xx_the_megaman_xinspired/ | F9: the_binding_of_isaac---20xx | G9: No
A10: 20XX | B10: 30XX | C10: 2017 | D10: Yes | F10: 20xx---30xx | G10: No
A11: Realm of the Mad God | B11: 33 Immortals | C11: 2010 | E11: check folder | F11: realm_of_the_mad_god---33_immortals | G11: No
A12: Sundered | B12: 33 Immortals | C12: 2017 | D12: Yes | F12: sundered---33_immortals | G12: No
A13: 868-Hack | B13: 868-Back | C13: 2015 | D13: Yes | F13: 868_hack---868_back | G13: No
A14: Rogue | B14: 868-Hack | C14: 1980 | E14: https://www.gamedeveloper.com/design/how-michael-brough-s-love-of-exploring-a-single-game-mechanic-beget-i-cinco-paus-i- | F14: rogue---868_hack | G14: No
A15: Seraph's Last Stand | B15: 9 Kings | C15: 2022 | D15: Yes | F15: seraph_s_last_stand---9_kings | G15: No
A16: Slay the Spire | B16: 9 Kings | C16: 2017 | E16: https://www.youtube.com/watch?v=9fxnPkfyHuA | F16: slay_the_spire---9_kings | G16: No
A17: Spelunky Classic | B17: 99 Levels to Hell | C17: 2008 | E17: https://youtu.be/wJ2cgBoxsi4 | F17: spelunky_classic-the_binding_of_isaac---99_levels_to_hell | G17: No
A18: The Binding of Isaac | B18: 99 Levels to Hell | C18: 2011 | E18: https://youtu.be/wJ2cgBoxsi4 | F18: spelunky_classic-the_binding_of_isaac---99_levels_to_hell | G18: No
A19: Slay the Spire | B19: A la Card | C19: 2017 | E19: check folder | F19: slay_the_spire---a_la_card | G19: No
A20: The Binding of Isaac | B20: A Robot Named Fight! | C20: 2011 | E20: https://www.reddit.com/r/NintendoSwitch/comments/8jv8rd/im_matt_bitner_sole_developer_of_a_robot_named/#:~:text=I%20left%20my%20old%20job,as%20The%20Binding%20of%20Isaac. | F20: the_binding_of_isaac---a_robot_named_fight | G20: No
A21: FTL | B21: Abandon Ship | C21: 2012 | E21: https://bigbossbattle.com/abandon-ship-interview-fireblade-softwares-gary-burchell/ | F21: ftl---abandon_ship | G21: No
A22: Enter the Gungeon | B22: Abandoned Archive | C22: 2016 | E22: https://www.reddit.com/r/playmygame/comments/sqb852/our_spellcasting_roguelike_abandoned_archive_now/ | F22: enter_the_gungeon---abandoned_archive | G22: No
A23: Wizard of Legend | B23: Abandoned Archive | C23: 2018 | E23: https://www.reddit.com/r/playmygame/comments/sqb852/our_spellcasting_roguelike_abandoned_archive_now/ | F23: wizard_of_legend---abandoned_archive | G23: No
A24: Dead Cells | B24: Absolum | C24: 2018 | E24: https://www.polygon.com/absolum-roguelike-interview-dotemu-guard-crush/ | F24: dead_cells---absolum | G24: No
A25: Gunfire Reborn | B25: Abyssus | C25: 2020 | E25: https://steamcommunity.com/app/1721110/discussions/0/600775708393865281/ | F25: gunfire_reborn---abyssus | G25: No
A26: Nuclear Throne | B26: Abyssus | C26: 2015 | E26: https://steamcommunity.com/app/1721110/discussions/0/600775708393865281/ | F26: nuclear_throne---abyssus | G26: No
A27: Roboquest | B27: Abyssus | C27: 2020 | E27: https://steamcommunity.com/app/1721110/discussions/0/600775708393865281/ | F27: roboquest---abyssus | G27: No
A28: Popup Dungeon | B28: Aces & Adventures | C28: 2020 | D28: Yes | F28: popup_dungeon---aces_adventures | G28: No
A29: Slay the Spire | B29: Aces & Adventures | C29: 2017 | E29: https://creators.spotify.com/pod/show/the-indie-diarist/episodes/Indie-Diary-5-Enrique-Dryere-Triple-B-Titles---Creativity-as-Sacrifice--Secrets-of-Inspiration--DnD-and----Poker-e207m5b | F29: slay_the_spire---aces_adventures | G29: No
A30: Darkest Dungeon | B30: Across the Obelisk | C30: 2015 | E30: duh also check the folder for proof | F30: darkest_dungeon---across_the_obelisk | G30: No
A31: Slay the Spire | B31: Across the Obelisk | C31: 2017 | E31: duh also the devs talk about loving sts in discord | F31: slay_the_spire---across_the_obelisk | G31: Yes
A32: Dead Cells | B32: Aethermancer | C32: 2018 | E32: check folder | F32: dead_cells---aethermancer | G32: No
A33: Enter the Gungeon | B33: AK-xolotl | C33: 2016 | E33: https://www.reddit.com/r/Games/comments/v2kcsr/ama_were_the_team_behind_akxolotl_a_cute_but/ | F33: enter_the_gungeon---ak_xolotl | G33: No
A34: Nuclear Throne | B34: AK-xolotl | C34: 2015 | E34: https://www.reddit.com/r/Games/comments/v2kcsr/ama_were_the_team_behind_akxolotl_a_cute_but/ | F34: nuclear_throne---ak_xolotl | G34: No
A35: Into the Breach | B35: Alina of the Arena | C35: 2018 | E35: https://store.steampowered.com/app/1668690/Alina_of_the_Arena/#:~:text=About%20This%20Game-,ABOUT,and%20'Into%20the%20Breach'. | F35: into_the_breach---alina_of_the_arena | G35: No
A36: Slay the Spire | B36: Alina of the Arena | C36: 2017 | E36: https://store.steampowered.com/app/1668690/Alina_of_the_Arena/#:~:text=About%20This%20Game-,ABOUT,and%20'Into%20the%20Breach'. | F36: slay_the_spire---alina_of_the_arena | G36: No
A37: Dead Cells | B37: An Amazing Wizard | C37: 2018 | E37: https://x.com/AnAmazingWizard/status/1489554155597352962?s=20 | F37: dead_cells---an_amazing_wizard | G37: No
A38: Hades | B38: An Amazing Wizard | C38: 2019 | E38: https://x.com/AnAmazingWizard/status/1489554155597352962?s=20 | F38: hades---an_amazing_wizard | G38: No
A39: The Binding of Isaac | B39: An Amazing Wizard | C39: 2011 | E39: https://x.com/AnAmazingWizard/status/1489554155597352962?s=20 | F39: the_binding_of_isaac---an_amazing_wizard | G39: No
A40: Hack | B40: Ancient Domains of Mystery | C40: 1984 | E40: https://roguebasin.com/index.php/ADOM | F40: hack---ancient_domains_of_mystery | G40: No
...

Sheet characters
A1: Name | B1: Game | C1: Health | D1: Gold | E1: Bash | F1: Dash | G1: Push | H1: Transmute | I1: Scramble | J1: Bombs | K1: Keys | L1: Random | M1: Level Up | N1: Reward | O1: Description | P1: Starting loadout | Q1: File
A2: Antonio Belpaese | B2: Vampire Survivors | C2: 7 | D2: 3 | E2: 1 | F2: 0 | G2: 1 | H2: 0 | I2: 0 | J2: 0 | K2: 0 | L2: 0 | M2: Beat a game while having defeated a vampire | N2: Gain +1 Random Sized Chest | O2: What a wonderful night to hunt beasts! | P2: Whip | Q2: AntonioBelpaese
A3: Erratic Deck | B3: Balatro | C3: 7 | D3: 3 | E3: 0 | F3: 0 | G3: 0 | H3: 0 | I3: 0 | J3: 0 | K3: 0 | L3: 2 | M3: Beat a game while having selected a random starting build | N3: Gain +1 Random Card | O3: All Ranks and Suits in deck are randomized | P3: 1 random joker card | Q3: ErraticDeck
A4: Ironclad | B4: Slay the Spire | C4: 8 | D4: 3 | E4: 2 | F4: 0 | G4: 0 | H4: 0 | I4: 0 | J4: 0 | K4: 0 | L4: 0 | M4: Beat a game while having made a Faustian bargain | N4: Gain +1 Small Chest | O4: The remaining soldier of the Ironclads. Sold his soul to harness demonic energies. | P4: Burning Blood | Q4: Ironclad
A5: Isaac | B5: The Binding of Isaac; The Binding of Isaac: Rebirth | C5: 6 | D5: 3 | E5: 0 | F5: 0 | G5: 0 | H5: 0 | I5: 0 | J5: 1 | K5: 0 | L5: 0 | M5: Beat a game while having used sorrow or self-inflicted pain as a weapon | N5: Gain +1 Small Chest and +1 Scramble | O5: Who am I? | P5: D6 | Q5: Isaac
A6: Manager | B6: Raccoin: Coin Pusher Roguelike | C6: 7 | D6: 3 | E6: 0 | F6: 0 | G6: 2 | H6: 0 | I6: 0 | J6: 0 | K6: 0 | L6: 0 | M6: Beat a game while having collected 3 different types of currency | N6: Gain +1 Push and +1 Gold | O6: Master in using Math coins and earning tickets. | P6: N/A | Q6: Manager
A7: Minä | B7: Noita | C7: 7 | D7: 3 | E7: 0 | F7: 0 | G7: 0 | H7: 2 | I7: 0 | J7: 0 | K7: 0 | L7: 0 | M7: Beat a game while having crafted or combined a spell or weapon | N7: Gain +1 Transmute | O7: Why must you go destroying everything? Why? For glory? For your precious god of gods. Is it really worth all this? Is it? Is it really? | P7: 1 random wand | Q7: Minä
A8: Poe Ratcho | B8: Vampire Survivors | C8: 7 | D8: 3 | E8: 0 | F8: 0 | G8: 2 | H8: 0 | I8: 0 | J8: 0 | K8: 0 | L8: 0 | M8: Beat a game while being stinky | N8: Gain +1 Random Sized Chest | O8: A malodorous hero | P8: Pummarola | Q8: PoeRatcho
A9: Regent | B9: Slay the Spire 2 | C9: 7 | D9: 3 | E9: 0 | F9: 0 | G9: 1 | H9: 1 | I9: 0 | J9: 0 | K9: 0 | L9: 0 | M9: Beat a game while having made a friend | N9: Gain +1 Small Chest | O9: Heir to the Throne of Stars. Wields cosmic powers but his minions do the work. | P9: N/A | Q9: Regent
A10: Rodney | B10: Rogue | C10: 5 | D10: 3 | E10: 0 | F10: 0 | G10: 0 | H10: 0 | I10: 0 | J10: 0 | K10: 0 | L10: 2 | M10: Beat a game without meta progression | N10: Gain +1 Max Health and +1 Loot | O10: Now I abide here, searching endlessly for the precious Amulet... and finding a thousand horrors. | P10: N/A | Q10: Rodney
A11: The Makeshift Sisyphus | B11: Ball x Pit | C11: 7 | D11: 3 | E11: 1 | F11: 0 | G11: 0 | H11: 0 | I11: 0 | J11: 0 | K11: 0 | L11: 0 | M11: Beat a game while having pushed a boulder | N11: Gain +1 Small Chest | O11: A former king, tormented by time | P11: Earthquake | Q11: TheMakeshiftSisyphus
A12: Zagreus | B12: Hades | C12: 7 | D12: 3 | E12: 1 | F12: 1 | G12: 0 | H12: 0 | I12: 0 | J12: 0 | K12: 0 | L12: 0 | M12: Beat a game with the help of a God | N12: Gain +1 Large Chest | O12: ... All right, let's give it another shot. | P12: N/A | Q12: Zagreus
A13: Zoe | B13: Haste | C13: 7 | D13: 3 | E13: 0 | F13: 1 | G13: 1 | H13: 0 | I13: 0 | J13: 0 | K13: 0 | L13: 0 | M13: Perfect a game by beating it without losing | N13: Gain +1 Dash | O13: Express Delivery: Arrives with haste, before the world ends. | P13: N/A | Q13: Zoe

Sheet items
A1: Name | B1: Rating | C1: Type | D1: Description | E1: Effect | F1: Reference | G1: tags | H1: pools | I1: File | J1: Sorting
A2: Alien Baby | B2: Rare | C2: Pickup, Passive | D2: Gain +6 Max Health, but all enemies gain +1 Health | E2: item_acquired: gain_max_hp 6; passive: +1 enemy_health | F2: Brotato | G2: alien | I2: AlienBaby | J2: Health
A3: Anchor | B3: Common | C3: Triggered | D3: At the start of combat, Gain +1 Temporary Shield | E3: game_selected: gain_stat shields 1 | F3: Slay the Spire | G3: sea, ship | I3: Anchor | J3: Defense
A4: Ban Hammer | B4: Uncommon | C4: Pickup | D4: Gain +2 Bashes | E4: item_acquired: gain_stat bash 2 | F4: Yet Another Zombie Survivors | G4: tool, hammer | I4: BanHammer | J4: Stats
A5: Bionic Face Plating | B5: Uncommon | C5: Passive | D5: Gain +3 Speed, but this is destroyed when taking damage | E5: passive_status: speed 3; destroy_on_damage | F5: Mewgenics | G5: cybernetics | I5: BionicFacePlating | J5: Stats
A6: Blood Bag | B6: Event | C6: Pickup | D6: Gain +2 Max Health and +8 Health | E6: item_acquired: gain_max_hp 2; gain_hp 8 | F6: The Binding of Isaac | G6: blood | I6: BloodBag | J6: Health
A7: Blood Bombs | B7: Uncommon | C7: Pickup, Triggered | D7: Gain +1 Bomb. When using a Bomb, Gain +1 Health | E7: item_acquired: gain_stat bombs 1; bomb_used: gain_hp 1 | F7: The Binding of Isaac: Rebirth | G7: bomb, blood | I7: BloodBombs | J7: Bomb
A8: Book of Revelations | B8: Rare | C8: Charged, 3 | D8: Gain +1 Shield | E8: item_used: gain_stat bonus_shields 1 | F8: The Binding of Isaac | G8: book | I8: BookOfRevelations | J8: Defense
A9: Brimstone Bombs | B9: Rare | C9: Pickup, Passive | D9: Gain +1 Bomb. Bombs now apply 1 Stun to all rows in the 4 cardinal directions | E9: item_acquired: gain_stat bombs 1; bomb_cardinal | F9: The Binding of Isaac: Rebirth | G9: bomb | H9: devil_room | I9: BrimstoneBombs | J9: Bomb, Grid
A10: Burning Blood | B10: Starter | C10: Triggered | D10: After beating a game, Gain +1 Health | E10: game_beaten: gain_hp 1 | F10: Slay the Spire | I10: BurningBlood | J10: Health
A11: Caffeine Pill | B11: Common | C11: Passive, Pickup | D11: Gain +1 Speed and +1 Pill | E11: passive_status: speed 1; item_acquired: gain_pill 1 | F11: The Binding of Isaac: Rebirth | G11: drugs, pills | I11: CaffeinePill | J11: Loot, Stats
A12: Calling Bell | B12: Boss | C12: Pickup | D12: Obtain Curse of the Bell and 3 random items — one Common, one Uncommon, one Rare | E12: item_acquired: add_curse curse_of_the_bell, gain_item_per_rarity 3 | F12: Slay the Spire | I12: CallingBell | J12: Special
A13: Candy Bag | B13: Rare | C13: Passive | D13: After Combat ends, Gain +1 Bash, Dash, Push, Transmute or Scramble, but have a 10% chance to spawn a Boss | E13: game_beaten: one_of gain_stat bash 1 | gain_stat dash 1 | gain_stat push 1 | gain_stat transmute 1 | gain_stat scramble 1, 10% chance spawn_boss | F13: Brotato | G13: food, sweets, bag | I13: CandyBag | J13: Stats
A14: Cauldron | B14: Rare | C14: Pickup | D14: Gain +5 Potions | E14: item_acquired: gain_potion 5 | F14: Slay the Spire | G14: pot | H14: shop | I14: Cauldron | J14: Loot
A15: Censer | B15: Uncommon | C15: Passive | D15: Enemies in the 2 leftmost columns take no extra turns | E15: front_column_slow 2 | F15: The Binding of Isaac: Rebirth | G15: holy | H15: angel_room | I15: Censer | J15: Combat
A16: Ceremonial Dagger | B16: Rare | C16: Passive | D16: Whenever an Enemy is defeated, Apply 1 Stun to a random Enemy | E16: enemy_killed: apply_status stun 1 target=random | F16: Risk of Rain | G16: weapon, dagger | I16: CeremonialDagger | J16: Offense
A17: Charm of the Vampire | B17: Uncommon | C17: Triggered, Incremental | D17: When you defeat 3 enemies, Gain +1 Health | E17: enemy_killed: counter key=enemies_defeated every=3 -> gain_hp 1 | F17: The Binding of Isaac | G17: bat, vampire | I17: CharmOfTheVampire | J17: Health
A18: Clover | B18: Uncommon | C18: Passive | D18: Gain +1 Luck | E18: passive: +1 luck | F18: Vampire Survivors | G18: plant | I18: Clover | J18: Stats
A19: Crown | B19: Uncommon | C19: Triggered | D19: When Levelling Up, 50% chance to Level Up an additional time | E19: level_up: 50% | F19: Vampire Survivors | G19: wearable, hat, crown | I19: Crown | J19: Economy
A20: D10 | B20: Common | C20: Charged, 2 | D20: Reroll all non-boss enemies | E20: item_used: reroll_enemies | F20: The Binding of Isaac: Rebirth | G20: dice | I20: D10 | J20: Grid
A21: D6 | B21: Uncommon | C21: Charged, 2 | D21: Gain +1 Scramble | E21: item_used: gain_stat scramble 1 | F21: The Binding of Isaac | G21: dice | I21: D6 | J21: Stats
A22: Deck of Cards | B22: Uncommon | C22: Charged, 2 | D22: Gain +1 Card | E22: item_used: gain_card 1 | F22: The Binding of Isaac | I22: DeckOfCards | J22: Loot
A23: Dragon Fruit | B23: Rare | C23: Triggered | D23: Whenever you obtain any amount of gold, Gain +1 Max Health | E23: gold_gained: gain_max_hp 1 | F23: Slay the Spire 2 | G23: food, fruit | H23: shop | I23: DragonFruit | J23: Economy
A24: Dumb Bell | B24: Uncommon | C24: Passive | D24: When Charging a Weapon, Gain +1 Temporary Strength | E24: weapon_charged: apply_status strength 1 games=1 | F24: Peglin | G24: bell | I24: DumbBell | J24: Stats
A25: Echo Chamber | B25: Rare | C25: Passive | D25: Whenever you use Loot, you also use a copy of the last 3 Loot you used after picking up Echo Chamber | E25: echo_loot 3 | F25: The Binding of Isaac: Rebirth | I25: EchoChamber | J25: Loot
A26: Fanny Pack | B26: Uncommon | C26: Passive | D26: 50% chance to spawn 1 random loot on the grid when losing health | E26: health_lost: 50% chance drop_loot 1 | F26: The Binding of Isaac: Rebirth | G26: wearable, bag | I26: FannyPack | J26: Economy
A27: Fortune Necklace | B27: Common | C27: Triggered | D27: When selecting a game, Gain +1 Gold, but this is destroyed when taking damage | E27: game_selected: gain_gold 1; destroy_on_damage | F27: Mewgenics | G27: wearable, necklace | I27: FortuneNecklace | J27: Economy
A28: Gasoline | B28: Common | C28: Passive | D28: Whenever an Enemy is defeated, Add the Fire Tile Effect to the Tile it died on | E28: death_tile fire | F28: Risk of Rain 2 | G28: fire | I28: Gasoline | J28: Grid
A29: Golden Idol | B29: Event | C29: Passive | D29: All enemies drop +1 Gold | E29: gold_per_enemy: 1 | F29: Slay the Spire | G29: gold | I29: GoldenIdol | J29: Economy
A30: Hollow Heart | B30: Common | C30: Pickup | D30: Gain +4 Empty Max Health | E30: item_acquired: gain_empty_max_hp 4 | F30: Vampire Survivors | G30: heart | I30: HollowHeart | J30: Health
A31: Hot Bombs | B31: Uncommon | C31: Passive | D31: Gain +1 Bomb and Bombs Apply the Fire Tile | E31: item_acquired: gain_stat bombs 1; bomb_tile fire | F31: The Binding of Isaac: Rebirth | G31: bomb, fire | I31: HotBombs | J31: Bomb, Grid
A32: Infusion | B32: Uncommon | C32: Triggered | D32: Every time you defeat an Enemy, Gain +1 Empty Max Health | E32: enemy_killed: gain_empty_max_hp 1 | F32: Risk of Rain 2 | G32: blood | I32: Infusion | J32: Health
A33: IV Bag | B33: Event | C33: Usable, 0 | D33: Lose 1 Health and Gain +1 Gold | E33: item_used: lose_hp 1; gain_gold 1 | F33: The Binding of Isaac | G33: blood | I33: IvBag | J33: Economy
A34: Knight Cap | B34: Common | C34: Passive | D34: After Combat ends, Gain +1 Health if you had remaining Shield | E34: game_beaten if_shields: gain_hp 1 | F34: Peglin | G34: wearable, hat | I34: KnightCap | J34: Health
A35: Landmines | B35: Uncommon | C35: Passive | D35: After Combat ends, Apply the Landmine Unit to a random empty Tile | E35: game_beaten: apply_unit landmine target=random_empty | F35: Brotato | G35: bomb | I35: Landmines | J35: Grid
A36: Latch Key | B36: Common | C36: Pickup, Passive | D36: Gain +1 Key, +1 Shield, and +1 Luck | E36: passive: +1 luck; item_acquired: gain_stat keys 1; gain_stat bonus_shields 1 | F36: The Binding of Isaac: Rebirth | G36: key | I36: LatchKey | J36: Economy
A37: Link Cable | B37: Rare | C37: Passive | D37: All Loot count as adjacent to each other | E37: link_loot | F37: Batomon Showdown | G37: wire | I37: LinkCable | J37: Loot
... A47: Mom's Coin Purse | B47: Common | C47: Pickup | D47: Gain +4 Pills | E47: item_acquired: gain_pill 4 | F47: The Binding of Isaac | G47: mom, bag, drugs, pills | I47: MomsCoinPurse | J47: Loot
A48: Mom's Key | B48: Uncommon | C48: Pickup, Passive | D48: Gain +1 Key, and +1 Base Chest Value | E48: item_acquired: gain_stat keys 1; base_chest_bonus: 1 | F48: The Binding of Isaac: Rebirth | G48: mom, key | H48: shop | I48: MomsKey | J48: Economy
A49: Mysterious Mask | B49: Rare | C49: Pickup | D49: Choose one of 3 Starting Characters and gain their Level Up Condition | E49: item_acquired: mask_choice | F49: Batomon Showdown | G49: wearable, mask | I49: MysteriousMask | J49: Goals
...

Sheet enemies
A1: Name | B1: Type | C1: Difficulty | D1: Size | E1: Game | F1: Health | G1: Damage | H1: Goal Type | I1: Goal | J1: Ability | K1: File | L1: Tag | M1: Ticked | N1: Count
A2: Attack Fly | B2: Action | C2: 1-Low | D2: 1x1 | E2: The Binding of Isaac | F2: 1 | G2: 1 | H2: Bounty | I2: Defeat 3 bugs | J2: N/A | K2: AttackFly | L2: bug, fly | M2: any time | N2: 3
A3: Baby Alien | B3: Action | C3: 1-Low | D3: 1x1 | E3: Brotato | F3: 1 | G3: 1 | H3: Bounty | I3: Defeat an enemy that is an alien | J3: N/A | K3: BabyAlien | L3: alien | M3: any time
A4: Bullat | B4: Action | C4: 1-Low | D4: 1x1 | E4: Enter the Gungeon | F4: 1 | G4: 1 | H4: Feat | I4: Shoot down a flying enemy | J4: N/A | K4: Bullat | L4: bat, bullet | M4: any time
A5: Doomvas | B5: Action | C5: 1-Low | D5: 1x1 | E5: Rogue Legacy | F5: 1 | G5: 1 | H5: Feat | I5: Destroy a painting | J5: N/A | K5: Doomvas | L5: art | M5: any time
A6: Flaming Fatty | B6: Action | C6: 1-Low | D6: 1x1 | E6: The Binding of Isaac: Rebirth | F6: 1 | G6: 1 | H6: Feat | I6: Push an enemy into fire | J6: Aftermath (Fire) | K6: FlamingFatty | L6: fire | M6: any time
A7: Keybullet Kin | B7: Action | C7: 1-Low | D7: 1x1 | E7: Enter the Gungeon | F7: 1 | G7: 1 | H7: Fetch | I7: Obtain a key | J7: N/A | K7: KeybulletKin | L7: bullet | M7: any time
A8: Lil Dave | B8: Action | C8: 1-Low | D8: 1x1 | E8: Muck | F8: 1 | G8: 1 | H8: Feat | I8: Destroy a wooden structure | J8: N/A | K8: LilDave | M8: any time
A9: Mysterious Tree | B9: Action | C9: 1-Low | D9: 1x1 | E9: 20 Minutes Till Dawn | F9: 3 | G9: 1 | H9: Feat | I9: Destroy a tree | J9: Immobile | K9: MysteriousTree | L9: plant, tree, wood | M9: any time
A10: Numbskull | B10: Action | C10: 1-Low | D10: 1x1 | E10: Hades | F10: 1 | G10: 1 | H10: Bounty | I10: Defeat an animated body part | J10: N/A | K10: Numbskull | L10: undead, skeleton | M10: any time
A11: Pacer | B11: Action | C11: 1-Low | D11: 1x1 | E11: The Binding of Isaac | F11: 1 | G11: 1 | H11: Bounty | I11: Defeat a headless enemy | J11: N/A | K11: Pacer | M11: any time
A12: Psychic Horf | B12: Action | C12: 1-Low | D12: 1x1 | E12: The Binding of Isaac: Rebirth | F12: 1 | G12: 1 | H12: Feat | I12: Use a homing attack | J12: Ranged (N/A) | K12: PsychicHorf | M12: any time
A13: Skeleton Warrior | B13: Action | C13: 1-Low | D13: 1x1 | E13: Ball x Pit | F13: 1 | G13: 1 | H13: Bounty | I13: Defeat a skeleton with a ball | J13: N/A | K13: SkeletonWarrior | L13: undead, skeleton | M13: any time
A14: Spider | B14: Action | C14: 1-Low | D14: 1x1 | E14: The Binding of Isaac | F14: 1 | G14: 1 | H14: Bounty | I14: Defeat 3 spiders | J14: N/A | K14: Spider | L14: bug, spider | M14: any time | N14: 3
A15: Wisp | B15: Action | C15: 1-Low | D15: 1x1 | E15: Risk of Rain | F15: 1 | G15: 1 | H15: Bounty | I15: Defeat an enemy made of fire | J15: N/A | K15: Wisp | L15: fire | M15: any time
A16: Wringer | B16: Action | C16: 1-Low | D16: 1x1 | E16: Hades | F16: 1 | G16: 1 | H16: Feat | I16: Grab an enemy | J16: N/A | K16: Wringer | L16: undead | M16: any time
A17: Bony | B17: Action | C17: 2-Medium | D17: 1x1 | E17: The Binding of Isaac: Rebirth | F17: 1 | G17: 2 | H17: Bounty | I17: Defeat 5 skeletons | J17: Ranged (3) | K17: Bony | L17: undead, skeleton | M17: any time | N17: 5
A18: Child | B18: Action | C18: 2-Medium | D18: 1x1 | E18: Risk of Rain | F18: 1 | G18: 2 | H18: Bounty | I18: Defeat a child | J18: N/A | K18: Child | L18: alien | M18: any time
A19: Coal Spider | B19: Action | C19: 2-Medium | D19: 1x1 | E19: The Binding of Isaac: Rebirth | F19: 1 | G19: 2 | H19: Feat | I19: Set a rock on fire | J19: N/A | K19: CoalSpider | L19: spider, rock, fire | M19: any time
A20: Flaming Hopper | B20: Action | C20: 2-Medium | D20: 1x1 | E20: The Binding of Isaac | F20: 1 | G20: 2 | H20: Bounty | I20: Defeat an enemy while on fire | J20: Infliction (2, Burn) | K20: FlamingHopper | L20: fire | M20: any time
A21: Fungun | B21: Action | C21: 2-Medium | D21: 1x1 | E21: Enter the Gungeon | F21: 1 | G21: 2 | H21: Feat | I21: Shoot a mushroom | J21: N/A | K21: Fungun | L21: mushroom | M21: any time
A22: King Bullat | B22: Action | C22: 2-Medium | D22: 1x1 | E22: Enter the Gungeon | F22: 1 | G22: 2 | H22: Feat | I22: Shoot down 2 flying enemies | J22: N/A | K22: KingBullat | L22: bat, bullet | M22: any time | N22: 2
A23: Skeletal Brute | B23: Action | C23: 2-Medium | D23: 1x2 | E23: Ball x Pit | F23: 1 | G23: 2 | H23: Bounty | I23: Defeat 2 skeletons with a ball | J23: N/A | K23: SkeletalBrute | L23: undead, skeleton | M23: any time | N23: 2
A24: Bishop | B24: Action | C24: 3-High | D24: 1x1 | E24: The Binding of Isaac: Rebirth | F24: 1 | G24: 3 | H24: Feat | I24: Block damage done to a friendly unit | J24: Bolster (1, Dexterity) | K24: Bishop | M24: any time
A25: Gigantic Vermin | B25: Action | C25: 3-High | D25: 2x2 | E25: Hades | F25: 1 | G25: 3 | H25: Bounty | I25: Defeat a large rodent | J25: N/A | K25: GiganticVermin | L25: rodent, rat | M25: any time
A26: Nemean Chariot | B26: Action | C26: 3-High | D26: 1x1 | E26: Hades | F26: 1 | G26: 3 | H26: Feat | I26: Hit an enemy with a vehicle | J26: Haste (1) | K26: NemeanChariot | M26: any time
A27: Skeletal Bastion | B27: Action | C27: 3-High | D27: 2x3 L 90 CC | E27: Ball x Pit | F27: 1 | G27: 3 | H27: Bounty | I27: Defeat 3 skeletons with a ball | J27: N/A | K27: SkeletalBastion | L27: undead, skeleton | M27: any time | N27: 3
A28: Cultist | B28: Deckbuilder | C28: 1-Low | D28: 1x1 | E28: Slay the Spire | F28: 1 | G28: 1 | H28: Feat | I28: Perform a religious act | J28: Ritual | K28: Cultist | M28: any time
A29: Fungi Beast | B29: Deckbuilder | C29: 1-Low | D29: 1x1 | E29: Slay the Spire | F29: 1 | G29: 1 | H29: Feat | I29: Get infected | J29: N/A | K29: FungiBeast | L29: mushroom | M29: any time
A30: Ice Slime | B30: Deckbuilder | C30: 1-Low | D30: 1x1 | E30: Dungeon Clawler | F30: 1 | G30: 1 | H30: Feat | I30: Freeze an enemy | J30: N/A | K30: IceSlime | L30: slime, ice | M30: any time
A31: Lava Slime | B31: Deckbuilder | C31: 1-Low | D31: 1x1 | E31: Dungeon Clawler | F31: 1 | G31: 1 | H31: Feat | I31: Touch lava | J31: Infliction (1, Burn) | K31: LavaSlime | L31: slime, lava | M31: any time
A32: Punch Construct | B32: Deckbuilder | C32: 1-Low | D32: 1x1 | E32: Slay the Spire 2 | F32: 1 | G32: 1 | H32: Feat | I32: Punch a robot | J32: N/A | K32: PunchConstruct | L32: robot | M32: any time
A33: Shrinker Beetle | B33: Deckbuilder | C33: 1-Low | D33: 1x1 | E33: Slay the Spire 2 | F33: 1 | G33: 1 | H33: Feat | I33: Shrink in size | J33: N/A | K33: ShrinkerBeetle | L33: bug, beetle | M33: any time
A34: Spike Slime (L) | B34: Deckbuilder | C34: 1-Low | D34: 2x2 | E34: Slay the Spire | F34: 1 | G34: 1 | H34: Bounty | I34: Defeat an enemy that splits into another enemy | J34: Split (2, slime tag) | K34: SpikeSlime(L) | L34: slime | M34: any time
A35: Stumpy Stump | B35: Deckbuilder | C35: 1-Low | D35: 1x1 | E35: Peglin | F35: 1 | G35: 1 | H35: Feat | I35: Have a defeated enemy block an attack | J35: N/A | K35: StumpyStump | L35: plant, tree, wood | M35: any time
A36: Shelled Parasite | B36: Deckbuilder | C36: 2-Medium | D36: 1x1 | E36: Slay the Spire | F36: 1 | G36: 2 | H36: Bounty | I36: Defeat an enemy that looks edible | J36: N/A | K36: ShelledParasite | M36: any time
A37: Snecko | B37: Deckbuilder | C37: 2-Medium | D37: 1x1 | E37: Slay the Spire | F37: 1 | G37: 2 | H37: Restriction | I37: Beat a game while having selected a random starting build | J37: N/A | K37: Snecko | M37: game beaten
A38: The Obscura | B38: Deckbuilder | C38: 2-Medium | D38: 1x1 | E38: Slay the Spire 2 | F38: 1 | G38: 2 | H38: Feat | I38: Create an illusion | J38: Illusionist (1, Random Medium) | K38: TheObscura | M38: any time
A39: Chosen | B39: Deckbuilder | C39: 3-High | D39: 1x1 | E39: Slay the Spire | F39: 1 | G39: 3 | H39: Restriction | I39: Beat a game without using magic | J39: Hexer | K39: Chosen | M39: game beaten
A40: Transient | B40: Deckbuilder | C40: 3-High | D40: 2x2 | E40: Slay the Spire | F40: 1 | G40: 3 | H40: Discovery | I40: Witness an enemy kill itself | J40: Tanky (8), Fading (3) | K40: Transient | M40: any time
...

Sheet bosses
A1: Name | B1: Type | C1: Difficulty | D1: Size | E1: Game | F1: Health | G1: Damage | H1: Goal Type | I1: Goal | J1: Ability | K1: File | L1: Tag | M1: Phases | N1: Ticked | O1: Count
A2: Baby Plum | B2: Action | C2: 1-Low | D2: 2x2 | E2: The Binding of Isaac: Rebirth | F2: 1 | G2: 3 | H2: Bounty | I2: Defeat a boss without using violence | J2: N/A | K2: BabyPlum | N2: any time
A3: Beholster | B3: Action | C3: 1-Low | D3: 2x2 | E3: Enter the Gungeon | F3: 1 | G3: 3 | H3: Fetch | I3: Have 6 Guns at once | J3: Ranged (4) | K3: Beholster | L3: gun | N3: any time
A4: Big Chunk | B4: Action | C4: 1-Low | D4: 2x2 | E4: Muck | F4: 1 | G4: 3 | H4: Bounty | I4: Defeat an enemy made of stone | J4: N/A | K4: BigChunk | L4: rock | N4: any time
A5: Colossus | B5: Action | C5: 1-Low | D5: 2x2 | E5: Risk of Rain | F5: 1 | G5: 3 | H5: Discovery | I5: Witness a living structure | J5: Trample | K5: Colossus | N5: any time
A6: Famine | B6: Action | C6: 1-Low | D6: 1x1 | E6: The Binding of Isaac | F6: 1 | G6: 3 | H6: Restriction | I6: Beat a game without eating any food | J6: Ranged (1) | K6: Famine | N6: game beaten
A7: Khidr | B7: Action | C7: 1-Low | D7: 2x2 | E7: Rogue Legacy | F7: 1 | G7: 3 | H7: Feat | I7: Poke an eye | J7: N/A | K7: Khidr | L7: eye | N7: any time
A8: Mega Fatty | B8: Action | C8: 1-Low | D8: 2x2 | E8: The Binding of Isaac: Rebirth | F8: 1 | G8: 3 | H8: Bounty | I8: Defeat an obese enemy | J8: Ranged (2) | K8: MegaFatty | N8: any time
A9: Megaera | B9: Action | C9: 1-Low | D9: 1x1 | E9: Hades | F9: 1 | G9: 3 | H9: Fetch | I9: Date someone | J9: N/A | K9: Megaera | N9: any time
A10: Steven | B10: Action | C10: 1-Low | D10: 1x1 | E10: The Binding of Isaac | F10: 1 | G10: 3 | H10: Discovery | I10: Be in a time loop | J10: N/A | K10: Steven | N10: any time
A11: The Rainmaker | B11: Action | C11: 1-Low | D11: 1x1 | E11: The Binding of Isaac: Rebirth | F11: 1 | G11: 3 | H11: Feat | I11: Take a shower | J11: N/A | K11: TheRainmaker | N11: any time
A12: Charon | B12: Action | C12: 2-Medium | D12: 2x1 | E12: Hades | F12: 1 | G12: 5 | H12: Fetch | I12: Steal from a shop | J12: N/A | K12: Charon | N12: any time
A13: Mom's Heart | B13: Action | C13: 2-Medium | D13: 1x1 | E13: The Binding of Isaac | F13: 1 | G13: 5 | H13: Feat | I13: Break a Heart | J13: N/A | K13: MomsHeart | N13: any time
A14: Resourceful Rat | B14: Action | C14: 2-Medium | D14: 1x1 | E14: Enter the Gungeon | F14: 1 | G14: 5 | H14: Feat | I14: Beat a mini-game inside of a game | J14: N/A | K14: ResourcefulRat | L14: rat | N14: any time
A15: Royal Phalanx | B15: Action | C15: 2-Medium | D15: 1x1 | E15: Ember Knights | F15: 1 | G15: 5 | H15: Feat | I15: Block an attack with an element | J15: Defensive Stance (2) | K15: RoyalPhalanx | N15: any time
A16: Scylla | B16: Action | C16: 2-Medium | D16: 1x1 | E16: Hades II | F16: 1 | G16: 5 | H16: Feat | I16: Perform a song | J16: N/A | K16: Scylla | N16: any time
A17: Wallmonger | B17: Action | C17: 2-Medium | D17: 2x3 | E17: Enter the Gungeon | F17: 1 | G17: 5 | H17: Feat | I17: Destroy a wall | J17: N/A | K17: Wallmonger | N17: any time
A18: Isaac | B18: Action | C18: 3-High | D18: 1x1 | E18: The Binding of Isaac | F18: 1 | G18: 7 | H18: Bounty | I18: Defeat yourself | J18: N/A | K18: Isaac | N18: any time
A19: Lich | B19: Action | C19: 4-Insane | D19: 1x2 | E19: Enter the Gungeon | F19: 1 | G19: 9 | H19: Bounty | I19: Defeat a magic enemy with a gun | J19: N/A | K19: Lich | L19: undead, skeleton | N19: any time
A20: The Beast | B20: Action | C20: 4-Insane | D20: 3x3 | E20: The Binding of Isaac: Rebirth | F20: 1 | G20: 9 | H20: Bounty | I20: Defeat a true final boss while on the brink of death | J20: Trample | K20: TheBeast | N20: any time
A21: The One Who Waits | B21: Action | C21: 4-Insane | D21: 2x2 | E21: Cult of the Lamb | F21: 1 | G21: 9 | H21: Feat | I21: Enter or Create a religion | J21: N/A | K21: TheOneWhoWaits | N21: any time
A22: Gremlin Nob | B22: Deckbuilder | C22: 1-Low | D22: 1x1 | E22: Slay the Spire | F22: 1 | G22: 3 | H22: Feat | I22: Taunt at someone | J22: N/A | K22: GremlinNob | N22: any time
A23: Lagavulin | B23: Deckbuilder | C23: 1-Low | D23: 2x2 | E23: Slay the Spire | F23: 1 | G23: 3 | H23: Feat | I23: Go to sleep | J23: N/A | K23: Lagavulin | N23: any time
A24: Slime Boss | B24: Deckbuilder | C24: 1-Low | D24: 2x2 | E24: Peglin | F24: 1 | G24: 3 | H24: Feat | I24: Enter an enemy | J24: N/A | K24: SlimeBoss | L24: slime | N24: any time
A25: Vantom | B25: Deckbuilder | C25: 1-Low | D25: 1x1 | E25: Slay the Spire 2 | F25: 1 | G25: 3 | H25: Feat | I25: Use an attack that hits 4+ times | J25: Lacerator | K25: Vantom | N25: any time
A26: The Club | B26: Deckbuilder | C26: 2-Medium | D26: 1x1 | E26: Balatro | F26: 1 | G26: 5 | H26: Restriction | I26: Beat a game without backtracking | J26: N/A | K26: TheClub | N26: game beaten
A27: The Goad | B27: Deckbuilder | C27: 2-Medium | D27: 1x1 | E27: Balatro | F27: 1 | G27: 5 | H27: Restriction | I27: Beat a game without using a weapon | J27: N/A | K27: TheGoad | N27: game beaten
A28: The Head | B28: Deckbuilder | C28: 2-Medium | D28: 1x1 | E28: Balatro | F28: 1 | G28: 5 | H28: Restriction | I28: Beat a game without purposefully healing | J28: N/A | K28: TheHead | N28: game beaten
A29: The Insatiable | B29: Deckbuilder | C29: 2-Medium | D29: 2x2 | E29: Slay the Spire 2 | F29: 1 | G29: 5 | H29: Bounty | I29: Consume an enemy | J29: Ruthless, Devour Whole | K29: TheInsatiable | N29: any time
A30: The Window | B30: Deckbuilder | C30: 2-Medium | D30: 1x1 | E30: Balatro | F30: 1 | G30: 5 | H30: Restriction | I30: Beat a game without spending currency | J30: N/A | K30: TheWindow | N30: game beaten
A31: Cerulean Bell | B31: Deckbuilder | C31: 3-High | D31: 1x1 | E31: Balatro | F31: 1 | G31: 7 | H31: Restriction | I31: Beat a game while only taking the first option offered when taking reward options | J31: N/A | K31: CeruleanBell | N31: game beaten
A32: The Needle | B32: Deckbuilder | C32: 3-High | D32: 1x1 | E32: Balatro | F32: 1 | G32: 7 | H32: Restriction | I32: Beat a game while only using 1 hand | J32: N/A | K32: TheNeedle | N32: game beaten
A33: Time Eater | B33: Deckbuilder | C33: 3-High | D33: 1x1 | E33: Slay the Spire | F33: 1 | G33: 7 | H33: Restriction | I33: Beat the game in 2 hours or less | J33: Bolster (3, Speed) | K33: TimeEater | N33: game beaten
A34: Corrupt Heart | B34: Deckbuilder | C34: 4-Insane | D34: 2x2 | E34: Slay the Spire | F34: 1 | G34: 9 | H34: Feat | I34: Get the true ending on the hardest difficulty possible | J34: Hexer (2) | K34: CorruptHeart | N34: any time
A35: Giant Spider | B35: Strategy | C35: 1-Low | D35: 2x2 | E35: Forward: Escape the Fold | F35: 1 | G35: 3 | H35: Bounty | I35: Defeat a bug larger than you | J35: N/A | K35: GiantSpider | L35: bug, spider | N35: any time
A36: Hickory | B36: Strategy | C36: 1-Low | D36: 1x1 | E36: Brutal Orchestra | F36: 1 | G36: 3 | H36: Feat | I36: Light a liquid on fire | J36: Infliction (1, Burn) | K36: Hickory | L36: fire | N36: any time
A37: Marshmallow | B37: Strategy | C37: 1-Low | D37: 1x1 | E37: Mewgenics | F37: 1 | G37: 3 | H37: Feat | I37: Have an enemy defeat another enemy | J37: N/A | K37: Marshmallow | L37: cat | N37: any time
A38: Mobius | B38: Strategy | C38: 1-Low | D38: 2x2 | E38: Brutal Orchestra | F38: 1 | G38: 3 | H38: Fetch | I38: Obtain a large fish | J38: N/A | K38: Mobius | L38: fish | N38: any time
A39: Morana | B39: Strategy | C39: 1-Low | D39: 1x1 | E39: Mewgenics | F39: 1 | G39: 3 | H39: Feat | I39: Raise the dead | J39: Necromancy (1) | K39: Morana | L39: cat | N39: any time
A40: Trigger Fingers | B40: Strategy | C40: 1-Low | D40: 1x1 | E40: Brutal Orchestra | F40: 1 | G40: 3 | H40: Bounty | I40: Defeat a fascist | J40: N/A | K40: TriggerFingers | N40: any time
...

Sheet abilities
A1: Name | B1: Type | C1: Variables | D1: Description | E1: Effect
A2: Aftermath | B2: Death | C2: Tile Effect | D2: On Death, will Add X Tile Effect to the Tile it died on | E2: death: apply_tile Y
A3: Agile | B3: Movement | C3: N/A | D3: Can move diagonally if necessary | E3: passive: move_diagonal
A4: Bolster | B4: Buff | C4: Amount, Status Type | D4: Grants X amount of X Status to all other Enemies and Bosses until death | E4: passive: aura_status Y X
A5: Defensive Stance | B5: Intent | C5: Stacks | D5: Will Gain X Dexterity on it's first turn instead of moving or attacking | E5: first_turn: gain_status dexterity X
A6: Degradation | B6: Attack | C6: Amount | D6: When this Enemy attacks and deals damage, it will Destroy X amount of random obtained Loot | E6: hit: destroy_loot X
A7: Devour Whole | B7: Attack | C7: N/A | D7: When this Enemy attacks and deals damage, the target is eaten and dies, including the plaer | E7: hit: devour
A8: Drain | B8: Attack | C8: Amount, Stats | D8: When this Enemy attacks and deals damage, decrease by X the player's Y(Max Health, Luck, Scramble, Bash, Dash, Transmute) | E8: hit: drain_stat Y X
A9: Entry Summon | B9: Summoner | C9: Amount, Enemy Type | D9: Instead of moving or attacking on it's first turn, it will Summon X amount of Y Enemies to a random adjacent tile | E9: first_turn: summon_adjacent X Y
A10: Fading | B10: Death | C10: Amount | D10: Will die at the end of X amount of combats | E10: spawn: set_fades X
A11: Fireproof | B11: Resistance | C11: N/A | D11: Cannot be Burned | E11: passive: immune burn
A12: Haste | B12: Buff | C12: Stacks | D12: Spawns with X Speed | E12: spawn: gain_status speed X
... A32: Restless Remains | B32: Death | C32: N/A | D32: On Health depletion, will leave a corpse with 1 Max Health that will revive in it's current tile on game completion unless fully defeated | E32: death: leave_corpse 1 revive=game_end

Sheet statuses
A1: Name | B1: Type | C1: Game | D1: On Player | E1: On Player Effect | F1: On Enemy | G1: On Enemy Effect | H1: Combat | I1: Decrease | J1: EnemyOnly | K1: Enemy Combat Effect | L1: Stackable | M1: Image
A2: Burn | B2: Debuff | C2: Brutal Orchestra | D2: Gain "You must beat a game while skipping or trashing X items/upgrades or take 3 Damage." | E2: demand "skip or trash {X} [item/upgrade|items/upgrades]" else -> take_damage 3 | F2: Gains "or instead beat a game while skipping or trashing 4-X items/upgrades" | G2: instead "skip or trash {4-X} [item/upgrade|items/upgrades]" | H2: Half Damage dealt | I2: On Completion | J2: Yes | K2: damage_dealt x0.5 | L2: Max: 3 | M2: Burn
A3: Dexterity | B3: Buff | C3: Slay the Spire | D3: Gain "if X or all bosses were beaten without getting hit when beating a game, Gain a [chest reward]" | E3: goal "{X} or all bosses were beaten without getting hit" -> gain_chest reward {X} | F3: Gains "and you must beat X or all bosses without getting hit in the run you complete the goal in" | G3: clause "you must beat {X} or all bosses without getting hit" | H3: Gain +X Shields | I3: N/A | J3: Yes | K3: shield +{X} | L3: Intensity | M3: Dexterity
A4: Marked | B4: Debuff | C4: Mewgenics | D4: Gain "You must beat a game while getting X achievements or take 3 Damage." | E4: demand "get {X} [achievement|achievements]" else -> take_damage 3 | F4: Gains "and if you get X achievements in the run you complete the goal in, Gain a [chest reward]" | G4: bonus "you get {X} [achievement|achievements]" decay -> gain_chest reward {X} | H4: Damage taken increased by x2. Ignores shields. | I4: On Completion | J4: No | K4: damage_taken x2; pierce_shields | L4: Intensity | M4: Marked
A5: Speed | B5: Buff | C5: Mewgenics | D5: Gain "If beaten in 1+(1/2)^(X-2) hours or less, Gain a [chest reward] and 1 Dash" | E5: goal "beaten in {1+(1/2)^(X-2):hours} or less" -> gain_chest reward {X}; gain_stat dash 1 | F5: Gains "and the game must be beaten in 1+(1/2)^(X-2) hours or less" — on a goal you can do any time, "and you must do it within 1+(1/2)^(X-2) hours of starting the game" | G5: clause "the game must be beaten in {1+(1/2)^(X-2):hours} or less" any_time "you must do it within {1+(1/2)^(X-2):hours} of starting the game" | H5: Increase tile movement by X | I5: N/A | J5: Yes | K5: tile_move +{X} | L5: Intensity | M5: Speed
A6: Strength | B6: Buff | C6: Slay the Spire | D6: Gain "If beaten while the difficulty is increased X times or as much as possible, Gain a [chest reward] and 1 Bash" | E6: goal "the difficulty is increased {X} [time|times] or as much as possible" -> gain_chest reward {X}; gain_stat bash 1 | F6: Gains "and the difficulty must be increased X times or as much as possible in the run you complete the goal in" | G6: clause "the difficulty must be increased {X} [time|times] or as much as possible" | H6: Increase Damage Dealt by X | I6: N/A | J6: Yes | K6: damage_dealt +{X} | L6: Intensity | M6: Strength
A7: Bleed | B7: Debuff | C7: Mewgenics | D7: Gain "You must beat a game while not healing intentionally or take 3 Damage. This lasts for X games." | E7: demand "not heal intentionally" else -> take_damage 3 | F7: Gains "and if you didn't intentionally heal in the game you beat it in, Gain a [chest reward]" — on a goal you can do any time, "before clearing it" | G7: bonus "you didn't intentionally heal" any_time "you didn't intentionally heal before clearing it" -> gain_chest reward {X} | H7: 50% chance to take 1 Damage when attacking | I7: On Trigger | J7: Yes | K7: recoil +1 chance=50 | L7: Intensity | M7: Bleed
A8: Stun | B8: Debuff | C8: Slay the Spire | H8: Skip their turn | I8: Each Turn | J8: Yes | K8: skip_turn | L8: Intensity | M8: Stun

Sheet events
A1: Event | B1: Game | C1: Tier | D1: Where | E1: Requirement | F1: Trigger | G1: Rarity | H1: Image | I1: Prompt | J1: Opens With | K1: Goal Met | L1: Goal Missed | M1: Chance Won | N1: Chance Lost | O1: Choice 1 | P1: Repeat 1 | Q1: Result 1 | R1: Effect 1 | S1: Choice 2 | T1: Repeat 2 | U1: Result 2 | V1: Effect 2 | W1: Choice 3 | X1: Repeat 3 | Y1: Result 3 | Z1: Effect 3 | AA1: Choice 4 | AB1: Repeat 4 | AC1: Result 4 | AD1: Effect 4 | AE1: Choice 5 | AF1: Repeat 5 | AG1: Result 5 | AH1: Effect 5 | AI1: Choice 6 | AJ1: Repeat 6 | AK1: Result 6 | AL1: Effect 6
A2: Abyssal Baths | B2: Slay the Spire 2 | C2: All | F2: After | G2: Common | H2: AbyssalBaths | I2: You discover a secluded chamber. Steam rises from bubbling pools of hot liquid that shifts colors with hypnotic rhythm. Barnacled growths hang from the ceiling, dripping viscous fluid that hisses and writhes when it touches the surface. The air feels heavy, laden with salt and something unmistakably organic. As you approach the edge of the largest pool, the liquid ripples. The waters bubble more intensely as if anticipating your entry. | O2: Immerse | P2: Stay | Q2: The liquid burns against your skin, simultaneously freezing and scalding. Beneath the surface, something brushes against your legs—tendrils? Currents with purpose? But when the pain subsides, you feel... denser somehow. More substantial. | R2: gain_max_hp 1; lose_hp 2 | S2: Linger | T2: Again | U2: The temperature keeps rising! How long can you endure before the steam cooks you from within? || It keeps getting hotter! The pool's bubbling sounds like laughter. IT'S SO HOT! || You wonder if this is what it's like to live in the Village of Demons? You have bathed so long you have lost track of time and your mind... It's nice in here. Really fantastic. || If you bathe any longer you will die. | V2: needs Immerse > 0; gain_max_hp 1; lose_hp {3+X} | W2: Abstain | Y2: You decline the temptation of the waters, instead gathering crystalline salts that have formed along the edges. As you apply them to your skin, the pools churn and froth agitatedly. | Z2: needs Immerse = 0; gain_hp 3 | AA2: Exit Baths | AC2: The heat finally gets to you, and you hop out of the bath. | AD2: needs Immerse > 0; nothing
A3: Arcade Room | B3: The Binding of Isaac | C3: All | E3: gold>=1 | F3: After | G3: Common | H3: ArcadeRoom | O3: Enter | P3: Stay | R3: lose_gold 1; spawn_object tag=arcade 2-3 | S3: Leave | V3: nothing
A4: Battleworn Dummy | B4: Slay the Spire 2 | C4: All | F4: After | G4: Common | H4: BattlewornDummy | I4: As you approach, it begins to rumble and fizzle and lights up brilliantly! "BZZZT! TIME TO TRAIN!!! YOU HAVE 3 TURNS TO DEFEAT ME! CHOOSE A SETTING OR FACE LETHAL HUMILIATION." | K4: "YOU PASS THE TRAINING! YOU ARE NOW EQUIPPED TO DEFEND THIS FACTORY AGAINST INTRUDERS!! BE SURE TO HYDRATE AFTER TRAINING SESSIONS!" | L4: "YOU ARE WEAK!! HUMILIATION HAS BEEN ADMINISTERED!" The dummy is silent for a moment and— "Choose a lower setting next time." | O4: Setting 1 | R4: add_goal "beat a game in 5 attempts or fewer" for 3 games -> gain_potion 1 | S4: Setting 2 | V4: add_goal "beat a game in 3 attempts or fewer" for 3 games -> gain_chest small 1 | W4: Setting 3 | Z4: add_goal "beat a game in 1 attempt" for 3 games -> gain_chest large 1
A5: Golden Idol | B5: Slay the Spire | C5: All | F5: After | G5: Common | H5: GoldenIdol | I5: You come across an inconspicuous pedestal with a shining gold idol sitting peacefully atop. It looks incredibly valuable. You sure don't see any traps nearby. | O5: Take | P5: Stay | Q5: As you grab the Idol and stow it away, a giant boulder smashes through the ceiling into the ground next to you. You realize that the floor is slanted downwards as the boulder starts to roll towards you. | R5: gain_item golden_idol | S5: Leave | U5: If there was ever an obvious trap, this would be it. You decide not to interfere with objects placed upon pedestals. | V5: needs Take = 0; nothing | W5: Outrun | Y5: RUUUUUUUUUUN! You barely leap into a side passageway as the boulder rushes by. Unfortunately it feels like you sprained something however. | Z5: needs Take > 0; lose_hp {max(1,round(0.25*MAX_HP))} | AA5: Smash | AC5: You throw yourself at the boulder with everything you have. When the dust clears, you can make a safe way out. | AD5: needs Take > 0; add_curse injury | AE5: Hide | AG5: SQUISH! The boulder flattens you a little as it passes by, but otherwise you can get out of here. | AH5: needs Take > 0; lose_max_hp {max(1,round(0.08*MAX_HP))}
A6: Golden Monkey | B6: Tiny Rogues | C6: All | F6: After | G6: Common | H6: GoldenMonkey | O6: Touch the Golden Monkey | R6: gain_stat luck 1; add_curse random | S6: Leave | V6: nothing
A7: Jungle Maze Adventure | B7: Slay the Spire 2 | C7: All | F7: After | G7: Common | H7: JungleMazeAdventure | I7: In a clearing, you run into a Ragtag Group of Adventurers looking down and gesturing at a gigantic maze. They offer to join forces with you in an Epic Quest to loot the riches of this maze. As an experienced adventurer yourself, it's clear this maze is filled with deadly traps and guardians. It would be easier if you work together, but then you would have to split the loot. | O7: Solo Quest | Q7: Feeling misanthropic, you wordlessly walk past their now-frowning faces. One of them even shakes their fist at you. The maze is not welcoming. You fall into a spike trap, you are struck by a massive log with spikes, and feisty creatures with spiky clubs fight you along the entire journey. You are sick of spikes, and consider teamwork for the next adventure. | R7: gain_gold 3; lose_hp 2 | S7: Join Forces | U7: Everyone's face immediately lights up, including your own! One of the adventurers turns out to be a bard! You merrily waltz into the maze as Aquid the squid wizard effortlessly disarms traps, while you and the Grathorian fighter take out the spiky club-wielding guards with ease. This was the most joyous adventure of your life and you've made some truly Great Memories. | V7: gain_gold 1
A8: Morphic Grove | B8: Slay the Spire 2 | C8: All | E8: gold >=3 | F8: After | G8: Common | H8: MorphicGrove | I8: You enter a grove of crystalline trees, and they begin to quiver excitedly! A chorus of hellos and welcomes bombard you as a group of Morphics burst forth from trees. One of the Morphics is fidgeting in the corner, clearly not as sociable as the others. Approach the group or the loner? | O8: Group | Q8: You greet the chittering Morphics and they embrace you into their crystally arms. They share their combined knowledge and inject you with Morphic Magic, changing your nature... Such lovely creatures, these Morphics. One of them stole your gold. | R8: gain_stat transmute 2; lose_gold all | S8: Loner | U8: You reach out a hand to the lone Morphic, sympathizing with its nature. It gifts you a tiny crystal fruit, and you consume it, as is custom. The fruit clarifies your mind and purpose. You give thanks, then make your way onwards. | V8: gain_max_hp 1
A9: Potion Lab | B9: Tiny Rogues | C9: All | F9: After | G9: Rare | H9: PotionLab | J9: offer_loot potion 3 | O9: Leave | R9: nothing
A10: Punch Off | B10: Slay the Spire 2 | C10: All | E10: games >= 6 | F10: After | G10: Common | H10: PunchOff | I10: Two Punch Constructs are duking it out and you see some treasure in between them... Should you try to nab it? | O10: Nab | Q10: You successfully nab the relic! ...or so you thought. A right-hook clocks you in the face. | R10: add_curse injury; gain_chest small 1 | S10: I Can Take Them | U10: The Constructs turn to you menacingly! | V10: spawn_enemy tag=robot 1; play_game tag=mecha -> gain_loot 1; gain_chest small 2
A11: Ranwid the Elder | B11: Slay the Spire 2 | C11: All | E11: gold>=2 and potions>=1 and relics>=1 | F11: After | G11: Common | H11: RanwidTheElder | I11: You are approached by the oldest person you have ever seen. “We meet once more... it's me, Ranwid!” You do not know this man. | O11: Give 2 Gold | Q11: “Mag.. nificent...” Ranwid mumbles while chewing the gold. | R11: needs gold 2; lose_gold 2; gain_random_item 1 | S11: Give <potion> | U11: “Exquisite...” Glup glup glup. He downs the <potion> in one go. | V11: lose_potion; gain_random_item 1 | W11: Give <relic> | Y11: “Exemplary...” Ranwid observes the relic studiously for several minutes... Then eats the <relic>. | Z11: lose_relic; gain_random_item 2
A12: Relic Trader | B12: Slay the Spire 2 | C12: All | E12: relics >= 5 | F12: After | G12: Common | H12: RelicTrader | I12: You turn a corner and suddenly, a shadowy figure is just standing there. He pivots to face you. “Welcome! What're ya trading?” The figure inquires as he flares open his cloak to reveal a slew of suspicious wares. | O12: Take the Top One | Q12: “Hehehe Heh... Thank you!” | R12: trade_relic 1 | S12: Take the Middle One | U12: “Hehehe Heh... Thank you!” | V12: trade_relic 2 | W12: Take the Bottom One | Y12: “Hehehe Heh... Thank you!” | Z12: trade_relic 3
