Workbook

Sheet games
A1: Name | B1: Year | C1: Type | D1: Connected? | E1: Influencer? | F1: Tags | G1: File | H1: Owned | I1: File Location | J1: Steam Page
A2: [Redacted] | B2: 2024 | C2: Action | D2: =TRUE() -> TRUE | E2: =COUNTIF(connections!A:A, A2) > 0 -> FALSE | G2: redacted
A3: 100 Rogues | B3: 2010 | C3: Traditional | D3: =TRUE() -> TRUE | E3: =COUNTIF(connections!A:A, A3) > 0 -> TRUE | G3: 100-rogues
A4: 2 Fights in 2 Tight Spaces | B4: 2026 | C4: Deckbuilder | D4: =TRUE() -> TRUE | E4: =COUNTIF(connections!A:A, A4) > 0 -> FALSE | G4: 2-fights-in-2-tight-spaces | J4: https://store.steampowered.com/app/3734890/2_Fights_in_2_Tight_Spaces/
A5: 20 Minutes Till Dawn | B5: 2022 | C5: Action | D5: =TRUE() -> TRUE | E5: =COUNTIF(connections!A:A, A5) > 0 -> TRUE | G5: 20-minutes-till-dawn | H5: Yes | I5: C:\Users\Owner\Documents\Roguelike Roguelike\Roguelikes\20 Minutes Till Dawn.url | J5: https://store.steampowered.com/app/1966900/20_Minutes_Till_Dawn/
A6: 20XX | B6: 2017 | C6: Action | D6: =TRUE() -> TRUE | E6: =COUNTIF(connections!A:A, A6) > 0 -> TRUE | G6: 20xx | H6: Yes | I6: C:\Users\Owner\Documents\Roguelike Roguelike\Roguelikes\20XX.url | J6: https://store.steampowered.com/app/322110/20XX/
A7: 30XX | B7: 2021 | C7: Action | D7: =TRUE() -> TRUE | E7: =COUNTIF(connections!A:A, A7) > 0 -> FALSE | G7: 30xx | H7: Yes | I7: C:\Users\Owner\Documents\Roguelike Roguelike\Roguelikes\30XX.url | J7: https://store.steampowered.com/app/1029210/30XX/
A8: 33 Immortals | B8: 2026 | C8: Action | D8: =TRUE() -> TRUE | E8: =COUNTIF(connections!A:A, A8) > 0 -> FALSE | F8: hell | G8: 33-immortals | H8: Yes | I8: C:\Users\Owner\Documents\Roguelike Roguelike\Roguelikes\33 Immortals.url | J8: https://store.steampowered.com/app/958520/33_Immortals/
A9: 868-Back | B9: 2026 | C9: Traditional | D9: =TRUE() -> TRUE | E9: =COUNTIF(connections!A:A, A9) > 0 -> FALSE | G9: 868-back | J9: https://store.steampowered.com/app/3304110/868BACK/
A10: 868-Hack | B10: 2015 | C10: Traditional | D10: =TRUE() -> TRUE | E10: =COUNTIF(connections!A:A, A10) > 0 -> TRUE | G10: 868-hack | H10: Yes | I10: C:\Users\Owner\Documents\Roguelike Roguelike\Roguelikes\868-HACK.url | J10: https://store.steampowered.com/app/274700/868HACK/
A11: 9 Kings | B11: 2024 | C11: Deckbuilder | D11: =TRUE() -> TRUE | E11: =COUNTIF(connections!A:A, A11) > 0 -> TRUE | G11: 9-kings | H11: Yes | I11: C:\Users\Owner\Documents\Roguelike Roguelike\Roguelikes\9 Kings.url | J11: https://store.steampowered.com/app/2784470/9_Kings/
A12: 99 Levels to Hell | B12: 2013 | C12: Action | D12: =TRUE() -> TRUE | E12: =COUNTIF(connections!A:A, A12) > 0 -> FALSE | F12: hell | G12: 99-levels-to-hell
A13: A la Card | B13: 2025 | C13: Deckbuilder | D13: =TRUE() -> TRUE | E13: =COUNTIF(connections!A:A, A13) > 0 -> FALSE | G13: a-la-card
A14: A Robot Named Fight! | B14: 2017 | C14: Action | D14: =TRUE() -> TRUE | E14: =COUNTIF(connections!A:A, A14) > 0 -> FALSE | G14: a-robot-named-fight | H14: Yes | I14: C:\Users\Owner\Documents\Roguelike Roguelike\Roguelikes\A Robot Named Fight.url | J14: https://store.steampowered.com/app/603530/A_Robot_Named_Fight/
A15: Abandon Ship | B15: 2019 | C15: Strategy | D15: =TRUE() -> TRUE | E15: =COUNTIF(connections!A:A, A15) > 0 -> FALSE | G15: abandon-ship | H15: Yes | I15: C:\Users\Owner\Documents\Roguelike Roguelike\Roguelikes\Abandon Ship.url | J15: https://store.steampowered.com/app/551860/Abandon_Ship/
A16: Abandoned Archive | B16: 2025 | C16: Action | D16: =TRUE() -> TRUE | E16: =COUNTIF(connections!A:A, A16) > 0 -> FALSE | G16: abandoned-archive
A17: Absolum | B17: 2025 | C17: Action | D17: =TRUE() -> TRUE | E17: =COUNTIF(connections!A:A, A17) > 0 -> FALSE | F17: beat 'em up | G17: absolum | H17: Yes | I17: C:\Users\Owner\Documents\Roguelike Roguelike\Roguelikes\Absolum.url | J17: https://store.steampowered.com/app/1904480/Absolum/
A18: Abyssus | B18: 2025 | C18: Action | D18: =TRUE() -> TRUE | E18: =COUNTIF(connections!A:A, A18) > 0 -> FALSE | G18: abyssus | H18: Yes | I18: C:\Users\Owner\Documents\Roguelike Roguelike\Roguelikes\Abyssus.url | J18: https://store.steampowered.com/app/1721110/Abyssus/
A19: Aces & Adventures | B19: 2023 | C19: Deckbuilder | D19: =TRUE() -> TRUE | E19: =COUNTIF(connections!A:A, A19) > 0 -> FALSE | G19: aces-adventures | H19: Yes | I19: C:\Users\Owner\Documents\Roguelike Roguelike\Roguelikes\Aces and Adventures.url | J19: https://store.steampowered.com/app/1815570/Aces__Adventures/
A20: Across the Obelisk | B20: 2021 | C20: Deckbuilder | D20: =TRUE() -> TRUE | E20: =COUNTIF(connections!A:A, A20) > 0 -> TRUE | G20: across-the-obelisk | H20: Yes | I20: C:\Users\Owner\Documents\Roguelike Roguelike\Roguelikes\Across the Obelisk.url | J20: https://store.steampowered.com/app/1385380/Across_the_Obelisk/
A21: Aethermancer | B21: 2025 | C21: Strategy | D21: =TRUE() -> TRUE | E21: =COUNTIF(connections!A:A, A21) > 0 -> TRUE | G21: aethermancer | H21: Yes | I21: C:\Users\Owner\Documents\Roguelike Roguelike\Roguelikes\Aethermancer.url | J21: https://store.steampowered.com/app/2288470/Aethermancer/
A22: AK-xolotl | B22: 2023 | C22: Action | D22: =TRUE() -> TRUE | E22: =COUNTIF(connections!A:A, A22) > 0 -> FALSE | G22: ak-xolotl | H22: Yes | I22: C:\Users\Owner\Documents\Roguelike Roguelike\Roguelikes\AK-xolotl Together.url | J22: https://store.steampowered.com/app/1479140/AKxolotl_Together/
A23: Alina of the Arena | B23: 2022 | C23: Deckbuilder | D23: =TRUE() -> TRUE | E23: =COUNTIF(connections!A:A, A23) > 0 -> FALSE | G23: alina-of-the-arena | H23: Yes | I23: C:\Users\Owner\Documents\Roguelike Roguelike\Roguelikes\Alina of the Arena.url | J23: https://store.steampowered.com/app/1668690/Alina_of_the_Arena/
A24: An Amazing Wizard | B24: 2025 | C24: Action | D24: =TRUE() -> TRUE | E24: =COUNTIF(connections!A:A, A24) > 0 -> FALSE | G24: an-amazing-wizard | J24: https://store.steampowered.com/app/1372660/An_Amazing_Wizard/
A25: Ancient Domains of Mystery | B25: 1994 | C25: Traditional | D25: =TRUE() -> TRUE | E25: =COUNTIF(connections!A:A, A25) > 0 -> TRUE | G25: ancient-domains-of-mystery | H25: Yes | I25: C:\Users\Owner\Documents\Roguelike Roguelike\Roguelikes\ADOM (Ancient Domains Of Mystery).url | J25: https://store.steampowered.com/app/333300/ADOM_Ancient_Domains_Of_Mystery/
A26: Angband | B26: 1990 | C26: Traditional | D26: =TRUE() -> TRUE | E26: =COUNTIF(connections!A:A, A26) > 0 -> TRUE | G26: angband | H26: Yes | I26: C:\Users\Owner\Documents\Roguelike Roguelike\Roguelikes\angband.lnk
A27: Anomaly Collapse | B27: 2024 | C27: Strategy | D27: =TRUE() -> TRUE | E27: =COUNTIF(connections!A:A, A27) > 0 -> FALSE | G27: anomaly-collapse | J27: https://store.steampowered.com/app/2082410/Anomaly_Collapse/
A28: Another Farm Roguelike | B28: 2022 | C28: Strategy | D28: =FALSE() -> FALSE | E28: =COUNTIF(connections!A:A, A28) > 0 -> TRUE | F28: food | G28: another-farm-roguelike | H28: Yes | I28: C:\Users\Owner\Documents\Roguelike Roguelike\Roguelikes\Another Farm Roguelike.url | J28: https://store.steampowered.com/app/2116850/Another_Farm_Roguelike/
A29: Another Farm Roguelike: Rebirth | B29: 2025 | C29: Strategy | D29: =FALSE() -> FALSE | E29: =COUNTIF(connections!A:A, A29) > 0 -> FALSE | F29: food | G29: another-farm-roguelike-rebirth
A30: Aotenjo: Infinite Hands | B30: 2024 | C30: Deckbuilder | D30: =TRUE() -> TRUE | E30: =COUNTIF(connections!A:A, A30) > 0 -> FALSE | F30: mahjong | G30: aotenjo-infinite-hands
A31: Approaching Infinity | B31: 2020 | C31: Traditional | D31: =TRUE() -> TRUE | E31: =COUNTIF(connections!A:A, A31) > 0 -> FALSE | F31: space | G31: approaching-infinity
A32: Arc Seed | B32: 2024 | C32: Deckbuilder | D32: =TRUE() -> TRUE | E32: =COUNTIF(connections!A:A, A32) > 0 -> FALSE | F32: mecha | G32: arc-seed | H32: Yes | I32: C:\Users\Owner\Documents\Roguelike Roguelike\Roguelikes\ARC SEED.url | J32: https://store.steampowered.com/app/2332970/ARC_SEED/
A33: Arcane Trigger | B33: 2025 | C33: Action | D33: TRUE | E33: =COUNTIF(connections!A:A, A33) > 0 -> FALSE | G33: arcane-trigger
A34: Arcanium: Rise of Akhan | B34: 2020 | C34: Deckbuilder | D34: =TRUE() -> TRUE | E34: =COUNTIF(connections!A:A, A34) > 0 -> FALSE | G34: arcanium-rise-of-akhan | H34: Yes | I34: C:\Users\Owner\Documents\Roguelike Roguelike\Roguelikes\Arcanium.url | J34: https://store.steampowered.com/app/1056840/Arcanium_Rise_of_Akhan/
A35: Archon Soul | B35: 2026 | C35: Deckbuilder | D35: =TRUE() -> TRUE | E35: =COUNTIF(connections!A:A, A35) > 0 -> FALSE | G35: archon-soul | J35: https://store.steampowered.com/app/4252700/Archon_Soul/
A36: Archons | B36: 2024 | C36: Action | D36: =TRUE() -> TRUE | E36: =COUNTIF(connections!A:A, A36) > 0 -> FALSE | G36: archons | H36: Yes | I36: C:\Users\Owner\Documents\Roguelike Roguelike\Roguelikes\Archons.url | J36: https://store.steampowered.com/app/2779570/Archons/
A37: Arms of God | B37: 2026 | C37: Action | D37: =TRUE() -> TRUE | E37: =COUNTIF(connections!A:A, A37) > 0 -> FALSE | G37: arms-of-god | J37: https://store.steampowered.com/app/3100310/Arms_of_God/
A38: Army of Ruin | B38: 2022 | C38: Action | D38: =TRUE() -> TRUE | E38: =COUNTIF(connections!A:A, A38) > 0 -> FALSE | G38: army-of-ruin | H38: Yes | I38: C:\Users\Owner\Documents\Roguelike Roguelike\Roguelikes\Army of Ruin.url | J38: https://store.steampowered.com/app/1918040/Army_of_Ruin/
A39: Arrogue | B39: 2025 | C39: Deckbuilder | D39: =TRUE() -> TRUE | E39: =COUNTIF(connections!A:A, A39) > 0 -> FALSE | G39: arrogue
A40: As We Descend | B40: 2025 | C40: Deckbuilder | D40: =TRUE() -> TRUE | E40: =COUNTIF(connections!A:A, A40) > 0 -> FALSE | G40: as-we-descend
...

Sheet connections
A1: Influencer | B1: Influencee | C1: Influencer Time | D1: Dev/Series Relation | E1: Source | F1: Proof
A2: Hades | B2: [Redacted] | C2: 2019 | E2: look at it
A3: Mystery Dungeon 2: Shiren the Wanderer | B3: 100 Rogues | C3: 1995 | E3: https://www.gamedeveloper.com/business/marketing-on-the-app-store-the-cautionary-tale-of-i-100-rogues-i- | F3: mystery_dungeon_2_shiren_the_wanderer---100_rogues
A4: Powder | B4: 100 Rogues | C4: 2003 | E4: https://www.gamedeveloper.com/business/marketing-on-the-app-store-the-cautionary-tale-of-i-100-rogues-i- | F4: powder---100_rogues
A5: Fights in Tight Spaces | B5: 2 Fights in 2 Tight Spaces | C5: 2021 | D5: Yes
A6: Vampire Survivors | B6: 20 Minutes Till Dawn | C6: 2021 | E6: look at it
A7: Crypt of the NecroDancer | B7: 20XX | C7: 2015 | E7: https://www.reddit.com/r/IAmA/comments/4po4pn/i_am_the_developer_of_20xx_the_megaman_xinspired/ | F7: crypt_of_the_necrodancer---20xx
A8: The Binding of Isaac | B8: 20XX | C8: 2011 | E8: https://www.reddit.com/r/IAmA/comments/4po4pn/i_am_the_developer_of_20xx_the_megaman_xinspired/ | F8: the_binding_of_isaac---20xx
A9: 20XX | B9: 30XX | C9: 2017 | D9: Yes
A10: Realm of the Mad God | B10: 33 Immortals | C10: 2010 | E10: check folder | F10: realm_of_the_mad_god---33_immortals
A11: Sundered | B11: 33 Immortals | C11: 2017 | D11: Yes
A12: 868-Hack | B12: 868-Back | C12: 2015 | D12: Yes
A13: Rogue | B13: 868-Hack | C13: 1980 | E13: https://www.gamedeveloper.com/design/how-michael-brough-s-love-of-exploring-a-single-game-mechanic-beget-i-cinco-paus-i- | F13: rogue---868_hack
A14: Seraph's Last Stand | B14: 9 Kings | C14: 2022 | D14: Yes
A15: Slay the Spire | B15: 9 Kings | C15: 2017 | E15: https://www.youtube.com/watch?v=9fxnPkfyHuA
A16: Spelunky Classic | B16: 99 Levels to Hell | C16: 2008 | E16: https://youtu.be/wJ2cgBoxsi4
A17: The Binding of Isaac | B17: 99 Levels to Hell | C17: 2011 | E17: https://youtu.be/wJ2cgBoxsi4
A18: Slay the Spire | B18: A la Card | C18: 2017 | E18: check folder | F18: slay_the_spire---a_la_card
A19: The Binding of Isaac | B19: A Robot Named Fight! | C19: 2011 | E19: https://www.reddit.com/r/NintendoSwitch/comments/8jv8rd/im_matt_bitner_sole_developer_of_a_robot_named/#:~:text=I%20left%20my%20old%20job,as%20The%20Binding%20of%20Isaac. | F19: the_binding_of_isaac---a_robot_named_fight
A20: FTL | B20: Abandon Ship | C20: 2012 | E20: https://bigbossbattle.com/abandon-ship-interview-fireblade-softwares-gary-burchell/ | F20: ftl---abandon_ship
A21: Enter the Gungeon | B21: Abandoned Archive | C21: 2016 | E21: https://www.reddit.com/r/playmygame/comments/sqb852/our_spellcasting_roguelike_abandoned_archive_now/ | F21: enter_the_gungeon---abandoned_archive
A22: Wizard of Legend | B22: Abandoned Archive | C22: 2018 | E22: https://www.reddit.com/r/playmygame/comments/sqb852/our_spellcasting_roguelike_abandoned_archive_now/ | F22: wizard_of_legend---abandoned_archive
A23: Dead Cells | B23: Absolum | C23: 2018 | E23: https://www.polygon.com/absolum-roguelike-interview-dotemu-guard-crush/ | F23: dead_cells---absolum
A24: Gunfire Reborn | B24: Abyssus | C24: 2020 | E24: https://steamcommunity.com/app/1721110/discussions/0/600775708393865281/ | F24: gunfire_reborn---abyssus
A25: Nuclear Throne | B25: Abyssus | C25: 2015 | E25: https://steamcommunity.com/app/1721110/discussions/0/600775708393865281/ | F25: nuclear_throne---abyssus
A26: Roboquest | B26: Abyssus | C26: 2020 | E26: https://steamcommunity.com/app/1721110/discussions/0/600775708393865281/ | F26: roboquest---abyssus
A27: Popup Dungeon | B27: Aces & Adventures | C27: 2020 | E27: https://creators.spotify.com/pod/show/the-indie-diarist/episodes/Indie-Diary-5-Enrique-Dryere-Triple-B-Titles---Creativity-as-Sacrifice--Secrets-of-Inspiration--DnD-and----Poker-e207m5b
A28: Slay the Spire | B28: Aces & Adventures | C28: 2017 | E28: https://creators.spotify.com/pod/show/the-indie-diarist/episodes/Indie-Diary-5-Enrique-Dryere-Triple-B-Titles---Creativity-as-Sacrifice--Secrets-of-Inspiration--DnD-and----Poker-e207m5b
A29: Darkest Dungeon | B29: Across the Obelisk | C29: 2015 | E29: duh also check the folder for proof | F29: darkest_dungeon---across_the_obelisk
A30: Slay the Spire | B30: Across the Obelisk | C30: 2017 | E30: duh also the devs talk about loving sts in discord
A31: Dead Cells | B31: Aethermancer | C31: 2018 | E31: check folder | F31: dead_cells---aethermancer
A32: Enter the Gungeon | B32: AK-xolotl | C32: 2016 | E32: https://www.reddit.com/r/Games/comments/v2kcsr/ama_were_the_team_behind_akxolotl_a_cute_but/ | F32: enter_the_gungeon---ak_xolotl
A33: Nuclear Throne | B33: AK-xolotl | C33: 2015 | E33: https://www.reddit.com/r/Games/comments/v2kcsr/ama_were_the_team_behind_akxolotl_a_cute_but/ | F33: nuclear_throne---ak_xolotl
A34: Into the Breach | B34: Alina of the Arena | C34: 2018 | E34: https://store.steampowered.com/app/1668690/Alina_of_the_Arena/#:~:text=About%20This%20Game-,ABOUT,and%20'Into%20the%20Breach'. | F34: into_the_breach---alina_of_the_arena
A35: Slay the Spire | B35: Alina of the Arena | C35: 2017 | E35: https://store.steampowered.com/app/1668690/Alina_of_the_Arena/#:~:text=About%20This%20Game-,ABOUT,and%20'Into%20the%20Breach'. | F35: slay_the_spire---alina_of_the_arena
A36: Dead Cells | B36: An Amazing Wizard | C36: 2018 | E36: https://x.com/AnAmazingWizard/status/1489554155597352962?s=20 | F36: dead_cells---an_amazing_wizard
A37: Hades | B37: An Amazing Wizard | C37: 2019 | E37: https://x.com/AnAmazingWizard/status/1489554155597352962?s=20 | F37: hades---an_amazing_wizard
A38: The Binding of Isaac | B38: An Amazing Wizard | C38: 2011 | E38: https://x.com/AnAmazingWizard/status/1489554155597352962?s=20 | F38: the_binding_of_isaac---an_amazing_wizard
A39: Hack | B39: Ancient Domains of Mystery | C39: 1984 | E39: https://roguebasin.com/index.php/ADOM | F39: hack---ancient_domains_of_mystery
A40: NetHack | B40: Ancient Domains of Mystery | C40: 1987 | E40: https://www.gamedeveloper.com/design/-play-86-interview-with-adom-creator-dr-thomas-biskup | F40: nethack---ancient_domains_of_mystery
...

Sheet characters
A1: Name | B1: Game | C1: Health | D1: Gold | E1: Bash | F1: Dash | G1: Push | H1: Transmute | I1: Scramble | J1: Bombs | K1: Keys | L1: Random | M1: Level Up | N1: Reward | O1: Description | P1: Starting loadout | Q1: File
A2: Antonio Belpaese | B2: Vampire Survivors | C2: 7 | D2: 3 | E2: 1 | F2: 0 | G2: 1 | H2: 0 | I2: 0 | J2: 0 | K2: 0 | L2: 0 | M2: Beat a game while having defeated a vampire | N2: Gain +1 Random Sized Chest | O2: What a wonderful night to hunt beasts! | P2: Whip | Q2: AntonioBelpaese
A3: Erratic Deck | B3: Balatro | C3: 7 | D3: 3 | E3: 0 | F3: 0 | G3: 0 | H3: 0 | I3: 0 | J3: 0 | K3: 0 | L3: 2 | M3: Beat a game while having selected a random starting build | N3: Gain +1 Random Card | O3: All Ranks and Suits in deck are randomized | P3: 1 random joker card | Q3: ErraticDeck
A4: Ironclad | B4: Slay the Spire | C4: 8 | D4: 3 | E4: 2 | F4: 0 | G4: 0 | H4: 0 | I4: 0 | J4: 0 | K4: 0 | L4: 0 | M4: Beat a game while having made a Faustian bargain | N4: Gain +1 Small Chest | O4: The remaining soldier of the Ironclads. Sold his soul to harness demonic energies. | P4: Burning Blood | Q4: Ironclad
A5: Isaac | B5: The Binding of Isaac | C5: 6 | D5: 3 | E5: 0 | F5: 0 | G5: 0 | H5: 0 | I5: 0 | J5: 1 | K5: 0 | L5: 0 | M5: Beat a game while having used sorrow or self-inflicted pain as a weapon | N5: Gain +1 Small Chest and +1 Scramble | O5: Who am I? | P5: D6 | Q5: Isaac
A6: Manager | B6: Raccoin: Coin Pusher Roguelike | C6: 7 | D6: 3 | E6: 0 | F6: 0 | G6: 2 | H6: 0 | I6: 0 | J6: 0 | K6: 0 | L6: 0 | M6: Beat a game while having collected 3 different types of currency | N6: Gain +1 Push and +1 Gold | O6: Master in using Math coins and earning tickets. | P6: N/A | Q6: Manager
A7: Minä | B7: Noita | C7: 7 | D7: 3 | E7: 0 | F7: 0 | G7: 0 | H7: 2 | I7: 0 | J7: 0 | K7: 0 | L7: 0 | M7: Beat a game while having crafted or combined a spell or weapon | N7: Gain +1 Transmute | O7: Why must you go destroying everything? Why? For glory? For your precious god of gods. Is it really worth all this? Is it? Is it really? | P7: 1 random wand | Q7: Minä
A8: Poe Ratcho | B8: Vampire Survivors | C8: 7 | D8: 3 | E8: 0 | F8: 0 | G8: 2 | H8: 0 | I8: 0 | J8: 0 | K8: 0 | L8: 0 | M8: Beat a game while being stinky | N8: Gain +1 Random Sized Chest | O8: A malodorous hero | P8: Pummarola | Q8: PoeRatcho
A9: Regent | B9: Slay the Spire 2 | C9: 7 | D9: 3 | E9: 0 | F9: 0 | G9: 1 | H9: 1 | I9: 0 | J9: 0 | K9: 0 | L9: 0 | M9: Beat a game while having made a friend | N9: Gain +1 Small Chest | O9: Heir to the Throne of Stars. Wields cosmic powers but his minions do the work. | P9: N/A | Q9: Regent
A10: Rodney | B10: Rogue | C10: 5 | D10: 3 | E10: 0 | F10: 0 | G10: 0 | H10: 0 | I10: 0 | J10: 0 | K10: 0 | L10: 2 | M10: Beat a game without meta progression | N10: Gain +1 Max Health and +1 Loot | O10: Now I abide here, searching endlessly for the precious Amulet... and finding a thousand horrors. | P10: N/A | Q10: Rodney
A11: Zagreus | B11: Hades | C11: 7 | D11: 3 | E11: 1 | F11: 1 | G11: 0 | H11: 0 | I11: 0 | J11: 0 | K11: 0 | L11: 0 | M11: Beat a game with the help of a God | N11: Gain +1 Large Chest | O11: ... All right, let's give it another shot. | P11: N/A | Q11: Zagreus
A12: Zoe | B12: Haste | C12: 7 | D12: 3 | E12: 0 | F12: 1 | G12: 1 | H12: 0 | I12: 0 | J12: 0 | K12: 0 | L12: 0 | M12: Perfect a game by beating it without losing | N12: Gain +1 Dash | O12: Express Delivery: Arrives with haste, before the world ends. | P12: N/A | Q12: Zoe

Sheet items
A1: Name | B1: Rating | C1: Type | D1: Description | E1: Effect | F1: Reference | G1: tags | H1: pools | I1: File | J1: Sorting
A2: Alien Baby | B2: Rare | C2: Pickup, Passive | D2: Gain +6 Max Health, but all enemies gain +1 Health | E2: item_acquired: gain_max_hp 6; passive: +1 enemy_health | F2: Brotato | G2: alien | I2: AlienBaby | J2: Health
A3: Anchor | B3: Common | C3: Triggered | D3: At the start of combat, Gain +1 Temporary Shield | E3: game_selected: gain_stat shields 1 | F3: Slay the Spire | G3: sea, ship | I3: Anchor | J3: Defense
A4: Ban Hammer | B4: Uncommon | C4: Pickup | D4: Gain +2 Bashes | E4: item_acquired: gain_stat bash 2 | F4: Yet Another Zombie Survivors | G4: tool, hammer | I4: BanHammer | J4: Stats
A5: Bionic Face Plating | B5: Uncommon | C5: Passive | D5: Gain +3 Speed, but this is destroyed when taking damage | E5: passive_status: speed 3; destroy_on_damage | F5: Mewgenics | G5: cybernetics | I5: BionicFacePlating | J5: Stats
A6: Blood Bag | B6: Event | C6: Pickup | D6: Gain +2 Max Health and +8 Health | E6: item_acquired: gain_max_hp 2; gain_hp 8 | F6: The Binding of Isaac | G6: blood | I6: BloodBag | J6: Health
A7: Blood Bombs | B7: Uncommon | C7: Pickup, Triggered | D7: Gain +1 Bomb. When using a Bomb, Gain +1 Health | E7: item_acquired: gain_stat bombs 1; bomb_used: gain_hp 1 | F7: The Binding of Isaac: Rebirth | G7: bomb, blood | I7: BloodBombs | J7: Bomb
A8: Brimstone Bombs | B8: Rare | C8: Pickup, Passive | D8: Gain +1 Bomb. Bombs now apply 1 Stun to all rows in the 4 cardinal directions | E8: item_acquired: gain_stat bombs 1; bomb_cardinal | F8: The Binding of Isaac: Rebirth | G8: bomb | H8: devil_room | I8: BrimstoneBombs | J8: Bomb, Grid
A9: Burning Blood | B9: Starter | C9: Triggered | D9: After beating a game, Gain +1 Health | E9: game_beaten: gain_hp 1 | F9: Slay the Spire | I9: BurningBlood | J9: Health
A10: Caffeine Pill | B10: Common | C10: Passive, Pickup | D10: Gain +1 Speed and +1 Pill | E10: passive_status: speed 1; item_acquired: gain_pill 1 | F10: The Binding of Isaac: Rebirth | G10: drugs, pills | I10: CaffeinePill | J10: Loot, Stats
A11: Calling Bell | B11: Boss | C11: Pickup | D11: Obtain Curse of the Bell and 3 random items — one Common, one Uncommon, one Rare | E11: item_acquired: add_curse curse_of_the_bell, gain_item_per_rarity 3 | F11: Slay the Spire | I11: CallingBell | J11: Special
A12: Cauldron | B12: Rare | C12: Pickup | D12: Gain +5 Potions | E12: item_acquired: gain_potion 5 | F12: Slay the Spire | G12: pot | H12: shop | I12: Cauldron | J12: Loot
A13: Censer | B13: Uncommon | C13: Passive | D13: Enemies in the 2 leftmost columns take no extra turns | E13: front_column_slow 2 | F13: The Binding of Isaac: Rebirth | G13: holy | H13: angel_room | I13: Censer | J13: Combat
A14: Charm of the Vampire | B14: Uncommon | C14: Triggered, Incremental | D14: When you defeat 3 enemies, Gain +1 Health | E14: enemy_killed: counter key=enemies_defeated every=3 -> gain_hp 1 | F14: The Binding of Isaac | G14: bat, vampire | I14: CharmOfTheVampire | J14: Health
A15: Clover | B15: Uncommon | C15: Passive | D15: Gain +1 Luck | E15: passive: +1 luck | F15: Vampire Survivors | G15: plant | I15: Clover | J15: Stats
A16: Crown | B16: Uncommon | C16: Triggered | D16: When Levelling Up, 50% chance to Level Up an additional time | E16: level_up: 50% | F16: Vampire Survivors | G16: wearable, hat, crown | I16: Crown | J16: Economy
A17: D10 | B17: Common | C17: Charged, 2 | D17: Reroll all non-boss enemies | E17: item_used: reroll_enemies | F17: The Binding of Isaac: Rebirth | G17: dice | I17: D10 | J17: Grid
A18: D6 | B18: Uncommon | C18: Charged, 2 | D18: Gain +1 Scramble | E18: item_used: gain_stat scramble 1 | F18: The Binding of Isaac | G18: dice | I18: D6 | J18: Stats
A19: Deck of Cards | B19: Uncommon | C19: Charged, 2 | D19: Gain +1 Card | E19: item_used: gain_card 1 | F19: The Binding of Isaac | I19: DeckOfCards | J19: Loot
A20: Dragon Fruit | B20: Rare | C20: Triggered | D20: Whenever you obtain any amount of gold, Gain +1 Max Health | E20: gold_gained: gain_max_hp 1 | F20: Slay the Spire 2 | G20: food, fruit | H20: shop | I20: DragonFruit | J20: Economy
A21: Echo Chamber | B21: Rare | C21: Passive | D21: Whenever you use Loot, you also use a copy of the last 3 Loot you used after picking up Echo Chamber | E21: echo_loot 3 | F21: The Binding of Isaac: Rebirth | I21: EchoChamber | J21: Loot
A22: Fanny Pack | B22: Uncommon | C22: Passive | D22: 50% chance to spawn 1 random loot on the grid when losing health | E22: health_lost: 50% chance drop_loot 1 | F22: The Binding of Isaac: Rebirth | G22: wearable, bag | I22: FannyPack | J22: Economy
A23: Fortune Necklace | B23: Common | C23: Triggered | D23: When selecting a game, Gain +1 Gold, but this is destroyed when taking damage | E23: game_selected: gain_gold 1; destroy_on_damage | F23: Mewgenics | G23: wearable, necklace | I23: FortuneNecklace | J23: Economy
A24: Gasoline | B24: Common | C24: Passive | D24: Whenever an Enemy is defeated, Add the Fire Tile Effect to the Tile it died on | E24: death_tile fire | F24: Risk of Rain 2 | G24: fire | I24: Gasoline | J24: Grid
A25: Golden Idol | B25: Event | C25: Passive | D25: All enemies drop +1 Gold | E25: gold_per_enemy: 1 | F25: Slay the Spire | G25: gold | I25: GoldenIdol | J25: Economy
A26: Hollow Heart | B26: Common | C26: Pickup | D26: Gain +4 Empty Max Health | E26: item_acquired: gain_empty_max_hp 4 | F26: Vampire Survivors | G26: heart | I26: HollowHeart | J26: Health
A27: Hot Bombs | B27: Uncommon | C27: Passive | D27: Gain +1 Bomb and Bombs Apply the Fire Tile | E27: item_acquired: gain_stat bombs 1; bomb_tile fire | F27: The Binding of Isaac: Rebirth | G27: bomb, fire | I27: HotBombs | J27: Bomb, Grid
A28: Infusion | B28: Uncommon | C28: Triggered | D28: Every time you defeat an Enemy, Gain +1 Empty Max Health | E28: enemy_killed: gain_empty_max_hp 1 | F28: Risk of Rain 2 | G28: blood | I28: Infusion | J28: Health
A29: IV Bag | B29: Event | C29: Usable, 0 | D29: Lose 1 Health and Gain +1 Gold | E29: item_used: lose_hp 1; gain_gold 1 | F29: The Binding of Isaac | G29: blood | I29: IvBag | J29: Economy
A30: Landmines | B30: Uncommon | C30: Passive | D30: After Combat ends, Apply the Landmine Unit to a random empty Tile | E30: game_beaten: apply_unit landmine target=random_empty | F30: Brotato | G30: bomb | I30: Landmines | J30: Grid
A31: Lord's Parasol | B31: Boss | C31: Passive | D31: When encountering a shop, purchase everything in it | E31: shop_sweep | F31: Slay the Spire 2 | G31: umbrella | I31: LordsParasol | J31: Special
A32: Lucky Foot | B32: Uncommon | C32: Passive, Pickup | D32: Gain +1 Luck, +1 Pill, and all negative pills become positive | E32: passive: +1 luck; item_acquired: gain_pill 1; pills_positive | F32: The Binding of Isaac | G32: foot | I32: LuckyFoot | J32: Loot, Stats
A33: Lucky Fysh | B33: Uncommon | C33: Triggered | D33: Whenever you obtain a Card, Gain +1 Gold | E33: card_obtained: gain_gold 1 | F33: Slay the Spire 2 | G33: fish | I33: LuckyFysh | J33: Economy
... A43: Philosophers Stone | B43: Boss | C43: Passive | D43: Increase the Grid length by 1, but give all spawned enemies +1 Strength | E43: grid_length; spawn_status strength 1 | F43: Slay the Spire | G43: stone | I43: PhilosophersStone | J43: Grid
A44: Piggy Bank | B44: Uncommon | C44: Passive | D44: Whenever you lose Health, Gain +1 Gold | E44: health_lost: gain_gold 1 | F44: The Binding of Isaac: Rebirth | G44: pig, bank | H44: shop | I44: PiggyBank | J44: Economy
A45: Pummarola | B45: Uncommon | C45: Triggered | D45: After beating a game, Gain +1 Health | E45: game_beaten: gain_hp 1 | F45: Vampire Survivors | G45: heart | I45: Pummarola | J45: Health
A46: Red Candle | B46: Common | C46: Charged, 1 | D46: Apply the Fire Tile to any tile within the columns 2 and 3 | E46: item_used: apply_tile fire target=tile cols=2-3 | F46: The Binding of Isaac: Rebirth | G46: fire | H46: shop | I46: RedCandle | J46: Grid
A47: Rejuvenation Rack | B47: Rare | C47: Passive | D47: Double the effect of all Healing | E47: heal_multiplier: 2 | F47: Risk of Rain 2 | I47: RejuvenationRack | J47: Health
A48: Reptile Trinket | B48: Uncommon | C48: Triggered | D48: Whenever you drink or throw a potion, Gain +3 Strength until the end of the next combat | E48: potion_used: apply_status strength 3 games=1 | F48: Slay the Spire 2 | I48: ReptileTrinket | J48: Loot, Stats
A49: Ripple Basin | B49: Uncommon | C49: Triggered | D49: If you lose a run before completing any goals, Gain +1 Temporary Shield | E49: run_lost if_goals=0: gain_stat shields 1 | F49: Slay the Spire 2 | I49: RippleBasin | J49: Combat
...

Sheet enemies
A1: Name | B1: Type | C1: Difficulty | D1: Size | E1: Game | F1: Health | G1: Damage | H1: Goal Type | I1: Goal | J1: Ability | K1: File | L1: Tag | M1: Ticked | N1: Count
A2: Attack Fly | B2: Action | C2: 1-Low | D2: 1x1 | E2: The Binding of Isaac | F2: 1 | G2: 1 | H2: Bounty | I2: Defeat 3 bugs | J2: N/A | K2: AttackFly | L2: bug, fly | M2: any time | N2: 3
A3: Baby Alien | B3: Action | C3: 1-Low | D3: 1x1 | E3: Brotato | F3: 1 | G3: 1 | H3: Bounty | I3: Defeat an enemy that is an alien | J3: N/A | K3: BabyAlien | L3: alien | M3: any time
A4: Bullat | B4: Action | C4: 1-Low | D4: 1x1 | E4: Enter the Gungeon | F4: 1 | G4: 1 | H4: Feat | I4: Shoot down a flying enemy | J4: N/A | K4: Bullat | L4: bat, bullet | M4: any time
A5: Doomvas | B5: Action | C5: 1-Low | D5: 1x1 | E5: Rogue Legacy | F5: 1 | G5: 1 | H5: Feat | I5: Destroy a painting | J5: N/A | K5: Doomvas | L5: art | M5: any time
A6: Flaming Fatty | B6: Action | C6: 1-Low | D6: 1x1 | E6: The Binding of Isaac: Rebirth | F6: 1 | G6: 1 | H6: Feat | I6: Push an enemy into fire | J6: Aftermath (Fire) | K6: FlamingFatty | L6: fire | M6: any time
A7: Keybullet Kin | B7: Action | C7: 1-Low | D7: 1x1 | E7: Enter the Gungeon | F7: 1 | G7: 1 | H7: Fetch | I7: Obtain a key | J7: N/A | K7: KeybulletKin | L7: bullet | M7: any time
A8: Lil Dave | B8: Action | C8: 1-Low | D8: 1x1 | E8: Muck | F8: 1 | G8: 1 | H8: Feat | I8: Destroy a wooden structure | J8: N/A | K8: LilDave | M8: any time
A9: Numbskull | B9: Action | C9: 1-Low | D9: 1x1 | E9: Hades | F9: 1 | G9: 1 | H9: Bounty | I9: Defeat an animated body part | J9: N/A | K9: Numbskull | L9: undead, skeleton | M9: any time
A10: Pacer | B10: Action | C10: 1-Low | D10: 1x1 | E10: The Binding of Isaac | F10: 1 | G10: 1 | H10: Bounty | I10: Defeat a headless enemy | J10: N/A | K10: Pacer | M10: any time
A11: Psychic Horf | B11: Action | C11: 1-Low | D11: 1x1 | E11: The Binding of Isaac: Rebirth | F11: 1 | G11: 1 | H11: Feat | I11: Use a homing attack | J11: Ranged (N/A) | K11: PsychicHorf | M11: any time
A12: Skeleton Warrior | B12: Action | C12: 1-Low | D12: 1x1 | E12: Ball x Pit | F12: 1 | G12: 1 | H12: Bounty | I12: Defeat a skeleton with a ball | J12: N/A | K12: SkeletonWarrior | L12: undead, skeleton | M12: any time
A13: Spider | B13: Action | C13: 1-Low | D13: 1x1 | E13: The Binding of Isaac | F13: 1 | G13: 1 | H13: Bounty | I13: Defeat 3 spiders | J13: N/A | K13: Spider | L13: bug, spider | M13: any time | N13: 3
A14: Wisp | B14: Action | C14: 1-Low | D14: 1x1 | E14: Risk of Rain | F14: 1 | G14: 1 | H14: Bounty | I14: Defeat an enemy made of fire | J14: N/A | K14: Wisp | L14: fire | M14: any time
A15: Wringer | B15: Action | C15: 1-Low | D15: 1x1 | E15: Hades | F15: 1 | G15: 1 | H15: Feat | I15: Grab an enemy | J15: N/A | K15: Wringer | L15: undead | M15: any time
A16: Bony | B16: Action | C16: 2-Medium | D16: 1x1 | E16: The Binding of Isaac: Rebirth | F16: 1 | G16: 2 | H16: Bounty | I16: Defeat 5 skeletons | J16: Ranged (3) | K16: Bony | L16: undead, skeleton | M16: any time | N16: 5
A17: Child | B17: Action | C17: 2-Medium | D17: 1x1 | E17: Risk of Rain | F17: 1 | G17: 2 | H17: Bounty | I17: Defeat a child | J17: N/A | K17: Child | L17: alien | M17: any time
A18: Coal Spider | B18: Action | C18: 2-Medium | D18: 1x1 | E18: The Binding of Isaac: Rebirth | F18: 1 | G18: 2 | H18: Feat | I18: Set a rock on fire | J18: N/A | K18: CoalSpider | L18: spider, rock, fire | M18: any time
A19: Flaming Hopper | B19: Action | C19: 2-Medium | D19: 1x1 | E19: The Binding of Isaac | F19: 1 | G19: 2 | H19: Bounty | I19: Defeat an enemy while on fire | J19: Infliction (2, Burn) | K19: FlamingHopper | L19: fire | M19: any time
A20: Fungun | B20: Action | C20: 2-Medium | D20: 1x1 | E20: Enter the Gungeon | F20: 1 | G20: 2 | H20: Feat | I20: Shoot a mushroom | J20: N/A | K20: Fungun | L20: mushroom | M20: any time
A21: King Bullat | B21: Action | C21: 2-Medium | D21: 1x1 | E21: Enter the Gungeon | F21: 1 | G21: 2 | H21: Feat | I21: Shoot down 2 flying enemies | J21: N/A | K21: KingBullat | L21: bat, bullet | M21: any time | N21: 2
A22: Skeletal Brute | B22: Action | C22: 2-Medium | D22: 1x2 | E22: Ball x Pit | F22: 1 | G22: 2 | H22: Bounty | I22: Defeat 2 skeletons with a ball | J22: N/A | K22: SkeletalBrute | L22: undead, skeleton | M22: any time | N22: 2
A23: Bishop | B23: Action | C23: 3-High | D23: 1x1 | E23: The Binding of Isaac: Rebirth | F23: 1 | G23: 3 | H23: Feat | I23: Block damage done to a friendly unit | J23: Bolster (1, Dexterity) | K23: Bishop | M23: any time
A24: Gigantic Vermin | B24: Action | C24: 3-High | D24: 2x2 | E24: Hades | F24: 1 | G24: 3 | H24: Bounty | I24: Defeat a large rodent | J24: N/A | K24: GiganticVermin | L24: rodent, rat | M24: any time
A25: Nemean Chariot | B25: Action | C25: 3-High | D25: 1x1 | E25: Hades | F25: 1 | G25: 3 | H25: Feat | I25: Hit an enemy with a vehicle | J25: Haste (1) | K25: NemeanChariot | M25: any time
A26: Skeletal Bastion | B26: Action | C26: 3-High | D26: 2x3 L 90 CC | E26: Ball x Pit | F26: 1 | G26: 3 | H26: Bounty | I26: Defeat 3 skeletons with a ball | J26: N/A | K26: SkeletalBastion | L26: undead, skeleton | M26: any time | N26: 3
A27: Cultist | B27: Deckbuilder | C27: 1-Low | D27: 1x1 | E27: Slay the Spire | F27: 1 | G27: 1 | H27: Feat | I27: Perform a religious act | J27: Ritual | K27: Cultist | M27: any time
A28: Fungi Beast | B28: Deckbuilder | C28: 1-Low | D28: 1x1 | E28: Slay the Spire | F28: 1 | G28: 1 | H28: Feat | I28: Get infected | J28: N/A | K28: FungiBeast | L28: mushroom | M28: any time
A29: Ice Slime | B29: Deckbuilder | C29: 1-Low | D29: 1x1 | E29: Dungeon Clawler | F29: 1 | G29: 1 | H29: Feat | I29: Freeze an enemy | J29: N/A | K29: IceSlime | L29: slime, ice | M29: any time
A30: Lava Slime | B30: Deckbuilder | C30: 1-Low | D30: 1x1 | E30: Dungeon Clawler | F30: 1 | G30: 1 | H30: Feat | I30: Touch lava | J30: Infliction (1, Burn) | K30: LavaSlime | L30: slime, lava | M30: any time
A31: Punch Construct | B31: Deckbuilder | C31: 1-Low | D31: 1x1 | E31: Slay the Spire 2 | F31: 1 | G31: 1 | H31: Feat | I31: Punch a robot | J31: N/A | K31: PunchConstruct | L31: robot | M31: any time
A32: Shrinker Beetle | B32: Deckbuilder | C32: 1-Low | D32: 1x1 | E32: Slay the Spire 2 | F32: 1 | G32: 1 | H32: Feat | I32: Shrink in size | J32: N/A | K32: ShrinkerBeetle | L32: bug, beetle | M32: any time
A33: Spike Slime (L) | B33: Deckbuilder | C33: 1-Low | D33: 2x2 | E33: Slay the Spire | F33: 1 | G33: 1 | H33: Bounty | I33: Defeat an enemy that splits into another enemy | J33: Split (2, slime tag) | K33: SpikeSlime(L) | L33: slime | M33: any time
A34: Shelled Parasite | B34: Deckbuilder | C34: 2-Medium | D34: 1x1 | E34: Slay the Spire | F34: 1 | G34: 2 | H34: Bounty | I34: Defeat an enemy that looks edible | J34: N/A | K34: ShelledParasite | M34: any time
A35: Snecko | B35: Deckbuilder | C35: 2-Medium | D35: 1x1 | E35: Slay the Spire | F35: 1 | G35: 2 | H35: Restriction | I35: Beat a game while having selected a random starting build | J35: N/A | K35: Snecko | M35: game beaten
A36: The Obscura | B36: Deckbuilder | C36: 2-Medium | D36: 1x1 | E36: Slay the Spire 2 | F36: 1 | G36: 2 | H36: Feat | I36: Create an illusion | J36: Illusionist (1, Random Medium) | K36: TheObscura | M36: any time
A37: Chosen | B37: Deckbuilder | C37: 3-High | D37: 1x1 | E37: Slay the Spire | F37: 1 | G37: 3 | H37: Restriction | I37: Beat a game without using magic | J37: Hexer | K37: Chosen | M37: game beaten
A38: Transient | B38: Deckbuilder | C38: 3-High | D38: 2x2 | E38: Slay the Spire | F38: 1 | G38: 3 | H38: Discovery | I38: Witness an enemy kill itself | J38: Tanky (8), Fading (3) | K38: Transient | M38: any time
A39: Carcass | B39: Strategy | C39: 1-Low | D39: 1x1 | E39: Mewgenics | F39: 1 | G39: 1 | H39: Bounty | I39: Destroy an enemy spawner | J39: Nested Spawner (1, fly tag) | K39: Carcass | M39: any time
A40: Cop Bot | B40: Strategy | C40: 1-Low | D40: 1x1 | E40: Mewgenics | F40: 1 | G40: 1 | H40: Feat | I40: Defy an officer of the law | J40: N/A | K40: CopBot | L40: robot, cop | M40: any time
...

Sheet bosses
A1: Name | B1: Type | C1: Difficulty | D1: Size | E1: Game | F1: Health | G1: Damage | H1: Goal Type | I1: Goal | J1: Ability | K1: File | L1: Tag | M1: Phases | N1: Ticked | O1: Count
A2: Beholster | B2: Action | C2: 1-Low | D2: 2x2 | E2: Enter the Gungeon | F2: 1 | G2: 3 | H2: Fetch | I2: Have 6 Guns at once | J2: Ranged (4) | K2: Beholster | L2: gun | N2: any time
A3: Big Chunk | B3: Action | C3: 1-Low | D3: 2x2 | E3: Muck | F3: 1 | G3: 3 | H3: Bounty | I3: Defeat an enemy made of stone | J3: N/A | K3: BigChunk | L3: rock | N3: any time
A4: Colossus | B4: Action | C4: 1-Low | D4: 2x2 | E4: Risk of Rain | F4: 1 | G4: 3 | H4: Discovery | I4: Witness a living structure | J4: Trample | K4: Colossus | N4: any time
A5: Famine | B5: Action | C5: 1-Low | D5: 1x1 | E5: The Binding of Isaac | F5: 1 | G5: 3 | H5: Restriction | I5: Beat a game without eating any food | J5: Ranged (1) | K5: Famine | N5: game beaten
A6: Khidr | B6: Action | C6: 1-Low | D6: 2x2 | E6: Rogue Legacy | F6: 1 | G6: 3 | H6: Feat | I6: Poke an eye | J6: N/A | K6: Khidr | L6: eye | N6: any time
A7: Mega Fatty | B7: Action | C7: 1-Low | D7: 2x2 | E7: The Binding of Isaac: Rebirth | F7: 1 | G7: 3 | H7: Bounty | I7: Defeat an obese enemy | J7: Ranged (2) | K7: MegaFatty | N7: any time
A8: Megaera | B8: Action | C8: 1-Low | D8: 1x1 | E8: Hades | F8: 1 | G8: 3 | H8: Fetch | I8: Date someone | J8: N/A | K8: Megaera | N8: any time
A9: Steven | B9: Action | C9: 1-Low | D9: 1x1 | E9: The Binding of Isaac | F9: 1 | G9: 3 | H9: Discovery | I9: Be in a time loop | J9: N/A | K9: Steven | N9: any time
A10: The Rainmaker | B10: Action | C10: 1-Low | D10: 1x1 | E10: The Binding of Isaac: Rebirth | F10: 1 | G10: 3 | H10: Feat | I10: Take a shower | J10: N/A | K10: TheRainmaker | N10: any time
A11: Charon | B11: Action | C11: 2-Medium | D11: 2x1 | E11: Hades | F11: 1 | G11: 5 | H11: Fetch | I11: Steal from a shop | J11: N/A | K11: Charon | N11: any time
A12: Mom's Heart | B12: Action | C12: 2-Medium | D12: 1x1 | E12: The Binding of Isaac | F12: 1 | G12: 5 | H12: Feat | I12: Break a Heart | J12: N/A | K12: MomsHeart | N12: any time
A13: Resourceful Rat | B13: Action | C13: 2-Medium | D13: 1x1 | E13: Enter the Gungeon | F13: 1 | G13: 5 | H13: Feat | I13: Beat a mini-game inside of a game | J13: N/A | K13: ResourcefulRat | L13: rat | N13: any time
A14: Royal Phalanx | B14: Action | C14: 2-Medium | D14: 1x1 | E14: Ember Knights | F14: 1 | G14: 5 | H14: Feat | I14: Block an attack with an element | J14: Defensive Stance (2) | K14: RoyalPhalanx | N14: any time
A15: Scylla | B15: Action | C15: 2-Medium | D15: 1x1 | E15: Hades II | F15: 1 | G15: 5 | H15: Feat | I15: Perform a song | J15: N/A | K15: Scylla | N15: any time
A16: Wallmonger | B16: Action | C16: 2-Medium | D16: 2x3 | E16: Enter the Gungeon | F16: 1 | G16: 5 | H16: Feat | I16: Destroy a wall | J16: N/A | K16: Wallmonger | N16: any time
A17: Isaac | B17: Action | C17: 3-High | D17: 1x1 | E17: The Binding of Isaac | F17: 1 | G17: 7 | H17: Bounty | I17: Defeat yourself | J17: N/A | K17: Isaac | N17: any time
A18: Lich | B18: Action | C18: 4-Insane | D18: 1x2 | E18: Enter the Gungeon | F18: 1 | G18: 9 | H18: Bounty | I18: Defeat a magic enemy with a gun | J18: N/A | K18: Lich | L18: undead, skeleton | N18: any time
A19: The One Who Waits | B19: Action | C19: 4-Insane | D19: 2x2 | E19: Cult of the Lamb | F19: 1 | G19: 9 | H19: Feat | I19: Enter or Create a religion | J19: N/A | K19: TheOneWhoWaits | N19: any time
A20: Gremlin Nob | B20: Deckbuilder | C20: 1-Low | D20: 1x1 | E20: Slay the Spire | F20: 1 | G20: 3 | H20: Feat | I20: Taunt at someone | J20: N/A | K20: GremlinNob | N20: any time
A21: Lagavulin | B21: Deckbuilder | C21: 1-Low | D21: 2x2 | E21: Slay the Spire | F21: 1 | G21: 3 | H21: Feat | I21: Go to sleep | J21: N/A | K21: Lagavulin | N21: any time
A22: Vantom | B22: Deckbuilder | C22: 1-Low | D22: 1x1 | E22: Slay the Spire 2 | F22: 1 | G22: 3 | H22: Feat | I22: Use an attack that hits 4+ times | J22: Lacerator | K22: Vantom | N22: any time
A23: The Club | B23: Deckbuilder | C23: 2-Medium | D23: 1x1 | E23: Balatro | F23: 1 | G23: 5 | H23: Restriction | I23: Beat a game without backtracking | J23: N/A | K23: TheClub | N23: game beaten
A24: The Goad | B24: Deckbuilder | C24: 2-Medium | D24: 1x1 | E24: Balatro | F24: 1 | G24: 5 | H24: Restriction | I24: Beat a game without using a weapon | J24: N/A | K24: TheGoad | N24: game beaten
A25: The Head | B25: Deckbuilder | C25: 2-Medium | D25: 1x1 | E25: Balatro | F25: 1 | G25: 5 | H25: Restriction | I25: Beat a game without purposefully healing | J25: N/A | K25: TheHead | N25: game beaten
A26: The Insatiable | B26: Deckbuilder | C26: 2-Medium | D26: 2x2 | E26: Slay the Spire 2 | F26: 1 | G26: 5 | H26: Bounty | I26: Consume an enemy | J26: Ruthless, Devour Whole | K26: TheInsatiable | N26: any time
A27: The Window | B27: Deckbuilder | C27: 2-Medium | D27: 1x1 | E27: Balatro | F27: 1 | G27: 5 | H27: Restriction | I27: Beat a game without spending currency | J27: N/A | K27: TheWindow | N27: game beaten
A28: Cerulean Bell | B28: Deckbuilder | C28: 3-High | D28: 1x1 | E28: Balatro | F28: 1 | G28: 7 | H28: Restriction | I28: Beat a game while only taking the first option offered when taking reward options | J28: N/A | K28: CeruleanBell | N28: game beaten
A29: The Needle | B29: Deckbuilder | C29: 3-High | D29: 1x1 | E29: Balatro | F29: 1 | G29: 7 | H29: Restriction | I29: Beat a game while only using 1 hand | J29: N/A | K29: TheNeedle | N29: game beaten
A30: Time Eater | B30: Deckbuilder | C30: 3-High | D30: 1x1 | E30: Slay the Spire | F30: 1 | G30: 7 | H30: Restriction | I30: Beat the game in 2 hours or less | J30: Bolster (3, Speed) | K30: TimeEater | N30: game beaten
A31: Corrupt Heart | B31: Deckbuilder | C31: 4-Insane | D31: 2x2 | E31: Slay the Spire | F31: 1 | G31: 9 | H31: Feat | I31: Get the true ending on the hardest difficulty possible | J31: Hexer (2) | K31: CorruptHeart | N31: any time
A32: Giant Spider | B32: Strategy | C32: 1-Low | D32: 2x2 | E32: Forward: Escape the Fold | F32: 1 | G32: 3 | H32: Bounty | I32: Defeat a bug larger than you | J32: N/A | K32: GiantSpider | L32: bug, spider | N32: any time
A33: Hickory | B33: Strategy | C33: 1-Low | D33: 1x1 | E33: Brutal Orchestra | F33: 1 | G33: 3 | H33: Feat | I33: Light a liquid on fire | J33: Infliction (1, Burn) | K33: Hickory | L33: fire | N33: any time
A34: Marshmallow | B34: Strategy | C34: 1-Low | D34: 1x1 | E34: Mewgenics | F34: 1 | G34: 3 | H34: Feat | I34: Have an enemy defeat another enemy | J34: N/A | K34: Marshmallow | L34: cat | N34: any time
A35: Mobius | B35: Strategy | C35: 1-Low | D35: 2x2 | E35: Brutal Orchestra | F35: 1 | G35: 3 | H35: Fetch | I35: Obtain a large fish | J35: N/A | K35: Mobius | L35: fish | N35: any time
A36: Morana | B36: Strategy | C36: 1-Low | D36: 1x1 | E36: Mewgenics | F36: 1 | G36: 3 | H36: Feat | I36: Raise the dead | J36: Necromancy (1) | K36: Morana | L36: cat | N36: any time
A37: Trigger Fingers | B37: Strategy | C37: 1-Low | D37: 1x1 | E37: Brutal Orchestra | F37: 1 | G37: 3 | H37: Bounty | I37: Defeat a fascist | J37: N/A | K37: TriggerFingers | N37: any time
A38: Chubs & Nubs | B38: Strategy | C38: 2-Medium | D38: 1x2 | E38: Mewgenics | F38: 1 | G38: 5 | H38: Feat | I38: Eat something smelly | J38: N/A | K38: Chubs&Nubs | L38: dog | N38: any time
A39: Flushmaster | B39: Strategy | C39: 2-Medium | D39: 1x1 | E39: Mewgenics | F39: 1 | G39: 5 | H39: Feat | I39: Flush or get flushed | J39: N/A | K39: Flushmaster | N39: any time
A40: Guillatina | B40: Strategy | C40: 2-Medium | D40: 2x2 | E40: Mewgenics | F40: 1 | G40: 5 | H40: Feat/Feat/Bounty | I40: Eat a living creature/Throw a body part/Defeat a rotten enemy | J40: Trample, Undying (2) | K40: Guillotina, Guillotina2, Guillotina3 | L40: cat | M40: 3 | N40: any time
...

Sheet abilities
A1: Name | B1: Type | C1: Variables | D1: Description | E1: Effect
A2: Aftermath | B2: Death | C2: Tile Effect | D2: On Death, will Add X Tile Effect to the Tile it died on | E2: death: apply_tile Y
A3: Agile | B3: Movement | C3: N/A | D3: Can move diagonally if necessary | E3: passive: move_diagonal
A4: Bolster | B4: Buff | C4: Amount, Status Type | D4: Grants X amount of X Status to all other Enemies and Bosses until death | E4: passive: aura_status Y X
A5: Defensive Stance | B5: Intent | C5: Stacks | D5: Will Gain X Dexterity on it's first turn instead of moving or attacking | E5: first_turn: gain_status dexterity X
A6: Degradation | B6: Attack | C6: Amount | D6: When this Enemy attacks and deals damage, it will Destroy X amount of random obtained Loot | E6: hit: destroy_loot X
A7: Devour Whole | B7: Attack | C7: N/A | D7: When this Enemy attacks and deals damage, the target is eaten and dies, including the plaer | E7: hit: devour
A8: Drain | B8: Attack | C8: Amount, Stats | D8: When this Enemy attacks and deals damage, decrease by X the player's Y(Max Health, Luck, Scramble, Bash, Dash, Transmute) | E8: hit: drain_stat Y X
A9: Entry Summon | B9: Summoner | C9: Amount, Enemy Type | D9: Instead of moving or attacking on it's first turn, it will Summon X amount of Y Enemies to a random adjacent tile | E9: first_turn: summon_adjacent X Y
A10: Fading | B10: Death | C10: Amount | D10: Will die at the end of X amount of combats | E10: spawn: set_fades X
A11: Fireproof | B11: Resistance | C11: N/A | D11: Cannot be Burned | E11: passive: immune burn
A12: Haste | B12: Buff | C12: Stacks | D12: Spawns with X Speed | E12: spawn: gain_status speed X
... A32: Restless Remains | B32: Death | C32: N/A | D32: On Health depletion, will leave a corpse with 1 Max Health that will revive in it's current tile on game completion unless fully defeated | E32: death: leave_corpse 1 revive=game_end

Sheet statuses
A1: Name | B1: Type | C1: Game | D1: On Player | E1: On Player Effect | F1: On Enemy | G1: On Enemy Effect | H1: Combat | I1: Decrease | J1: EnemyOnly | K1: Enemy Combat Effect | L1: Stackable | M1: Image
A2: Burn | B2: Debuff | C2: Brutal Orchestra | D2: Gain "You must beat a game while skipping or trashing X items/upgrades or take 3 Damage." | E2: demand "skip or trash {X} [item/upgrade|items/upgrades]" else -> take_damage 3 | F2: Gains "or instead beat a game while skipping or trashing 4-X items/upgrades" | G2: instead "skip or trash {4-X} [item/upgrade|items/upgrades]" | H2: Half Damage dealt | I2: On Completion | J2: Yes | K2: damage_dealt x0.5 | L2: Max: 3 | M2: Burn
A3: Dexterity | B3: Buff | C3: Slay the Spire | D3: Gain "if X or all bosses were beaten without getting hit when beating a game, Gain a [chest reward]" | E3: goal "{X} or all bosses were beaten without getting hit" -> gain_chest reward {X} | F3: Gains "and you must beat X or all bosses without getting hit in the run you complete the goal in" | G3: clause "you must beat {X} or all bosses without getting hit" | H3: Gain +X Shields | I3: N/A | J3: Yes | K3: shield +{X} | L3: Intensity | M3: Dexterity
A4: Marked | B4: Debuff | C4: Mewgenics | D4: Gain "You must beat a game while getting X achievements or take 3 Damage." | E4: demand "get {X} [achievement|achievements]" else -> take_damage 3 | F4: Gains "and if you get X achievements in the run you complete the goal in, Gain a [chest reward]" | G4: bonus "you get {X} [achievement|achievements]" decay -> gain_chest reward {X} | H4: Damage taken increased by x2. Ignores shields. | I4: On Completion | J4: No | K4: damage_taken x2; pierce_shields | L4: Intensity | M4: Marked
A5: Speed | B5: Buff | C5: Mewgenics | D5: Gain "If beaten in 1+(1/2)^(X-2) hours or less, Gain a [chest reward] and 1 Dash" | E5: goal "beaten in {1+(1/2)^(X-2):hours} or less" -> gain_chest reward {X}; gain_stat dash 1 | F5: Gains "and the goal must be completed 1+(1/2)^(X-2) hours or less into that run" | G5: clause "the game must be beaten in {1+(1/2)^(X-2):hours} or less" | H5: Increase tile movement by X | I5: N/A | J5: Yes | K5: tile_move +{X} | L5: Intensity | M5: Speed
A6: Strength | B6: Buff | C6: Slay the Spire | D6: Gain "If beaten while the difficulty is increased X times or as much as possible, Gain a [chest reward] and 1 Bash" | E6: goal "the difficulty is increased {X} [time|times] or as much as possible" -> gain_chest reward {X}; gain_stat bash 1 | F6: Gains "and the difficulty must be increased X times or as much as possible in the run you complete the goal in" | G6: clause "the difficulty must be increased {X} [time|times] or as much as possible" | H6: Increase Damage Dealt by X | I6: N/A | J6: Yes | K6: damage_dealt +{X} | L6: Intensity | M6: Strength
A7: Bleed | B7: Debuff | C7: Mewgenics | D7: Gain "You must beat a game while not healing intentionally or take 3 Damage. This lasts for X games." | E7: demand "not heal intentionally" else -> take_damage 3 | F7: Gains "and if you didn't intentionally heal in the run you complete the goal in, Gain a [chest reward]" | G7: bonus "you didn't intentionally heal" -> gain_chest reward {X} | H7: 50% chance to take 1 Damage when attacking | I7: On Trigger | J7: Yes | K7: recoil +1 chance=50 | L7: Intensity | M7: Bleed
A8: Stun | B8: Debuff | C8: Slay the Spire | D8: Gain "You must beat a game twice in a row to set it as Completed or take 5 Damage. This lasts for X games." | E8: demand "beat a game twice in a row to set it as Completed" else -> take_damage 5 | F8: Gains "and if the goal was completed twice, Gain a [chest reward]" | G8: bonus "you beat the game twice in a row" -> gain_chest reward {X} | H8: Skip their turn | I8: Each Turn | J8: Yes | K8: skip_turn | L8: Intensity | M8: Stun

Sheet events
A1: Event | B1: Game | C1: Tier | D1: Where | E1: Requirement | F1: Trigger | G1: Rarity | H1: Image | I1: Prompt | J1: Opens With | K1: Goal Met | L1: Goal Missed | M1: Chance Won | N1: Chance Lost | O1: Choice 1 | P1: Repeat 1 | Q1: Result 1 | R1: Effect 1 | S1: Choice 2 | T1: Repeat 2 | U1: Result 2 | V1: Effect 2 | W1: Choice 3 | X1: Repeat 3 | Y1: Result 3 | Z1: Effect 3 | AA1: Choice 4 | AB1: Repeat 4 | AC1: Result 4 | AD1: Effect 4 | AE1: Choice 5 | AF1: Repeat 5 | AG1: Result 5 | AH1: Effect 5 | AI1: Choice 6 | AJ1: Repeat 6 | AK1: Result 6 | AL1: Effect 6
A2: Abyssal Baths | B2: Slay the Spire 2 | C2: All | F2: After | G2: Common | H2: AbyssalBaths | I2: You discover a secluded chamber. Steam rises from bubbling pools of hot liquid that shifts colors with hypnotic rhythm. Barnacled growths hang from the ceiling, dripping viscous fluid that hisses and writhes when it touches the surface. The air feels heavy, laden with salt and something unmistakably organic. As you approach the edge of the largest pool, the liquid ripples. The waters bubble more intensely as if anticipating your entry. | O2: Immerse | P2: Stay | Q2: The liquid burns against your skin, simultaneously freezing and scalding. Beneath the surface, something brushes against your legs—tendrils? Currents with purpose? But when the pain subsides, you feel... denser somehow. More substantial. | R2: gain_max_hp 1; lose_hp 2 | S2: Linger | T2: Again | U2: The temperature keeps rising! How long can you endure before the steam cooks you from within? || It keeps getting hotter! The pool's bubbling sounds like laughter. IT'S SO HOT! || You wonder if this is what it's like to live in the Village of Demons? You have bathed so long you have lost track of time and your mind... It's nice in here. Really fantastic. || If you bathe any longer you will die. | V2: needs Immerse > 0; gain_max_hp 1; lose_hp {3+X} | W2: Abstain | Y2: You decline the temptation of the waters, instead gathering crystalline salts that have formed along the edges. As you apply them to your skin, the pools churn and froth agitatedly. | Z2: needs Immerse = 0; gain_hp 3 | AA2: Exit Baths | AC2: The heat finally gets to you, and you hop out of the bath. | AD2: needs Immerse > 0; nothing
A3: Arcade Room | B3: The Binding of Isaac | C3: All | E3: gold>=1 | F3: After | G3: Common | H3: ArcadeRoom | O3: Enter | P3: Stay | R3: lose_gold 1; spawn_object tag=arcade 2-3 | S3: Leave | V3: nothing
A4: Battleworn Dummy | B4: Slay the Spire 2 | C4: All | F4: After | G4: Common | H4: BattlewornDummy | I4: As you approach, it begins to rumble and fizzle and lights up brilliantly! "BZZZT! TIME TO TRAIN!!! YOU HAVE 3 TURNS TO DEFEAT ME! CHOOSE A SETTING OR FACE LETHAL HUMILIATION." | K4: "YOU PASS THE TRAINING! YOU ARE NOW EQUIPPED TO DEFEND THIS FACTORY AGAINST INTRUDERS!! BE SURE TO HYDRATE AFTER TRAINING SESSIONS!" | L4: "YOU ARE WEAK!! HUMILIATION HAS BEEN ADMINISTERED!" The dummy is silent for a moment and— "Choose a lower setting next time." | O4: Setting 1 | R4: add_goal "beat a game in 5 attempts or fewer" for 3 games -> gain_potion 1 | S4: Setting 2 | V4: add_goal "beat a game in 3 attempts or fewer" for 3 games -> gain_chest small 1 | W4: Setting 3 | Z4: add_goal "beat a game in 1 attempt" for 3 games -> gain_chest large 1
A5: Golden Idol | B5: Slay the Spire | C5: All | F5: After | G5: Common | H5: GoldenIdol | I5: You come across an inconspicuous pedestal with a shining gold idol sitting peacefully atop. It looks incredibly valuable. You sure don't see any traps nearby. | O5: Take | P5: Stay | Q5: As you grab the Idol and stow it away, a giant boulder smashes through the ceiling into the ground next to you. You realize that the floor is slanted downwards as the boulder starts to roll towards you. | R5: gain_item golden_idol | S5: Leave | U5: If there was ever an obvious trap, this would be it. You decide not to interfere with objects placed upon pedestals. | V5: needs Take = 0; nothing | W5: Outrun | Y5: RUUUUUUUUUUN! You barely leap into a side passageway as the boulder rushes by. Unfortunately it feels like you sprained something however. | Z5: needs Take > 0; lose_hp {max(1,round(0.25*MAX_HP))} | AA5: Smash | AC5: You throw yourself at the boulder with everything you have. When the dust clears, you can make a safe way out. | AD5: needs Take > 0; add_curse injury | AE5: Hide | AG5: SQUISH! The boulder flattens you a little as it passes by, but otherwise you can get out of here. | AH5: needs Take > 0; lose_max_hp {max(1,round(0.08*MAX_HP))}
A6: Golden Monkey | B6: Tiny Rogues | C6: All | F6: After | G6: Common | H6: GoldenMonkey | O6: Touch the Golden Monkey | R6: gain_stat luck 1; add_curse random | S6: Leave | V6: nothing
A7: Jungle Maze Adventure | B7: Slay the Spire 2 | C7: All | F7: After | G7: Common | H7: JungleMazeAdventure | I7: In a clearing, you run into a Ragtag Group of Adventurers looking down and gesturing at a gigantic maze. They offer to join forces with you in an Epic Quest to loot the riches of this maze. As an experienced adventurer yourself, it's clear this maze is filled with deadly traps and guardians. It would be easier if you work together, but then you would have to split the loot. | O7: Solo Quest | Q7: Feeling misanthropic, you wordlessly walk past their now-frowning faces. One of them even shakes their fist at you. The maze is not welcoming. You fall into a spike trap, you are struck by a massive log with spikes, and feisty creatures with spiky clubs fight you along the entire journey. You are sick of spikes, and consider teamwork for the next adventure. | R7: gain_gold 3; lose_hp 2 | S7: Join Forces | U7: Everyone's face immediately lights up, including your own! One of the adventurers turns out to be a bard! You merrily waltz into the maze as Aquid the squid wizard effortlessly disarms traps, while you and the Grathorian fighter take out the spiky club-wielding guards with ease. This was the most joyous adventure of your life and you've made some truly Great Memories. | V7: gain_gold 1
A8: Morphic Grove | B8: Slay the Spire 2 | C8: All | E8: gold >=3 | F8: After | G8: Common | H8: MorphicGrove | I8: You enter a grove of crystalline trees, and they begin to quiver excitedly! A chorus of hellos and welcomes bombard you as a group of Morphics burst forth from trees. One of the Morphics is fidgeting in the corner, clearly not as sociable as the others. Approach the group or the loner? | O8: Group | Q8: You greet the chittering Morphics and they embrace you into their crystally arms. They share their combined knowledge and inject you with Morphic Magic, changing your nature... Such lovely creatures, these Morphics. One of them stole your gold. | R8: gain_stat transmute 2; lose_gold all | S8: Loner | U8: You reach out a hand to the lone Morphic, sympathizing with its nature. It gifts you a tiny crystal fruit, and you consume it, as is custom. The fruit clarifies your mind and purpose. You give thanks, then make your way onwards. | V8: gain_max_hp 1
A9: Potion Lab | B9: Tiny Rogues | C9: All | F9: After | G9: Rare | H9: PotionLab | J9: offer_loot potion 3 | O9: Leave | R9: nothing
A10: Punch Off | B10: Slay the Spire 2 | C10: All | E10: games >= 6 | F10: After | G10: Common | H10: PunchOff | I10: Two Punch Constructs are duking it out and you see some treasure in between them... Should you try to nab it? | O10: Nab | Q10: You successfully nab the relic! ...or so you thought. A right-hook clocks you in the face. | R10: add_curse injury; gain_chest small 1 | S10: I Can Take Them | U10: The Constructs turn to you menacingly! | V10: spawn_enemy tag=robot 1; play_game tag=mecha -> gain_loot 1; gain_chest small 2
A11: Ranwid the Elder | B11: Slay the Spire 2 | C11: All | E11: gold>=2 and potions>=1 and relics>=1 | F11: After | G11: Common | H11: RanwidTheElder | I11: You are approached by the oldest person you have ever seen. “We meet once more... it's me, Ranwid!” You do not know this man. | O11: Give 2 Gold | Q11: “Mag.. nificent...” Ranwid mumbles while chewing the gold. | R11: needs gold 2; lose_gold 2; gain_random_item 1 | S11: Give <potion> | U11: “Exquisite...” Glup glup glup. He downs the <potion> in one go. | V11: lose_potion; gain_random_item 1 | W11: Give <relic> | Y11: “Exemplary...” Ranwid observes the relic studiously for several minutes... Then eats the <relic>. | Z11: lose_relic; gain_random_item 2
A12: Relic Trader | B12: Slay the Spire 2 | C12: All | E12: relics >= 5 | F12: After | G12: Common | H12: RelicTrader | I12: You turn a corner and suddenly, a shadowy figure is just standing there. He pivots to face you. “Welcome! What're ya trading?” The figure inquires as he flares open his cloak to reveal a slew of suspicious wares. | O12: Take the Top One | Q12: “Hehehe Heh... Thank you!” | R12: trade_relic 1 | S12: Take the Middle One | U12: “Hehehe Heh... Thank you!” | V12: trade_relic 2 | W12: Take the Bottom One | Y12: “Hehehe Heh... Thank you!” | Z12: trade_relic 3
A13: Scrap Ooze | B13: Slay the Spire | C13: All | F13: After | G13: Common | H13: ScrapOoze | I13: As you walk into the room you hear a gurgling and the grinding of metals. Before you is a slime-like creature that ate too much scrap for its own good. From the center of the creature you see glints of strange light, perhaps something magical? It looks like you can get some treasure if you just reach inside its... opening. However, the acid and sharp objects may hurt. | M13: Success! After rummaging through the metal and burning acid, you finally grab hold of a relic and yank it out. You pull your way out of the ooze damaged but rewarded. | N13: Ouch! All you find is corroded metal and a bit of burning pain. However, you're still convinced there's a relic... | O13: Reach Inside | P13: Stay | R13: lose_hp 1; chance 25% -> gain_chest small 1 | S13: Deeper | T13: Again | V13: needs Reach Inside > 0; lose_hp {2+X}; chance {35+10*X}% -> gain_chest small 1 | W13: Leave | Y13: You decide to leave the area. The slime pays no attention, content with its meal. | Z13: nothing
